<robot name = "robot">
    <link name="Link0">
        <inertial>
            <origin xyz="0 0 2" rpy="0 0 0"/>
            <mass value="0.3053225868731224" />
            <inertia ixx="100" ixy="0" ixz="0" iyy="100" iyz="0" izz="100" />
        </inertial>
        <visual>
            <origin xyz="0 0 2" rpy="0 0 0"/>
            <geometry>
                <box size="1.223252551767068 0.9875885099166811 0.25273580604540036" />
            </geometry>
            <material name="No Sensor">
                <color rgba="0.184 0.553 0.933 1.0"/>
            </material>
        </visual>
        <collision>
            <origin xyz="0 0 2" rpy="0 0 0"/>
            <geometry>
                <box size="1.223252551767068 0.9875885099166811 0.25273580604540036" />
            </geometry>
        </collision>
    </link>
    <joint name="Link0_Link1" type="revolute">
       <parent link="Link0"/>
       <child  link="Link1"/>
       <origin rpy="0 0 0" xyz="0.611626275883534 0 2" />
       <axis xyz="1 0 0"/>
       <limit effort="0.0" lower="-3.14159" upper="3.14159" velocity="0.0"/>
    </joint>
    <link name="Link1">
        <inertial>
            <origin xyz="0.15668025568701766 0 0" rpy="0 0 0"/>
            <mass value="0.15312179469356602" />
            <inertia ixx="100" ixy="0" ixz="0" iyy="100" iyz="0" izz="100" />
        </inertial>
        <visual>
            <origin xyz="0.15668025568701766 0 0" rpy="0 0 0"/>
            <geometry>
                <box size="0.3133605113740353 0.8342694052275808 0.5857151077556031" />
            </geometry>
            <material name="No Sensor">
                <color rgba="0.184 0.553 0.933 1.0"/>
            </material>
        </visual>
        <collision>
            <origin xyz="0.15668025568701766 0 0" rpy="0 0 0"/>
            <geometry>
                <box size="0.3133605113740353 0.8342694052275808 0.5857151077556031" />
            </geometry>
        </collision>
    </link>
    <joint name="Link1_Link2" type="revolute">
       <parent link="Link1"/>
       <child  link="Link2"/>
       <origin rpy="0 0 0" xyz="0.3133605113740353 0.0 0.0" />
       <axis xyz="0 1 0"/>
       <limit effort="0.0" lower="-3.14159" upper="3.14159" velocity="0.0"/>
    </joint>
    <link name="Link2">
        <inertial>
            <origin xyz="0.5659167403758983 0.0 0.0" rpy="0 0 0"/>
            <mass value="1.5738847324629939" />
            <inertia ixx="100" ixy="0" ixz="0" iyy="100" iyz="0" izz="100" />
        </inertial>
        <visual>
            <origin xyz="0.5659167403758983 0.0 0.0" rpy="0 0 0"/>
            <geometry>
                <box size="1.1318334807517967 1.1236693693569384 1.2375189087044416" />
            </geometry>
            <material name="No Sensor">
                <color rgba="0.184 0.553 0.933 1.0"/>
            </material>
        </visual>
        <collision>
            <origin xyz="0.5659167403758983 0.0 0.0" rpy="0 0 0"/>
            <geometry>
                <box size="1.1318334807517967 1.1236693693569384 1.2375189087044416" />
            </geometry>
        </collision>
    </link>
    <joint name="Link2_Link3" type="revolute">
       <parent link="Link2"/>
       <child  link="Link3"/>
       <origin rpy="0 0 0" xyz="1.1318334807517967 0.0 0.0" />
       <axis xyz="0 1 0"/>
       <limit effort="0.0" lower="-3.14159" upper="3.14159" velocity="0.0"/>
    </joint>
    <link name="Link3">
        <inertial>
            <origin xyz="0.48291598453629686 0.0 0.0" rpy="0 0 0"/>
            <mass value="0.6199959611826488" />
            <inertia ixx="100" ixy="0" ixz="0" iyy="100" iyz="0" izz="100" />
        </inertial>
        <visual>
            <origin xyz="0.48291598453629686 0.0 0.0" rpy="0 0 0"/>
            <geometry>
                <box size="0.9658319690725937 1.1268836998086516 0.5696501118620526" />
            </geometry>
            <material name="No Sensor">
                <color rgba="0.184 0.553 0.933 1.0"/>
            </material>
        </visual>
        <collision>
            <origin xyz="0.48291598453629686 0.0 0.0" rpy="0 0 0"/>
            <geometry>
                <box size="0.9658319690725937 1.1268836998086516 0.5696501118620526" />
            </geometry>
        </collision>
    </link>
    <joint name="Link3_Link4" type="revolute">
       <parent link="Link3"/>
       <child  link="Link4"/>
       <origin rpy="0 0 0" xyz="0.48291598453629686 0.0 -0.2848250559310263" />
       <axis xyz="1 0 0"/>
       <limit effort="0.0" lower="-3.14159" upper="3.14159" velocity="0.0"/>
    </joint>
    <link name="Link4">
        <inertial>
            <origin xyz="0.0 0.0 -0.2767362989807625" rpy="0 0 0"/>
            <mass value="0.22296300899048094" />
            <inertia ixx="100" ixy="0" ixz="0" iyy="100" iyz="0" izz="100" />
        </inertial>
        <visual>
            <origin xyz="0.0 0.0 -0.2767362989807625" rpy="0 0 0"/>
            <geometry>
                <box size="0.36117695191980603 1.1153641057823798 0.553472597961525" />
            </geometry>
            <material name="No Sensor">
                <color rgba="0.184 0.553 0.933 1.0"/>
            </material>
        </visual>
        <collision>
            <origin xyz="0.0 0.0 -0.2767362989807625" rpy="0 0 0"/>
            <geometry>
                <box size="0.36117695191980603 1.1153641057823798 0.553472597961525" />
            </geometry>
        </collision>
    </link>
    <joint name="Link4_Link5" type="revolute">
       <parent link="Link4"/>
       <child  link="Link5"/>
       <origin rpy="0 0 0" xyz="0.0 -0.5576820528911899 -0.2767362989807625" />
       <axis xyz="0 1 0"/>
       <limit effort="0.0" lower="-3.14159" upper="3.14159" velocity="0.0"/>
    </joint>
    <link name="Link5">
        <inertial>
            <origin xyz="0.0 -0.44801512853578634 0.0" rpy="0 0 0"/>
            <mass value="0.5128388573856506" />
            <inertia ixx="100" ixy="0" ixz="0" iyy="100" iyz="0" izz="100" />
        </inertial>
        <visual>
            <origin xyz="0.0 -0.44801512853578634 0.0" rpy="0 0 0"/>
            <geometry>
                <box size="0.6693322981668862 0.8960302570715727 0.8550991341555126" />
            </geometry>
            <material name="Sensor">
                <color rgba="0.239 0.875 0.282 1.0"/>
            </material>
        </visual>
        <collision>
            <origin xyz="0.0 -0.44801512853578634 0.0" rpy="0 0 0"/>
            <geometry>
                <box size="0.6693322981668862 0.8960302570715727 0.8550991341555126" />
            </geometry>
        </collision>
    </link>
    <joint name="Link5_Link6" type="revolute">
       <parent link="Link5"/>
       <child  link="Link6"/>
       <origin rpy="0 0 0" xyz="0.0 -0.44801512853578634 -0.4275495670777563" />
       <axis xyz="0 1 0"/>
       <limit effort="0.0" lower="-3.14159" upper="3.14159" velocity="0.0"/>
    </joint>
    <link name="Link6">
        <inertial>
            <origin xyz="0.0 0.0 -0.18634052092950315" rpy="0 0 0"/>
            <mass value="0.15906327383115731" />
            <inertia ixx="100" ixy="0" ixz="0" iyy="100" iyz="0" izz="100" />
        </inertial>
        <visual>
            <origin xyz="0.0 0.0 -0.18634052092950315" rpy="0 0 0"/>
            <geometry>
                <box size="0.6709230845148799 0.6361505118705936 0.3726810418590063" />
            </geometry>
            <material name="Sensor">
                <color rgba="0.239 0.875 0.282 1.0"/>
            </material>
        </visual>
        <collision>
            <origin xyz="0.0 0.0 -0.18634052092950315" rpy="0 0 0"/>
            <geometry>
                <box size="0.6709230845148799 0.6361505118705936 0.3726810418590063" />
            </geometry>
        </collision>
    </link>
    <joint name="Link6_Link7" type="revolute">
       <parent link="Link6"/>
       <child  link="Link7"/>
       <origin rpy="0 0 0" xyz="0.0 0.0 -0.3726810418590063" />
       <axis xyz="1 0 0"/>
       <limit effort="0.0" lower="-3.14159" upper="3.14159" velocity="0.0"/>
    </joint>
    <link name="Link7">
        <inertial>
            <origin xyz="0.0 0.0 -0.5024039255502306" rpy="0 0 0"/>
            <mass value="0.38031065050760476" />
            <inertia ixx="100" ixy="0" ixz="0" iyy="100" iyz="0" izz="100" />
        </inertial>
        <visual>
            <origin xyz="0.0 0.0 -0.5024039255502306" rpy="0 0 0"/>
            <geometry>
                <box size="0.7838618843034166 0.48285409724399597 1.0048078511004612" />
            </geometry>
            <material name="Sensor">
                <color rgba="0.239 0.875 0.282 1.0"/>
            </material>
        </visual>
        <collision>
            <origin xyz="0.0 0.0 -0.5024039255502306" rpy="0 0 0"/>
            <geometry>
                <box size="0.7838618843034166 0.48285409724399597 1.0048078511004612" />
            </geometry>
        </collision>
    </link>
    <joint name="Link7_Link8" type="revolute">
       <parent link="Link7"/>
       <child  link="Link8"/>
       <origin rpy="0 0 0" xyz="0.0 0.24142704862199799 -0.5024039255502306" />
       <axis xyz="1 0 0"/>
       <limit effort="0.0" lower="-3.14159" upper="3.14159" velocity="0.0"/>
    </joint>
    <link name="Link8">
        <inertial>
            <origin xyz="0.0 0.16096348240460723 0.0" rpy="0 0 0"/>
            <mass value="0.36897963386142957" />
            <inertia ixx="100" ixy="0" ixz="0" iyy="100" iyz="0" izz="100" />
        </inertial>
        <visual>
            <origin xyz="0.0 0.16096348240460723 0.0" rpy="0 0 0"/>
            <geometry>
                <box size="0.9248705841645001 0.32192696480921446 1.2392646847358004" />
            </geometry>
            <material name="Sensor">
                <color rgba="0.239 0.875 0.282 1.0"/>
            </material>
        </visual>
        <collision>
            <origin xyz="0.0 0.16096348240460723 0.0" rpy="0 0 0"/>
            <geometry>
                <box size="0.9248705841645001 0.32192696480921446 1.2392646847358004" />
            </geometry>
        </collision>
    </link>
    <joint name="Link8_Link9" type="revolute">
       <parent link="Link8"/>
       <child  link="Link9"/>
       <origin rpy="0 0 0" xyz="0.0 0.16096348240460723 -0.6196323423679002" />
       <axis xyz="0 1 0"/>
       <limit effort="0.0" lower="-3.14159" upper="3.14159" velocity="0.0"/>
    </joint>
    <link name="Link9">
        <inertial>
            <origin xyz="0.0 0.0 -0.14037140917484853" rpy="0 0 0"/>
            <mass value="0.1382318679157147" />
            <inertia ixx="100" ixy="0" ixz="0" iyy="100" iyz="0" izz="100" />
        </inertial>
        <visual>
            <origin xyz="0.0 0.0 -0.14037140917484853" rpy="0 0 0"/>
            <geometry>
                <box size="1.0304569355743411 0.4778258868905976 0.28074281834969705" />
            </geometry>
            <material name="Sensor">
                <color rgba="0.239 0.875 0.282 1.0"/>
            </material>
        </visual>
        <collision>
            <origin xyz="0.0 0.0 -0.14037140917484853" rpy="0 0 0"/>
            <geometry>
                <box size="1.0304569355743411 0.4778258868905976 0.28074281834969705" />
            </geometry>
        </collision>
    </link>
</robot>