<robot name = "robot">
    <link name="Link0">
        <inertial>
            <origin xyz="0 0 2" rpy="0 0 0"/>
            <mass value="0.11972454002546074" />
            <inertia ixx="100" ixy="0" ixz="0" iyy="100" iyz="0" izz="100" />
        </inertial>
        <visual>
            <origin xyz="0 0 2" rpy="0 0 0"/>
            <geometry>
                <box size="0.25871069360547383 0.9206225209371665 0.5026749022649195" />
            </geometry>
            <material name="No Sensor">
                <color rgba="0.184 0.553 0.933 1.0"/>
            </material>
        </visual>
        <collision>
            <origin xyz="0 0 2" rpy="0 0 0"/>
            <geometry>
                <box size="0.25871069360547383 0.9206225209371665 0.5026749022649195" />
            </geometry>
        </collision>
    </link>
    <joint name="Link0_Link1" type="revolute">
       <parent link="Link0"/>
       <child  link="Link1"/>
       <origin rpy="0 0 0" xyz="0.12935534680273691 0 2" />
       <axis xyz="1 0 0"/>
       <limit effort="0.0" lower="-3.14159" upper="3.14159" velocity="0.0"/>
    </joint>
    <link name="Link1">
        <inertial>
            <origin xyz="0.4083808138138715 0 0" rpy="0 0 0"/>
            <mass value="0.24237794987561107" />
            <inertia ixx="100" ixy="0" ixz="0" iyy="100" iyz="0" izz="100" />
        </inertial>
        <visual>
            <origin xyz="0.4083808138138715 0 0" rpy="0 0 0"/>
            <geometry>
                <box size="0.816761627627743 0.4916643869011911 0.6035719242869888" />
            </geometry>
            <material name="No Sensor">
                <color rgba="0.184 0.553 0.933 1.0"/>
            </material>
        </visual>
        <collision>
            <origin xyz="0.4083808138138715 0 0" rpy="0 0 0"/>
            <geometry>
                <box size="0.816761627627743 0.4916643869011911 0.6035719242869888" />
            </geometry>
        </collision>
    </link>
    <joint name="Link1_Link2" type="revolute">
       <parent link="Link1"/>
       <child  link="Link2"/>
       <origin rpy="0 0 0" xyz="0.4083808138138715 0.0 -0.3017859621434944" />
       <axis xyz="0 1 0"/>
       <limit effort="0.0" lower="-3.14159" upper="3.14159" velocity="0.0"/>
    </joint>
    <link name="Link2">
        <inertial>
            <origin xyz="0.0 0.0 -0.4680370366380986" rpy="0 0 0"/>
            <mass value="0.6476432602566873" />
            <inertia ixx="100" ixy="0" ixz="0" iyy="100" iyz="0" izz="100" />
        </inertial>
        <visual>
            <origin xyz="0.0 0.0 -0.4680370366380986" rpy="0 0 0"/>
            <geometry>
                <box size="0.9552384454927307 0.724292253873224 0.9360740732761972" />
            </geometry>
            <material name="Sensor">
                <color rgba="0.239 0.875 0.282 1.0"/>
            </material>
        </visual>
        <collision>
            <origin xyz="0.0 0.0 -0.4680370366380986" rpy="0 0 0"/>
            <geometry>
                <box size="0.9552384454927307 0.724292253873224 0.9360740732761972" />
            </geometry>
        </collision>
    </link>
    <joint name="Link2_Link3" type="revolute">
       <parent link="Link2"/>
       <child  link="Link3"/>
       <origin rpy="0 0 0" xyz="0.0 0.0 -0.9360740732761972" />
       <axis xyz="1 0 0"/>
       <limit effort="0.0" lower="-3.14159" upper="3.14159" velocity="0.0"/>
    </joint>
    <link name="Link3">
        <inertial>
            <origin xyz="0.0 0.0 -0.13745880007279465" rpy="0 0 0"/>
            <mass value="0.10385285125339688" />
            <inertia ixx="100" ixy="0" ixz="0" iyy="100" iyz="0" izz="100" />
        </inertial>
        <visual>
            <origin xyz="0.0 0.0 -0.13745880007279465" rpy="0 0 0"/>
            <geometry>
                <box size="0.7211534253924048 0.5238273978029255 0.2749176001455893" />
            </geometry>
            <material name="Sensor">
                <color rgba="0.239 0.875 0.282 1.0"/>
            </material>
        </visual>
        <collision>
            <origin xyz="0.0 0.0 -0.13745880007279465" rpy="0 0 0"/>
            <geometry>
                <box size="0.7211534253924048 0.5238273978029255 0.2749176001455893" />
            </geometry>
        </collision>
    </link>
    <joint name="Link3_Link4" type="revolute">
       <parent link="Link3"/>
       <child  link="Link4"/>
       <origin rpy="0 0 0" xyz="0.3605767126962024 0.0 -0.13745880007279465" />
       <axis xyz="0 0 1"/>
       <limit effort="0.0" lower="-3.14159" upper="3.14159" velocity="0.0"/>
    </joint>
    <link name="Link4">
        <inertial>
            <origin xyz="0.21572509231102416 0.0 0.0" rpy="0 0 0"/>
            <mass value="0.08702582501996244" />
            <inertia ixx="100" ixy="0" ixz="0" iyy="100" iyz="0" izz="100" />
        </inertial>
        <visual>
            <origin xyz="0.21572509231102416 0.0 0.0" rpy="0 0 0"/>
            <geometry>
                <box size="0.4314501846220483 0.7442613129634019 0.2710141991100593" />
            </geometry>
            <material name="No Sensor">
                <color rgba="0.184 0.553 0.933 1.0"/>
            </material>
        </visual>
        <collision>
            <origin xyz="0.21572509231102416 0.0 0.0" rpy="0 0 0"/>
            <geometry>
                <box size="0.4314501846220483 0.7442613129634019 0.2710141991100593" />
            </geometry>
        </collision>
    </link>
</robot>