<robot name = "robot">
    <link name="Link0">
        <inertial>
            <origin xyz="0 0 2" rpy="0 0 0"/>
            <mass value="0.18825230771277351" />
            <inertia ixx="100" ixy="0" ixz="0" iyy="100" iyz="0" izz="100" />
        </inertial>
        <visual>
            <origin xyz="0 0 2" rpy="0 0 0"/>
            <geometry>
                <box size="0.5065331178037924 0.463861345395875 0.8012061607760821" />
            </geometry>
            <material name="No Sensor">
                <color rgba="0.184 0.553 0.933 1.0"/>
            </material>
        </visual>
        <collision>
            <origin xyz="0 0 2" rpy="0 0 0"/>
            <geometry>
                <box size="0.5065331178037924 0.463861345395875 0.8012061607760821" />
            </geometry>
        </collision>
    </link>
    <joint name="Link0_Link1" type="revolute">
       <parent link="Link0"/>
       <child  link="Link1"/>
       <origin rpy="0 0 0" xyz="0.2532665589018962 0 2" />
       <axis xyz="1 0 0"/>
       <limit effort="0.0" lower="-3.14159" upper="3.14159" velocity="0.0"/>
    </joint>
    <link name="Link1">
        <inertial>
            <origin xyz="0.6006978014193955 0 0" rpy="0 0 0"/>
            <mass value="0.616200121572297" />
            <inertia ixx="100" ixy="0" ixz="0" iyy="100" iyz="0" izz="100" />
        </inertial>
        <visual>
            <origin xyz="0.6006978014193955 0 0" rpy="0 0 0"/>
            <geometry>
                <box size="1.201395602838791 0.4877366944896655 1.0515993547597384" />
            </geometry>
            <material name="Sensor">
                <color rgba="0.239 0.875 0.282 1.0"/>
            </material>
        </visual>
        <collision>
            <origin xyz="0.6006978014193955 0 0" rpy="0 0 0"/>
            <geometry>
                <box size="1.201395602838791 0.4877366944896655 1.0515993547597384" />
            </geometry>
        </collision>
    </link>
    <joint name="Link1_Link2" type="revolute">
       <parent link="Link1"/>
       <child  link="Link2"/>
       <origin rpy="0 0 0" xyz="1.201395602838791 0.0 0.0" />
       <axis xyz="0 1 0"/>
       <limit effort="0.0" lower="-3.14159" upper="3.14159" velocity="0.0"/>
    </joint>
    <link name="Link2">
        <inertial>
            <origin xyz="0.14020500914101353 0.0 0.0" rpy="0 0 0"/>
            <mass value="0.11324096765038538" />
            <inertia ixx="100" ixy="0" ixz="0" iyy="100" iyz="0" izz="100" />
        </inertial>
        <visual>
            <origin xyz="0.14020500914101353 0.0 0.0" rpy="0 0 0"/>
            <geometry>
                <box size="0.28041001828202705 0.7562200113876759 0.5340253587052725" />
            </geometry>
            <material name="Sensor">
                <color rgba="0.239 0.875 0.282 1.0"/>
            </material>
        </visual>
        <collision>
            <origin xyz="0.14020500914101353 0.0 0.0" rpy="0 0 0"/>
            <geometry>
                <box size="0.28041001828202705 0.7562200113876759 0.5340253587052725" />
            </geometry>
        </collision>
    </link>
    <joint name="Link2_Link3" type="revolute">
       <parent link="Link2"/>
       <child  link="Link3"/>
       <origin rpy="0 0 0" xyz="0.28041001828202705 0.0 0.0" />
       <axis xyz="0 0 1"/>
       <limit effort="0.0" lower="-3.14159" upper="3.14159" velocity="0.0"/>
    </joint>
    <link name="Link3">
        <inertial>
            <origin xyz="0.26636086493633027 0.0 0.0" rpy="0 0 0"/>
            <mass value="0.2686212661234085" />
            <inertia ixx="100" ixy="0" ixz="0" iyy="100" iyz="0" izz="100" />
        </inertial>
        <visual>
            <origin xyz="0.26636086493633027 0.0 0.0" rpy="0 0 0"/>
            <geometry>
                <box size="0.5327217298726605 0.6419738907254965 0.7854573610136704" />
            </geometry>
            <material name="Sensor">
                <color rgba="0.239 0.875 0.282 1.0"/>
            </material>
        </visual>
        <collision>
            <origin xyz="0.26636086493633027 0.0 0.0" rpy="0 0 0"/>
            <geometry>
                <box size="0.5327217298726605 0.6419738907254965 0.7854573610136704" />
            </geometry>
        </collision>
    </link>
    <joint name="Link3_Link4" type="revolute">
       <parent link="Link3"/>
       <child  link="Link4"/>
       <origin rpy="0 0 0" xyz="0.26636086493633027 0.0 0.3927286805068352" />
       <axis xyz="1 0 0"/>
       <limit effort="0.0" lower="-3.14159" upper="3.14159" velocity="0.0"/>
    </joint>
    <link name="Link4">
        <inertial>
            <origin xyz="0.0 0.0 0.20019281890541435" rpy="0 0 0"/>
            <mass value="0.49623295227953945" />
            <inertia ixx="100" ixy="0" ixz="0" iyy="100" iyz="0" izz="100" />
        </inertial>
        <visual>
            <origin xyz="0.0 0.0 0.20019281890541435" rpy="0 0 0"/>
            <geometry>
                <box size="1.0228853634255273 1.2116582544972534 0.4003856378108287" />
            </geometry>
            <material name="Sensor">
                <color rgba="0.239 0.875 0.282 1.0"/>
            </material>
        </visual>
        <collision>
            <origin xyz="0.0 0.0 0.20019281890541435" rpy="0 0 0"/>
            <geometry>
                <box size="1.0228853634255273 1.2116582544972534 0.4003856378108287" />
            </geometry>
        </collision>
    </link>
    <joint name="Link4_Link5" type="revolute">
       <parent link="Link4"/>
       <child  link="Link5"/>
       <origin rpy="0 0 0" xyz="0.0 -0.6058291272486267 0.20019281890541435" />
       <axis xyz="0 1 0"/>
       <limit effort="0.0" lower="-3.14159" upper="3.14159" velocity="0.0"/>
    </joint>
    <link name="Link5">
        <inertial>
            <origin xyz="0.0 -0.20637013008760752 0.0" rpy="0 0 0"/>
            <mass value="0.28918900110777174" />
            <inertia ixx="100" ixy="0" ixz="0" iyy="100" iyz="0" izz="100" />
        </inertial>
        <visual>
            <origin xyz="0.0 -0.20637013008760752 0.0" rpy="0 0 0"/>
            <geometry>
                <box size="0.6447901414439905 0.41274026017521503 1.0866421548115257" />
            </geometry>
            <material name="Sensor">
                <color rgba="0.239 0.875 0.282 1.0"/>
            </material>
        </visual>
        <collision>
            <origin xyz="0.0 -0.20637013008760752 0.0" rpy="0 0 0"/>
            <geometry>
                <box size="0.6447901414439905 0.41274026017521503 1.0866421548115257" />
            </geometry>
        </collision>
    </link>
    <joint name="Link5_Link6" type="revolute">
       <parent link="Link5"/>
       <child  link="Link6"/>
       <origin rpy="0 0 0" xyz="0.0 -0.41274026017521503 0.0" />
       <axis xyz="0 0 1"/>
       <limit effort="0.0" lower="-3.14159" upper="3.14159" velocity="0.0"/>
    </joint>
    <link name="Link6">
        <inertial>
            <origin xyz="0.0 -0.5531428608271833 0.0" rpy="0 0 0"/>
            <mass value="0.3669962970995349" />
            <inertia ixx="100" ixy="0" ixz="0" iyy="100" iyz="0" izz="100" />
        </inertial>
        <visual>
            <origin xyz="0.0 -0.5531428608271833 0.0" rpy="0 0 0"/>
            <geometry>
                <box size="0.33480241664150034 1.1062857216543667 0.9908451571254663" />
            </geometry>
            <material name="No Sensor">
                <color rgba="0.184 0.553 0.933 1.0"/>
            </material>
        </visual>
        <collision>
            <origin xyz="0.0 -0.5531428608271833 0.0" rpy="0 0 0"/>
            <geometry>
                <box size="0.33480241664150034 1.1062857216543667 0.9908451571254663" />
            </geometry>
        </collision>
    </link>
    <joint name="Link6_Link7" type="revolute">
       <parent link="Link6"/>
       <child  link="Link7"/>
       <origin rpy="0 0 0" xyz="0.0 -0.5531428608271833 -0.49542257856273314" />
       <axis xyz="1 0 0"/>
       <limit effort="0.0" lower="-3.14159" upper="3.14159" velocity="0.0"/>
    </joint>
    <link name="Link7">
        <inertial>
            <origin xyz="0.0 0.0 -0.20038832301740805" rpy="0 0 0"/>
            <mass value="0.5063473004801043" />
            <inertia ixx="100" ixy="0" ixz="0" iyy="100" iyz="0" izz="100" />
        </inertial>
        <visual>
            <origin xyz="0.0 0.0 -0.20038832301740805" rpy="0 0 0"/>
            <geometry>
                <box size="1.1083365084057961 1.1399202098221197 0.4007766460348161" />
            </geometry>
            <material name="No Sensor">
                <color rgba="0.184 0.553 0.933 1.0"/>
            </material>
        </visual>
        <collision>
            <origin xyz="0.0 0.0 -0.20038832301740805" rpy="0 0 0"/>
            <geometry>
                <box size="1.1083365084057961 1.1399202098221197 0.4007766460348161" />
            </geometry>
        </collision>
    </link>
    <joint name="Link7_Link8" type="revolute">
       <parent link="Link7"/>
       <child  link="Link8"/>
       <origin rpy="0 0 0" xyz="0.5541682542028981 0.0 -0.20038832301740805" />
       <axis xyz="1 0 0"/>
       <limit effort="0.0" lower="-3.14159" upper="3.14159" velocity="0.0"/>
    </joint>
    <link name="Link8">
        <inertial>
            <origin xyz="0.4033430221459675 0.0 0.0" rpy="0 0 0"/>
            <mass value="0.23231347610662817" />
            <inertia ixx="100" ixy="0" ixz="0" iyy="100" iyz="0" izz="100" />
        </inertial>
        <visual>
            <origin xyz="0.4033430221459675 0.0 0.0" rpy="0 0 0"/>
            <geometry>
                <box size="0.806686044291935 0.5525176099964864 0.5212231961231227" />
            </geometry>
            <material name="No Sensor">
                <color rgba="0.184 0.553 0.933 1.0"/>
            </material>
        </visual>
        <collision>
            <origin xyz="0.4033430221459675 0.0 0.0" rpy="0 0 0"/>
            <geometry>
                <box size="0.806686044291935 0.5525176099964864 0.5212231961231227" />
            </geometry>
        </collision>
    </link>
    <joint name="Link8_Link9" type="revolute">
       <parent link="Link8"/>
       <child  link="Link9"/>
       <origin rpy="0 0 0" xyz="0.806686044291935 0.0 0.0" />
       <axis xyz="0 0 1"/>
       <limit effort="0.0" lower="-3.14159" upper="3.14159" velocity="0.0"/>
    </joint>
    <link name="Link9">
        <inertial>
            <origin xyz="0.13321718779638742 0.0 0.0" rpy="0 0 0"/>
            <mass value="0.054851225127626226" />
            <inertia ixx="100" ixy="0" ixz="0" iyy="100" iyz="0" izz="100" />
        </inertial>
        <visual>
            <origin xyz="0.13321718779638742 0.0 0.0" rpy="0 0 0"/>
            <geometry>
                <box size="0.26643437559277483 0.765180771178199 0.26904939961756835" />
            </geometry>
            <material name="No Sensor">
                <color rgba="0.184 0.553 0.933 1.0"/>
            </material>
        </visual>
        <collision>
            <origin xyz="0.13321718779638742 0.0 0.0" rpy="0 0 0"/>
            <geometry>
                <box size="0.26643437559277483 0.765180771178199 0.26904939961756835" />
            </geometry>
        </collision>
    </link>
</robot>