<robot name = "robot">
    <link name="Link0">
        <inertial>
            <origin xyz="0 0 2" rpy="0 0 0"/>
            <mass value="0.17992568012272867" />
            <inertia ixx="100" ixy="0" ixz="0" iyy="100" iyz="0" izz="100" />
        </inertial>
        <visual>
            <origin xyz="0 0 2" rpy="0 0 0"/>
            <geometry>
                <box size="1.0770499529264703 0.45661973585883386 0.3658496369843246" />
            </geometry>
            <material name="No Sensor">
                <color rgba="0.184 0.553 0.933 1.0"/>
            </material>
        </visual>
        <collision>
            <origin xyz="0 0 2" rpy="0 0 0"/>
            <geometry>
                <box size="1.0770499529264703 0.45661973585883386 0.3658496369843246" />
            </geometry>
        </collision>
    </link>
    <joint name="Link0_Link1" type="revolute">
       <parent link="Link0"/>
       <child  link="Link1"/>
       <origin rpy="0 0 0" xyz="0.5385249764632352 0 2" />
       <axis xyz="0 1 0"/>
       <limit effort="0.0" lower="-3.14159" upper="3.14159" velocity="0.0"/>
    </joint>
    <link name="Link1">
        <inertial>
            <origin xyz="0.3539590847382555 0 0" rpy="0 0 0"/>
            <mass value="0.18947216165102634" />
            <inertia ixx="100" ixy="0" ixz="0" iyy="100" iyz="0" izz="100" />
        </inertial>
        <visual>
            <origin xyz="0.3539590847382555 0 0" rpy="0 0 0"/>
            <geometry>
                <box size="0.707918169476511 0.5386501754873054 0.4968846095366304" />
            </geometry>
            <material name="No Sensor">
                <color rgba="0.184 0.553 0.933 1.0"/>
            </material>
        </visual>
        <collision>
            <origin xyz="0.3539590847382555 0 0" rpy="0 0 0"/>
            <geometry>
                <box size="0.707918169476511 0.5386501754873054 0.4968846095366304" />
            </geometry>
        </collision>
    </link>
    <joint name="Link1_Link2" type="revolute">
       <parent link="Link1"/>
       <child  link="Link2"/>
       <origin rpy="0 0 0" xyz="0.707918169476511 0 0" />
       <axis xyz="0 1 0"/>
       <limit effort="0.0" lower="-3.14159" upper="3.14159" velocity="0.0"/>
    </joint>
    <link name="Link2">
        <inertial>
            <origin xyz="0.26977822532484097 0 0" rpy="0 0 0"/>
            <mass value="0.556231181917927" />
            <inertia ixx="100" ixy="0" ixz="0" iyy="100" iyz="0" izz="100" />
        </inertial>
        <visual>
            <origin xyz="0.26977822532484097 0 0" rpy="0 0 0"/>
            <geometry>
                <box size="0.5395564506496819 1.0465961175012644 0.9850070140034983" />
            </geometry>
            <material name="Sensor">
                <color rgba="0.239 0.875 0.282 1.0"/>
            </material>
        </visual>
        <collision>
            <origin xyz="0.26977822532484097 0 0" rpy="0 0 0"/>
            <geometry>
                <box size="0.5395564506496819 1.0465961175012644 0.9850070140034983" />
            </geometry>
        </collision>
    </link>
    <joint name="Link2_Link3" type="revolute">
       <parent link="Link2"/>
       <child  link="Link3"/>
       <origin rpy="0 0 0" xyz="0.5395564506496819 0 0" />
       <axis xyz="0 1 0"/>
       <limit effort="0.0" lower="-3.14159" upper="3.14159" velocity="0.0"/>
    </joint>
    <link name="Link3">
        <inertial>
            <origin xyz="0.2813299538924867 0 0" rpy="0 0 0"/>
            <mass value="0.06125189338723071" />
            <inertia ixx="100" ixy="0" ixz="0" iyy="100" iyz="0" izz="100" />
        </inertial>
        <visual>
            <origin xyz="0.2813299538924867 0 0" rpy="0 0 0"/>
            <geometry>
                <box size="0.5626599077849734 0.3874153060576846 0.2809938225484082" />
            </geometry>
            <material name="No Sensor">
                <color rgba="0.184 0.553 0.933 1.0"/>
            </material>
        </visual>
        <collision>
            <origin xyz="0.2813299538924867 0 0" rpy="0 0 0"/>
            <geometry>
                <box size="0.5626599077849734 0.3874153060576846 0.2809938225484082" />
            </geometry>
        </collision>
    </link>
    <joint name="Link3_Link4" type="revolute">
       <parent link="Link3"/>
       <child  link="Link4"/>
       <origin rpy="0 0 0" xyz="0.5626599077849734 0 0" />
       <axis xyz="0 1 0"/>
       <limit effort="0.0" lower="-3.14159" upper="3.14159" velocity="0.0"/>
    </joint>
    <link name="Link4">
        <inertial>
            <origin xyz="0.2110113506158477 0 0" rpy="0 0 0"/>
            <mass value="0.392512413416429" />
            <inertia ixx="100" ixy="0" ixz="0" iyy="100" iyz="0" izz="100" />
        </inertial>
        <visual>
            <origin xyz="0.2110113506158477 0 0" rpy="0 0 0"/>
            <geometry>
                <box size="0.4220227012316954 1.2192862726266467 0.7628021331154062" />
            </geometry>
            <material name="No Sensor">
                <color rgba="0.184 0.553 0.933 1.0"/>
            </material>
        </visual>
        <collision>
            <origin xyz="0.2110113506158477 0 0" rpy="0 0 0"/>
            <geometry>
                <box size="0.4220227012316954 1.2192862726266467 0.7628021331154062" />
            </geometry>
        </collision>
    </link>
    <joint name="Link4_Link5" type="revolute">
       <parent link="Link4"/>
       <child  link="Link5"/>
       <origin rpy="0 0 0" xyz="0.4220227012316954 0 0" />
       <axis xyz="0 1 0"/>
       <limit effort="0.0" lower="-3.14159" upper="3.14159" velocity="0.0"/>
    </joint>
    <link name="Link5">
        <inertial>
            <origin xyz="0.5600925331852753 0 0" rpy="0 0 0"/>
            <mass value="0.5020092248169797" />
            <inertia ixx="100" ixy="0" ixz="0" iyy="100" iyz="0" izz="100" />
        </inertial>
        <visual>
            <origin xyz="0.5600925331852753 0 0" rpy="0 0 0"/>
            <geometry>
                <box size="1.1201850663705506 0.8041939473134051 0.5572641681448881" />
            </geometry>
            <material name="No Sensor">
                <color rgba="0.184 0.553 0.933 1.0"/>
            </material>
        </visual>
        <collision>
            <origin xyz="0.5600925331852753 0 0" rpy="0 0 0"/>
            <geometry>
                <box size="1.1201850663705506 0.8041939473134051 0.5572641681448881" />
            </geometry>
        </collision>
    </link>
    <joint name="Link5_Link6" type="revolute">
       <parent link="Link5"/>
       <child  link="Link6"/>
       <origin rpy="0 0 0" xyz="1.1201850663705506 0 0" />
       <axis xyz="0 1 0"/>
       <limit effort="0.0" lower="-3.14159" upper="3.14159" velocity="0.0"/>
    </joint>
    <link name="Link6">
        <inertial>
            <origin xyz="0.4897549482254079 0 0" rpy="0 0 0"/>
            <mass value="0.23707409921134104" />
            <inertia ixx="100" ixy="0" ixz="0" iyy="100" iyz="0" izz="100" />
        </inertial>
        <visual>
            <origin xyz="0.4897549482254079 0 0" rpy="0 0 0"/>
            <geometry>
                <box size="0.9795098964508158 0.37575387189398235 0.6441274634964987" />
            </geometry>
            <material name="Sensor">
                <color rgba="0.239 0.875 0.282 1.0"/>
            </material>
        </visual>
        <collision>
            <origin xyz="0.4897549482254079 0 0" rpy="0 0 0"/>
            <geometry>
                <box size="0.9795098964508158 0.37575387189398235 0.6441274634964987" />
            </geometry>
        </collision>
    </link>
    <joint name="Link6_Link7" type="revolute">
       <parent link="Link6"/>
       <child  link="Link7"/>
       <origin rpy="0 0 0" xyz="0.9795098964508158 0 0" />
       <axis xyz="0 1 0"/>
       <limit effort="0.0" lower="-3.14159" upper="3.14159" velocity="0.0"/>
    </joint>
    <link name="Link7">
        <inertial>
            <origin xyz="0.556791664279942 0 0" rpy="0 0 0"/>
            <mass value="0.8550809426169802" />
            <inertia ixx="100" ixy="0" ixz="0" iyy="100" iyz="0" izz="100" />
        </inertial>
        <visual>
            <origin xyz="0.556791664279942 0 0" rpy="0 0 0"/>
            <geometry>
                <box size="1.113583328559884 0.6412291638681 1.1974881941358344" />
            </geometry>
            <material name="No Sensor">
                <color rgba="0.184 0.553 0.933 1.0"/>
            </material>
        </visual>
        <collision>
            <origin xyz="0.556791664279942 0 0" rpy="0 0 0"/>
            <geometry>
                <box size="1.113583328559884 0.6412291638681 1.1974881941358344" />
            </geometry>
        </collision>
    </link>
    <joint name="Link7_Link8" type="revolute">
       <parent link="Link7"/>
       <child  link="Link8"/>
       <origin rpy="0 0 0" xyz="1.113583328559884 0 0" />
       <axis xyz="0 1 0"/>
       <limit effort="0.0" lower="-3.14159" upper="3.14159" velocity="0.0"/>
    </joint>
    <link name="Link8">
        <inertial>
            <origin xyz="0.20059233863902376 0 0" rpy="0 0 0"/>
            <mass value="0.2934778089452228" />
            <inertia ixx="100" ixy="0" ixz="0" iyy="100" iyz="0" izz="100" />
        </inertial>
        <visual>
            <origin xyz="0.20059233863902376 0 0" rpy="0 0 0"/>
            <geometry>
                <box size="0.4011846772780475 1.018867087194433 0.7179817369440525" />
            </geometry>
            <material name="Sensor">
                <color rgba="0.239 0.875 0.282 1.0"/>
            </material>
        </visual>
        <collision>
            <origin xyz="0.20059233863902376 0 0" rpy="0 0 0"/>
            <geometry>
                <box size="0.4011846772780475 1.018867087194433 0.7179817369440525" />
            </geometry>
        </collision>
    </link>
    <joint name="Link8_Link9" type="revolute">
       <parent link="Link8"/>
       <child  link="Link9"/>
       <origin rpy="0 0 0" xyz="0.4011846772780475 0 0" />
       <axis xyz="0 1 0"/>
       <limit effort="0.0" lower="-3.14159" upper="3.14159" velocity="0.0"/>
    </joint>
    <link name="Link9">
        <inertial>
            <origin xyz="0.5281726735807172 0 0" rpy="0 0 0"/>
            <mass value="0.372522327501257" />
            <inertia ixx="100" ixy="0" ixz="0" iyy="100" iyz="0" izz="100" />
        </inertial>
        <visual>
            <origin xyz="0.5281726735807172 0 0" rpy="0 0 0"/>
            <geometry>
                <box size="1.0563453471614344 0.7882358126730648 0.4473940678202638" />
            </geometry>
            <material name="Sensor">
                <color rgba="0.239 0.875 0.282 1.0"/>
            </material>
        </visual>
        <collision>
            <origin xyz="0.5281726735807172 0 0" rpy="0 0 0"/>
            <geometry>
                <box size="1.0563453471614344 0.7882358126730648 0.4473940678202638" />
            </geometry>
        </collision>
    </link>
    <joint name="Link9_Link10" type="revolute">
       <parent link="Link9"/>
       <child  link="Link10"/>
       <origin rpy="0 0 0" xyz="1.0563453471614344 0 0" />
       <axis xyz="0 1 0"/>
       <limit effort="0.0" lower="-3.14159" upper="3.14159" velocity="0.0"/>
    </joint>
    <link name="Link10">
        <inertial>
            <origin xyz="0.6199081800682064 0 0" rpy="0 0 0"/>
            <mass value="0.3920641807174063" />
            <inertia ixx="100" ixy="0" ixz="0" iyy="100" iyz="0" izz="100" />
        </inertial>
        <visual>
            <origin xyz="0.6199081800682064 0 0" rpy="0 0 0"/>
            <geometry>
                <box size="1.2398163601364127 1.1891189610311694 0.26593438799682656" />
            </geometry>
            <material name="Sensor">
                <color rgba="0.239 0.875 0.282 1.0"/>
            </material>
        </visual>
        <collision>
            <origin xyz="0.6199081800682064 0 0" rpy="0 0 0"/>
            <geometry>
                <box size="1.2398163601364127 1.1891189610311694 0.26593438799682656" />
            </geometry>
        </collision>
    </link>
    <joint name="Link10_Link11" type="revolute">
       <parent link="Link10"/>
       <child  link="Link11"/>
       <origin rpy="0 0 0" xyz="1.2398163601364127 0 0" />
       <axis xyz="0 1 0"/>
       <limit effort="0.0" lower="-3.14159" upper="3.14159" velocity="0.0"/>
    </joint>
    <link name="Link11">
        <inertial>
            <origin xyz="0.6126953139673066 0 0" rpy="0 0 0"/>
            <mass value="0.4898981187686099" />
            <inertia ixx="100" ixy="0" ixz="0" iyy="100" iyz="0" izz="100" />
        </inertial>
        <visual>
            <origin xyz="0.6126953139673066 0 0" rpy="0 0 0"/>
            <geometry>
                <box size="1.2253906279346132 1.1148420034671513 0.35860628286243346" />
            </geometry>
            <material name="No Sensor">
                <color rgba="0.184 0.553 0.933 1.0"/>
            </material>
        </visual>
        <collision>
            <origin xyz="0.6126953139673066 0 0" rpy="0 0 0"/>
            <geometry>
                <box size="1.2253906279346132 1.1148420034671513 0.35860628286243346" />
            </geometry>
        </collision>
    </link>
</robot>