<robot name = "robot">
    <link name="Link0">
        <inertial>
            <origin xyz="0 0 2" rpy="0 0 0"/>
            <mass value="0.09736728915488231" />
            <inertia ixx="100" ixy="0" ixz="0" iyy="100" iyz="0" izz="100" />
        </inertial>
        <visual>
            <origin xyz="0 0 2" rpy="0 0 0"/>
            <geometry>
                <box size="0.4007843983721926 0.6193999256119063 0.39222125307278666" />
            </geometry>
            <material name="No Sensor">
                <color rgba="0.184 0.553 0.933 1.0"/>
            </material>
        </visual>
        <collision>
            <origin xyz="0 0 2" rpy="0 0 0"/>
            <geometry>
                <box size="0.4007843983721926 0.6193999256119063 0.39222125307278666" />
            </geometry>
        </collision>
    </link>
    <joint name="Link0_Link1" type="revolute">
       <parent link="Link0"/>
       <child  link="Link1"/>
       <origin rpy="0 0 0" xyz="0.2003921991860963 0 2" />
       <axis xyz="1 0 0"/>
       <limit effort="0.0" lower="-3.14159" upper="3.14159" velocity="0.0"/>
    </joint>
    <link name="Link1">
        <inertial>
            <origin xyz="0.4884468766722813 0 0" rpy="0 0 0"/>
            <mass value="0.49635385060748777" />
            <inertia ixx="100" ixy="0" ixz="0" iyy="100" iyz="0" izz="100" />
        </inertial>
        <visual>
            <origin xyz="0.4884468766722813 0 0" rpy="0 0 0"/>
            <geometry>
                <box size="0.9768937533445626 0.7270129944022632 0.6988788367067655" />
            </geometry>
            <material name="No Sensor">
                <color rgba="0.184 0.553 0.933 1.0"/>
            </material>
        </visual>
        <collision>
            <origin xyz="0.4884468766722813 0 0" rpy="0 0 0"/>
            <geometry>
                <box size="0.9768937533445626 0.7270129944022632 0.6988788367067655" />
            </geometry>
        </collision>
    </link>
    <joint name="Link1_Link2" type="revolute">
       <parent link="Link1"/>
       <child  link="Link2"/>
       <origin rpy="0 0 0" xyz="0.4884468766722813 0.0 -0.34943941835338277" />
       <axis xyz="1 0 0"/>
       <limit effort="0.0" lower="-3.14159" upper="3.14159" velocity="0.0"/>
    </joint>
    <link name="Link2">
        <inertial>
            <origin xyz="0.0 0.0 -0.32954541595842995" rpy="0 0 0"/>
            <mass value="0.5822232746195638" />
            <inertia ixx="100" ixy="0" ixz="0" iyy="100" iyz="0" izz="100" />
        </inertial>
        <visual>
            <origin xyz="0.0 0.0 -0.32954541595842995" rpy="0 0 0"/>
            <geometry>
                <box size="1.1359979711653514 0.7776187723115614 0.6590908319168599" />
            </geometry>
            <material name="Sensor">
                <color rgba="0.239 0.875 0.282 1.0"/>
            </material>
        </visual>
        <collision>
            <origin xyz="0.0 0.0 -0.32954541595842995" rpy="0 0 0"/>
            <geometry>
                <box size="1.1359979711653514 0.7776187723115614 0.6590908319168599" />
            </geometry>
        </collision>
    </link>
    <joint name="Link2_Link3" type="revolute">
       <parent link="Link2"/>
       <child  link="Link3"/>
       <origin rpy="0 0 0" xyz="0.0 0.3888093861557807 -0.32954541595842995" />
       <axis xyz="0 0 1"/>
       <limit effort="0.0" lower="-3.14159" upper="3.14159" velocity="0.0"/>
    </joint>
    <link name="Link3">
        <inertial>
            <origin xyz="0.0 0.16100601758488498 0.0" rpy="0 0 0"/>
            <mass value="0.11163851655168583" />
            <inertia ixx="100" ixy="0" ixz="0" iyy="100" iyz="0" izz="100" />
        </inertial>
        <visual>
            <origin xyz="0.0 0.16100601758488498 0.0" rpy="0 0 0"/>
            <geometry>
                <box size="0.5188920222126459 0.32201203516976995 0.6681361337253158" />
            </geometry>
            <material name="No Sensor">
                <color rgba="0.184 0.553 0.933 1.0"/>
            </material>
        </visual>
        <collision>
            <origin xyz="0.0 0.16100601758488498 0.0" rpy="0 0 0"/>
            <geometry>
                <box size="0.5188920222126459 0.32201203516976995 0.6681361337253158" />
            </geometry>
        </collision>
    </link>
    <joint name="Link3_Link4" type="revolute">
       <parent link="Link3"/>
       <child  link="Link4"/>
       <origin rpy="0 0 0" xyz="0.0 0.16100601758488498 0.3340680668626579" />
       <axis xyz="0 0 1"/>
       <limit effort="0.0" lower="-3.14159" upper="3.14159" velocity="0.0"/>
    </joint>
    <link name="Link4">
        <inertial>
            <origin xyz="0.0 0.0 0.37675475492419824" rpy="0 0 0"/>
            <mass value="0.11244251961964398" />
            <inertia ixx="100" ixy="0" ixz="0" iyy="100" iyz="0" izz="100" />
        </inertial>
        <visual>
            <origin xyz="0.0 0.0 0.37675475492419824" rpy="0 0 0"/>
            <geometry>
                <box size="0.2757534824065834 0.541153940552428 0.7535095098483965" />
            </geometry>
            <material name="Sensor">
                <color rgba="0.239 0.875 0.282 1.0"/>
            </material>
        </visual>
        <collision>
            <origin xyz="0.0 0.0 0.37675475492419824" rpy="0 0 0"/>
            <geometry>
                <box size="0.2757534824065834 0.541153940552428 0.7535095098483965" />
            </geometry>
        </collision>
    </link>
    <joint name="Link4_Link5" type="revolute">
       <parent link="Link4"/>
       <child  link="Link5"/>
       <origin rpy="0 0 0" xyz="0.0 0.270576970276214 0.37675475492419824" />
       <axis xyz="0 1 0"/>
       <limit effort="0.0" lower="-3.14159" upper="3.14159" velocity="0.0"/>
    </joint>
    <link name="Link5">
        <inertial>
            <origin xyz="0.0 0.1796914570967923 0.0" rpy="0 0 0"/>
            <mass value="0.40335561970673306" />
            <inertia ixx="100" ixy="0" ixz="0" iyy="100" iyz="0" izz="100" />
        </inertial>
        <visual>
            <origin xyz="0.0 0.1796914570967923 0.0" rpy="0 0 0"/>
            <geometry>
                <box size="1.2159330650197222 0.3593829141935846 0.923041054216622" />
            </geometry>
            <material name="Sensor">
                <color rgba="0.239 0.875 0.282 1.0"/>
            </material>
        </visual>
        <collision>
            <origin xyz="0.0 0.1796914570967923 0.0" rpy="0 0 0"/>
            <geometry>
                <box size="1.2159330650197222 0.3593829141935846 0.923041054216622" />
            </geometry>
        </collision>
    </link>
    <joint name="Link5_Link6" type="revolute">
       <parent link="Link5"/>
       <child  link="Link6"/>
       <origin rpy="0 0 0" xyz="0.0 0.3593829141935846 0.0" />
       <axis xyz="0 0 1"/>
       <limit effort="0.0" lower="-3.14159" upper="3.14159" velocity="0.0"/>
    </joint>
    <link name="Link6">
        <inertial>
            <origin xyz="0.0 0.5135491146378914 0.0" rpy="0 0 0"/>
            <mass value="0.3031774473683363" />
            <inertia ixx="100" ixy="0" ixz="0" iyy="100" iyz="0" izz="100" />
        </inertial>
        <visual>
            <origin xyz="0.0 0.5135491146378914 0.0" rpy="0 0 0"/>
            <geometry>
                <box size="0.7499323710992 1.0270982292757829 0.3936069978742093" />
            </geometry>
            <material name="Sensor">
                <color rgba="0.239 0.875 0.282 1.0"/>
            </material>
        </visual>
        <collision>
            <origin xyz="0.0 0.5135491146378914 0.0" rpy="0 0 0"/>
            <geometry>
                <box size="0.7499323710992 1.0270982292757829 0.3936069978742093" />
            </geometry>
        </collision>
    </link>
    <joint name="Link6_Link7" type="revolute">
       <parent link="Link6"/>
       <child  link="Link7"/>
       <origin rpy="0 0 0" xyz="0.0 0.5135491146378914 0.19680349893710464" />
       <axis xyz="0 0 1"/>
       <limit effort="0.0" lower="-3.14159" upper="3.14159" velocity="0.0"/>
    </joint>
    <link name="Link7">
        <inertial>
            <origin xyz="0.0 0.0 0.5234811259899501" rpy="0 0 0"/>
            <mass value="0.22648028871751005" />
            <inertia ixx="100" ixy="0" ixz="0" iyy="100" iyz="0" izz="100" />
        </inertial>
        <visual>
            <origin xyz="0.0 0.0 0.5234811259899501" rpy="0 0 0"/>
            <geometry>
                <box size="0.33320263643587555 0.6492186053524538 1.0469622519799002" />
            </geometry>
            <material name="Sensor">
                <color rgba="0.239 0.875 0.282 1.0"/>
            </material>
        </visual>
        <collision>
            <origin xyz="0.0 0.0 0.5234811259899501" rpy="0 0 0"/>
            <geometry>
                <box size="0.33320263643587555 0.6492186053524538 1.0469622519799002" />
            </geometry>
        </collision>
    </link>
    <joint name="Link7_Link8" type="revolute">
       <parent link="Link7"/>
       <child  link="Link8"/>
       <origin rpy="0 0 0" xyz="-0.16660131821793778 0.0 0.5234811259899501" />
       <axis xyz="0 0 1"/>
       <limit effort="0.0" lower="-3.14159" upper="3.14159" velocity="0.0"/>
    </joint>
    <link name="Link8">
        <inertial>
            <origin xyz="-0.22083786945494505 0.0 0.0" rpy="0 0 0"/>
            <mass value="0.24287880430138983" />
            <inertia ixx="100" ixy="0" ixz="0" iyy="100" iyz="0" izz="100" />
        </inertial>
        <visual>
            <origin xyz="-0.22083786945494505 0.0 0.0" rpy="0 0 0"/>
            <geometry>
                <box size="0.4416757389098901 1.017777192147274 0.5402979970618682" />
            </geometry>
            <material name="No Sensor">
                <color rgba="0.184 0.553 0.933 1.0"/>
            </material>
        </visual>
        <collision>
            <origin xyz="-0.22083786945494505 0.0 0.0" rpy="0 0 0"/>
            <geometry>
                <box size="0.4416757389098901 1.017777192147274 0.5402979970618682" />
            </geometry>
        </collision>
    </link>
    <joint name="Link8_Link9" type="revolute">
       <parent link="Link8"/>
       <child  link="Link9"/>
       <origin rpy="0 0 0" xyz="-0.22083786945494505 0.0 -0.2701489985309341" />
       <axis xyz="0 1 0"/>
       <limit effort="0.0" lower="-3.14159" upper="3.14159" velocity="0.0"/>
    </joint>
    <link name="Link9">
        <inertial>
            <origin xyz="0.0 0.0 -0.32432952996118936" rpy="0 0 0"/>
            <mass value="0.08077572123532749" />
            <inertia ixx="100" ixy="0" ixz="0" iyy="100" iyz="0" izz="100" />
        </inertial>
        <visual>
            <origin xyz="0.0 0.0 -0.32432952996118936" rpy="0 0 0"/>
            <geometry>
                <box size="0.46689148761179533 0.26671558907700643 0.6486590599223787" />
            </geometry>
            <material name="No Sensor">
                <color rgba="0.184 0.553 0.933 1.0"/>
            </material>
        </visual>
        <collision>
            <origin xyz="0.0 0.0 -0.32432952996118936" rpy="0 0 0"/>
            <geometry>
                <box size="0.46689148761179533 0.26671558907700643 0.6486590599223787" />
            </geometry>
        </collision>
    </link>
</robot>