<robot name = "robot">
    <link name="Link0">
        <inertial>
            <origin xyz="0 0 2" rpy="0 0 0"/>
            <mass value="0.18839090380199583" />
            <inertia ixx="100" ixy="0" ixz="0" iyy="100" iyz="0" izz="100" />
        </inertial>
        <visual>
            <origin xyz="0 0 2" rpy="0 0 0"/>
            <geometry>
                <box size="0.8934625222408049 0.2954982160406038 0.7135570909517118" />
            </geometry>
            <material name="No Sensor">
                <color rgba="0.184 0.553 0.933 1.0"/>
            </material>
        </visual>
        <collision>
            <origin xyz="0 0 2" rpy="0 0 0"/>
            <geometry>
                <box size="0.8934625222408049 0.2954982160406038 0.7135570909517118" />
            </geometry>
        </collision>
    </link>
    <joint name="Link0_Link1" type="revolute">
       <parent link="Link0"/>
       <child  link="Link1"/>
       <origin rpy="0 0 0" xyz="0.44673126112040246 0 2" />
       <axis xyz="1 0 0"/>
       <limit effort="0.0" lower="-3.14159" upper="3.14159" velocity="0.0"/>
    </joint>
    <link name="Link1">
        <inertial>
            <origin xyz="0.2923756718568319 0 0" rpy="0 0 0"/>
            <mass value="0.24458313612755814" />
            <inertia ixx="100" ixy="0" ixz="0" iyy="100" iyz="0" izz="100" />
        </inertial>
        <visual>
            <origin xyz="0.2923756718568319 0 0" rpy="0 0 0"/>
            <geometry>
                <box size="0.5847513437136638 0.7821815485216747 0.5347462086131314" />
            </geometry>
            <material name="Sensor">
                <color rgba="0.239 0.875 0.282 1.0"/>
            </material>
        </visual>
        <collision>
            <origin xyz="0.2923756718568319 0 0" rpy="0 0 0"/>
            <geometry>
                <box size="0.5847513437136638 0.7821815485216747 0.5347462086131314" />
            </geometry>
        </collision>
    </link>
    <joint name="Link1_Link2" type="revolute">
       <parent link="Link1"/>
       <child  link="Link2"/>
       <origin rpy="0 0 0" xyz="0.2923756718568319 0.0 0.2673731043065657" />
       <axis xyz="0 0 1"/>
       <limit effort="0.0" lower="-3.14159" upper="3.14159" velocity="0.0"/>
    </joint>
    <link name="Link2">
        <inertial>
            <origin xyz="0.0 0.0 0.46567987744565315" rpy="0 0 0"/>
            <mass value="0.31837917467269583" />
            <inertia ixx="100" ixy="0" ixz="0" iyy="100" iyz="0" izz="100" />
        </inertial>
        <visual>
            <origin xyz="0.0 0.0 0.46567987744565315" rpy="0 0 0"/>
            <geometry>
                <box size="0.3722612302300028 0.9182889887508018 0.9313597548913063" />
            </geometry>
            <material name="No Sensor">
                <color rgba="0.184 0.553 0.933 1.0"/>
            </material>
        </visual>
        <collision>
            <origin xyz="0.0 0.0 0.46567987744565315" rpy="0 0 0"/>
            <geometry>
                <box size="0.3722612302300028 0.9182889887508018 0.9313597548913063" />
            </geometry>
        </collision>
    </link>
    <joint name="Link2_Link3" type="revolute">
       <parent link="Link2"/>
       <child  link="Link3"/>
       <origin rpy="0 0 0" xyz="0.0 0.4591444943754009 0.46567987744565315" />
       <axis xyz="1 0 0"/>
       <limit effort="0.0" lower="-3.14159" upper="3.14159" velocity="0.0"/>
    </joint>
    <link name="Link3">
        <inertial>
            <origin xyz="0.0 0.19119074678136871 0.0" rpy="0 0 0"/>
            <mass value="0.4479426961582286" />
            <inertia ixx="100" ixy="0" ixz="0" iyy="100" iyz="0" izz="100" />
        </inertial>
        <visual>
            <origin xyz="0.0 0.19119074678136871 0.0" rpy="0 0 0"/>
            <geometry>
                <box size="1.1171392999990886 0.38238149356273743 1.048620308278031" />
            </geometry>
            <material name="Sensor">
                <color rgba="0.239 0.875 0.282 1.0"/>
            </material>
        </visual>
        <collision>
            <origin xyz="0.0 0.19119074678136871 0.0" rpy="0 0 0"/>
            <geometry>
                <box size="1.1171392999990886 0.38238149356273743 1.048620308278031" />
            </geometry>
        </collision>
    </link>
    <joint name="Link3_Link4" type="revolute">
       <parent link="Link3"/>
       <child  link="Link4"/>
       <origin rpy="0 0 0" xyz="-0.5585696499995443 0.19119074678136871 0.0" />
       <axis xyz="1 0 0"/>
       <limit effort="0.0" lower="-3.14159" upper="3.14159" velocity="0.0"/>
    </joint>
    <link name="Link4">
        <inertial>
            <origin xyz="-0.5383843692025645 0.0 0.0" rpy="0 0 0"/>
            <mass value="0.4391713505040554" />
            <inertia ixx="100" ixy="0" ixz="0" iyy="100" iyz="0" izz="100" />
        </inertial>
        <visual>
            <origin xyz="-0.5383843692025645 0.0 0.0" rpy="0 0 0"/>
            <geometry>
                <box size="1.076768738405129 0.8965499357511519 0.45492214578063384" />
            </geometry>
            <material name="Sensor">
                <color rgba="0.239 0.875 0.282 1.0"/>
            </material>
        </visual>
        <collision>
            <origin xyz="-0.5383843692025645 0.0 0.0" rpy="0 0 0"/>
            <geometry>
                <box size="1.076768738405129 0.8965499357511519 0.45492214578063384" />
            </geometry>
        </collision>
    </link>
    <joint name="Link4_Link5" type="revolute">
       <parent link="Link4"/>
       <child  link="Link5"/>
       <origin rpy="0 0 0" xyz="-0.5383843692025645 0.0 -0.22746107289031692" />
       <axis xyz="1 0 0"/>
       <limit effort="0.0" lower="-3.14159" upper="3.14159" velocity="0.0"/>
    </joint>
    <link name="Link5">
        <inertial>
            <origin xyz="0.0 0.0 -0.39589953639136566" rpy="0 0 0"/>
            <mass value="0.2707027374191666" />
            <inertia ixx="100" ixy="0" ixz="0" iyy="100" iyz="0" izz="100" />
        </inertial>
        <visual>
            <origin xyz="0.0 0.0 -0.39589953639136566" rpy="0 0 0"/>
            <geometry>
                <box size="0.5114207144058379 0.6684968175391757 0.7917990727827313" />
            </geometry>
            <material name="Sensor">
                <color rgba="0.239 0.875 0.282 1.0"/>
            </material>
        </visual>
        <collision>
            <origin xyz="0.0 0.0 -0.39589953639136566" rpy="0 0 0"/>
            <geometry>
                <box size="0.5114207144058379 0.6684968175391757 0.7917990727827313" />
            </geometry>
        </collision>
    </link>
    <joint name="Link5_Link6" type="revolute">
       <parent link="Link5"/>
       <child  link="Link6"/>
       <origin rpy="0 0 0" xyz="-0.25571035720291896 0.0 -0.39589953639136566" />
       <axis xyz="0 0 1"/>
       <limit effort="0.0" lower="-3.14159" upper="3.14159" velocity="0.0"/>
    </joint>
    <link name="Link6">
        <inertial>
            <origin xyz="-0.3637189777961085 0.0 0.0" rpy="0 0 0"/>
            <mass value="0.5687961026752923" />
            <inertia ixx="100" ixy="0" ixz="0" iyy="100" iyz="0" izz="100" />
        </inertial>
        <visual>
            <origin xyz="-0.3637189777961085 0.0 0.0" rpy="0 0 0"/>
            <geometry>
                <box size="0.727437955592217 0.7174598920453694 1.0898407101976675" />
            </geometry>
            <material name="Sensor">
                <color rgba="0.239 0.875 0.282 1.0"/>
            </material>
        </visual>
        <collision>
            <origin xyz="-0.3637189777961085 0.0 0.0" rpy="0 0 0"/>
            <geometry>
                <box size="0.727437955592217 0.7174598920453694 1.0898407101976675" />
            </geometry>
        </collision>
    </link>
    <joint name="Link6_Link7" type="revolute">
       <parent link="Link6"/>
       <child  link="Link7"/>
       <origin rpy="0 0 0" xyz="-0.3637189777961085 -0.3587299460226847 0.0" />
       <axis xyz="0 0 1"/>
       <limit effort="0.0" lower="-3.14159" upper="3.14159" velocity="0.0"/>
    </joint>
    <link name="Link7">
        <inertial>
            <origin xyz="0.0 -0.5333769821883834 0.0" rpy="0 0 0"/>
            <mass value="1.347580184814661" />
            <inertia ixx="100" ixy="0" ixz="0" iyy="100" iyz="0" izz="100" />
        </inertial>
        <visual>
            <origin xyz="0.0 -0.5333769821883834 0.0" rpy="0 0 0"/>
            <geometry>
                <box size="1.1201023653075677 1.0667539643767667 1.1278014186346996" />
            </geometry>
            <material name="No Sensor">
                <color rgba="0.184 0.553 0.933 1.0"/>
            </material>
        </visual>
        <collision>
            <origin xyz="0.0 -0.5333769821883834 0.0" rpy="0 0 0"/>
            <geometry>
                <box size="1.1201023653075677 1.0667539643767667 1.1278014186346996" />
            </geometry>
        </collision>
    </link>
    <joint name="Link7_Link8" type="revolute">
       <parent link="Link7"/>
       <child  link="Link8"/>
       <origin rpy="0 0 0" xyz="-0.5600511826537838 -0.5333769821883834 0.0" />
       <axis xyz="0 1 0"/>
       <limit effort="0.0" lower="-3.14159" upper="3.14159" velocity="0.0"/>
    </joint>
    <link name="Link8">
        <inertial>
            <origin xyz="-0.41050438096853653 0.0 0.0" rpy="0 0 0"/>
            <mass value="0.8537471337532289" />
            <inertia ixx="100" ixy="0" ixz="0" iyy="100" iyz="0" izz="100" />
        </inertial>
        <visual>
            <origin xyz="-0.41050438096853653 0.0 0.0" rpy="0 0 0"/>
            <geometry>
                <box size="0.8210087619370731 1.2140361333390817 0.8565443482504677" />
            </geometry>
            <material name="No Sensor">
                <color rgba="0.184 0.553 0.933 1.0"/>
            </material>
        </visual>
        <collision>
            <origin xyz="-0.41050438096853653 0.0 0.0" rpy="0 0 0"/>
            <geometry>
                <box size="0.8210087619370731 1.2140361333390817 0.8565443482504677" />
            </geometry>
        </collision>
    </link>
    <joint name="Link8_Link9" type="revolute">
       <parent link="Link8"/>
       <child  link="Link9"/>
       <origin rpy="0 0 0" xyz="-0.41050438096853653 -0.6070180666695408 0.0" />
       <axis xyz="1 0 0"/>
       <limit effort="0.0" lower="-3.14159" upper="3.14159" velocity="0.0"/>
    </joint>
    <link name="Link9">
        <inertial>
            <origin xyz="0.0 -0.2846488685373094 0.0" rpy="0 0 0"/>
            <mass value="0.4527053951468222" />
            <inertia ixx="100" ixy="0" ixz="0" iyy="100" iyz="0" izz="100" />
        </inertial>
        <visual>
            <origin xyz="0.0 -0.2846488685373094 0.0" rpy="0 0 0"/>
            <geometry>
                <box size="0.8539477410796814 0.5692977370746188 0.931204184117019" />
            </geometry>
            <material name="No Sensor">
                <color rgba="0.184 0.553 0.933 1.0"/>
            </material>
        </visual>
        <collision>
            <origin xyz="0.0 -0.2846488685373094 0.0" rpy="0 0 0"/>
            <geometry>
                <box size="0.8539477410796814 0.5692977370746188 0.931204184117019" />
            </geometry>
        </collision>
    </link>
</robot>