<robot name = "robot">
    <link name="Link0">
        <inertial>
            <origin xyz="0 0 2" rpy="0 0 0"/>
            <mass value="0.20307946769570936" />
            <inertia ixx="100" ixy="0" ixz="0" iyy="100" iyz="0" izz="100" />
        </inertial>
        <visual>
            <origin xyz="0 0 2" rpy="0 0 0"/>
            <geometry>
                <box size="0.37425924362545104 0.6545826515221878 0.8289512482609072" />
            </geometry>
            <material name="Sensor">
                <color rgba="0.239 0.875 0.282 1.0"/>
            </material>
        </visual>
        <collision>
            <origin xyz="0 0 2" rpy="0 0 0"/>
            <geometry>
                <box size="0.37425924362545104 0.6545826515221878 0.8289512482609072" />
            </geometry>
        </collision>
    </link>
    <joint name="Link0_Link1" type="revolute">
       <parent link="Link0"/>
       <child  link="Link1"/>
       <origin rpy="0 0 0" xyz="0.18712962181272552 0 2" />
       <axis xyz="1 0 0"/>
       <limit effort="0.0" lower="-3.14159" upper="3.14159" velocity="0.0"/>
    </joint>
    <link name="Link1">
        <inertial>
            <origin xyz="0.4264221829095663 0 0" rpy="0 0 0"/>
            <mass value="0.4703519347160949" />
            <inertia ixx="100" ixy="0" ixz="0" iyy="100" iyz="0" izz="100" />
        </inertial>
        <visual>
            <origin xyz="0.4264221829095663 0 0" rpy="0 0 0"/>
            <geometry>
                <box size="0.8528443658191326 1.2107778367838566 0.4555003210755252" />
            </geometry>
            <material name="No Sensor">
                <color rgba="0.184 0.553 0.933 1.0"/>
            </material>
        </visual>
        <collision>
            <origin xyz="0.4264221829095663 0 0" rpy="0 0 0"/>
            <geometry>
                <box size="0.8528443658191326 1.2107778367838566 0.4555003210755252" />
            </geometry>
        </collision>
    </link>
    <joint name="Link1_Link2" type="revolute">
       <parent link="Link1"/>
       <child  link="Link2"/>
       <origin rpy="0 0 0" xyz="0.4264221829095663 0.6053889183919283 0.0" />
       <axis xyz="0 0 1"/>
       <limit effort="0.0" lower="-3.14159" upper="3.14159" velocity="0.0"/>
    </joint>
    <link name="Link2">
        <inertial>
            <origin xyz="0.0 0.2532145703307252 0.0" rpy="0 0 0"/>
            <mass value="0.30880381077897284" />
            <inertia ixx="100" ixy="0" ixz="0" iyy="100" iyz="0" izz="100" />
        </inertial>
        <visual>
            <origin xyz="0.0 0.2532145703307252 0.0" rpy="0 0 0"/>
            <geometry>
                <box size="0.9131513275630005 0.5064291406614504 0.667761242510447" />
            </geometry>
            <material name="No Sensor">
                <color rgba="0.184 0.553 0.933 1.0"/>
            </material>
        </visual>
        <collision>
            <origin xyz="0.0 0.2532145703307252 0.0" rpy="0 0 0"/>
            <geometry>
                <box size="0.9131513275630005 0.5064291406614504 0.667761242510447" />
            </geometry>
        </collision>
    </link>
    <joint name="Link2_Link3" type="revolute">
       <parent link="Link2"/>
       <child  link="Link3"/>
       <origin rpy="0 0 0" xyz="0.0 0.2532145703307252 -0.3338806212552235" />
       <axis xyz="1 0 0"/>
       <limit effort="0.0" lower="-3.14159" upper="3.14159" velocity="0.0"/>
    </joint>
    <link name="Link3">
        <inertial>
            <origin xyz="0.0 0.0 -0.30601158268777007" rpy="0 0 0"/>
            <mass value="0.43456572344202643" />
            <inertia ixx="100" ixy="0" ixz="0" iyy="100" iyz="0" izz="100" />
        </inertial>
        <visual>
            <origin xyz="0.0 0.0 -0.30601158268777007" rpy="0 0 0"/>
            <geometry>
                <box size="1.221950462109533 0.5810774305910541 0.6120231653755401" />
            </geometry>
            <material name="Sensor">
                <color rgba="0.239 0.875 0.282 1.0"/>
            </material>
        </visual>
        <collision>
            <origin xyz="0.0 0.0 -0.30601158268777007" rpy="0 0 0"/>
            <geometry>
                <box size="1.221950462109533 0.5810774305910541 0.6120231653755401" />
            </geometry>
        </collision>
    </link>
    <joint name="Link3_Link4" type="revolute">
       <parent link="Link3"/>
       <child  link="Link4"/>
       <origin rpy="0 0 0" xyz="0.0 0.0 -0.6120231653755401" />
       <axis xyz="0 1 0"/>
       <limit effort="0.0" lower="-3.14159" upper="3.14159" velocity="0.0"/>
    </joint>
    <link name="Link4">
        <inertial>
            <origin xyz="0.0 0.0 -0.3242851192522141" rpy="0 0 0"/>
            <mass value="0.1299963942531489" />
            <inertia ixx="100" ixy="0" ixz="0" iyy="100" iyz="0" izz="100" />
        </inertial>
        <visual>
            <origin xyz="0.0 0.0 -0.3242851192522141" rpy="0 0 0"/>
            <geometry>
                <box size="0.6895684484649433 0.29066778988915665 0.6485702385044282" />
            </geometry>
            <material name="Sensor">
                <color rgba="0.239 0.875 0.282 1.0"/>
            </material>
        </visual>
        <collision>
            <origin xyz="0.0 0.0 -0.3242851192522141" rpy="0 0 0"/>
            <geometry>
                <box size="0.6895684484649433 0.29066778988915665 0.6485702385044282" />
            </geometry>
        </collision>
    </link>
    <joint name="Link4_Link5" type="revolute">
       <parent link="Link4"/>
       <child  link="Link5"/>
       <origin rpy="0 0 0" xyz="0.0 -0.14533389494457832 -0.3242851192522141" />
       <axis xyz="0 0 1"/>
       <limit effort="0.0" lower="-3.14159" upper="3.14159" velocity="0.0"/>
    </joint>
    <link name="Link5">
        <inertial>
            <origin xyz="0.0 -0.41403999342511666 0.0" rpy="0 0 0"/>
            <mass value="0.8083956321610509" />
            <inertia ixx="100" ixy="0" ixz="0" iyy="100" iyz="0" izz="100" />
        </inertial>
        <visual>
            <origin xyz="0.0 -0.41403999342511666 0.0" rpy="0 0 0"/>
            <geometry>
                <box size="0.8689850995707687 0.8280799868502333 1.1234127277887769" />
            </geometry>
            <material name="Sensor">
                <color rgba="0.239 0.875 0.282 1.0"/>
            </material>
        </visual>
        <collision>
            <origin xyz="0.0 -0.41403999342511666 0.0" rpy="0 0 0"/>
            <geometry>
                <box size="0.8689850995707687 0.8280799868502333 1.1234127277887769" />
            </geometry>
        </collision>
    </link>
    <joint name="Link5_Link6" type="revolute">
       <parent link="Link5"/>
       <child  link="Link6"/>
       <origin rpy="0 0 0" xyz="0.4344925497853844 -0.41403999342511666 0.0" />
       <axis xyz="1 0 0"/>
       <limit effort="0.0" lower="-3.14159" upper="3.14159" velocity="0.0"/>
    </joint>
    <link name="Link6">
        <inertial>
            <origin xyz="0.44559327890758843 0.0 0.0" rpy="0 0 0"/>
            <mass value="0.6405073805782511" />
            <inertia ixx="100" ixy="0" ixz="0" iyy="100" iyz="0" izz="100" />
        </inertial>
        <visual>
            <origin xyz="0.44559327890758843 0.0 0.0" rpy="0 0 0"/>
            <geometry>
                <box size="0.8911865578151769 0.806955944679331 0.8906471570721031" />
            </geometry>
            <material name="Sensor">
                <color rgba="0.239 0.875 0.282 1.0"/>
            </material>
        </visual>
        <collision>
            <origin xyz="0.44559327890758843 0.0 0.0" rpy="0 0 0"/>
            <geometry>
                <box size="0.8911865578151769 0.806955944679331 0.8906471570721031" />
            </geometry>
        </collision>
    </link>
    <joint name="Link6_Link7" type="revolute">
       <parent link="Link6"/>
       <child  link="Link7"/>
       <origin rpy="0 0 0" xyz="0.8911865578151769 0.0 0.0" />
       <axis xyz="1 0 0"/>
       <limit effort="0.0" lower="-3.14159" upper="3.14159" velocity="0.0"/>
    </joint>
    <link name="Link7">
        <inertial>
            <origin xyz="0.1488083917053195 0.0 0.0" rpy="0 0 0"/>
            <mass value="0.14897913347993014" />
            <inertia ixx="100" ixy="0" ixz="0" iyy="100" iyz="0" izz="100" />
        </inertial>
        <visual>
            <origin xyz="0.1488083917053195 0.0 0.0" rpy="0 0 0"/>
            <geometry>
                <box size="0.297616783410639 1.2461213485585052 0.40170541761946676" />
            </geometry>
            <material name="No Sensor">
                <color rgba="0.184 0.553 0.933 1.0"/>
            </material>
        </visual>
        <collision>
            <origin xyz="0.1488083917053195 0.0 0.0" rpy="0 0 0"/>
            <geometry>
                <box size="0.297616783410639 1.2461213485585052 0.40170541761946676" />
            </geometry>
        </collision>
    </link>
    <joint name="Link7_Link8" type="revolute">
       <parent link="Link7"/>
       <child  link="Link8"/>
       <origin rpy="0 0 0" xyz="0.297616783410639 0.0 0.0" />
       <axis xyz="0 0 1"/>
       <limit effort="0.0" lower="-3.14159" upper="3.14159" velocity="0.0"/>
    </joint>
    <link name="Link8">
        <inertial>
            <origin xyz="0.3342234433677131 0.0 0.0" rpy="0 0 0"/>
            <mass value="0.3014971044008327" />
            <inertia ixx="100" ixy="0" ixz="0" iyy="100" iyz="0" izz="100" />
        </inertial>
        <visual>
            <origin xyz="0.3342234433677131 0.0 0.0" rpy="0 0 0"/>
            <geometry>
                <box size="0.6684468867354262 0.5452514701436912 0.8272168940956345" />
            </geometry>
            <material name="No Sensor">
                <color rgba="0.184 0.553 0.933 1.0"/>
            </material>
        </visual>
        <collision>
            <origin xyz="0.3342234433677131 0.0 0.0" rpy="0 0 0"/>
            <geometry>
                <box size="0.6684468867354262 0.5452514701436912 0.8272168940956345" />
            </geometry>
        </collision>
    </link>
    <joint name="Link8_Link9" type="revolute">
       <parent link="Link8"/>
       <child  link="Link9"/>
       <origin rpy="0 0 0" xyz="0.6684468867354262 0.0 0.0" />
       <axis xyz="0 1 0"/>
       <limit effort="0.0" lower="-3.14159" upper="3.14159" velocity="0.0"/>
    </joint>
    <link name="Link9">
        <inertial>
            <origin xyz="0.4047805117238076 0.0 0.0" rpy="0 0 0"/>
            <mass value="0.5964560880738885" />
            <inertia ixx="100" ixy="0" ixz="0" iyy="100" iyz="0" izz="100" />
        </inertial>
        <visual>
            <origin xyz="0.4047805117238076 0.0 0.0" rpy="0 0 0"/>
            <geometry>
                <box size="0.8095610234476152 0.6021143242597727 1.22362946398106" />
            </geometry>
            <material name="No Sensor">
                <color rgba="0.184 0.553 0.933 1.0"/>
            </material>
        </visual>
        <collision>
            <origin xyz="0.4047805117238076 0.0 0.0" rpy="0 0 0"/>
            <geometry>
                <box size="0.8095610234476152 0.6021143242597727 1.22362946398106" />
            </geometry>
        </collision>
    </link>
</robot>