<robot name = "robot">
    <link name="Link0">
        <inertial>
            <origin xyz="0 0 2" rpy="0 0 0"/>
            <mass value="0.3758313615820647" />
            <inertia ixx="100" ixy="0" ixz="0" iyy="100" iyz="0" izz="100" />
        </inertial>
        <visual>
            <origin xyz="0 0 2" rpy="0 0 0"/>
            <geometry>
                <box size="1.1311683184289048 0.3760784803971985 0.8834608342357256" />
            </geometry>
            <material name="No Sensor">
                <color rgba="0.184 0.553 0.933 1.0"/>
            </material>
        </visual>
        <collision>
            <origin xyz="0 0 2" rpy="0 0 0"/>
            <geometry>
                <box size="1.1311683184289048 0.3760784803971985 0.8834608342357256" />
            </geometry>
        </collision>
    </link>
    <joint name="Link0_Link1" type="revolute">
       <parent link="Link0"/>
       <child  link="Link1"/>
       <origin rpy="0 0 0" xyz="0.5655841592144524 0 2" />
       <axis xyz="1 0 0"/>
       <limit effort="0.0" lower="-3.14159" upper="3.14159" velocity="0.0"/>
    </joint>
    <link name="Link1">
        <inertial>
            <origin xyz="0.2638563662367121 0 0" rpy="0 0 0"/>
            <mass value="0.34932728375952926" />
            <inertia ixx="100" ixy="0" ixz="0" iyy="100" iyz="0" izz="100" />
        </inertial>
        <visual>
            <origin xyz="0.2638563662367121 0 0" rpy="0 0 0"/>
            <geometry>
                <box size="0.5277127324734242 1.077200325139306 0.6145234475558883" />
            </geometry>
            <material name="No Sensor">
                <color rgba="0.184 0.553 0.933 1.0"/>
            </material>
        </visual>
        <collision>
            <origin xyz="0.2638563662367121 0 0" rpy="0 0 0"/>
            <geometry>
                <box size="0.5277127324734242 1.077200325139306 0.6145234475558883" />
            </geometry>
        </collision>
    </link>
    <joint name="Link1_Link2" type="revolute">
       <parent link="Link1"/>
       <child  link="Link2"/>
       <origin rpy="0 0 0" xyz="0.2638563662367121 -0.538600162569653 0.0" />
       <axis xyz="0 0 1"/>
       <limit effort="0.0" lower="-3.14159" upper="3.14159" velocity="0.0"/>
    </joint>
    <link name="Link2">
        <inertial>
            <origin xyz="0.0 -0.2212089452068694 0.0" rpy="0 0 0"/>
            <mass value="0.318221940085156" />
            <inertia ixx="100" ixy="0" ixz="0" iyy="100" iyz="0" izz="100" />
        </inertial>
        <visual>
            <origin xyz="0.0 -0.2212089452068694 0.0" rpy="0 0 0"/>
            <geometry>
                <box size="0.983366094468834 0.4424178904137388 0.7314458975407394" />
            </geometry>
            <material name="No Sensor">
                <color rgba="0.184 0.553 0.933 1.0"/>
            </material>
        </visual>
        <collision>
            <origin xyz="0.0 -0.2212089452068694 0.0" rpy="0 0 0"/>
            <geometry>
                <box size="0.983366094468834 0.4424178904137388 0.7314458975407394" />
            </geometry>
        </collision>
    </link>
    <joint name="Link2_Link3" type="revolute">
       <parent link="Link2"/>
       <child  link="Link3"/>
       <origin rpy="0 0 0" xyz="0.0 -0.2212089452068694 -0.3657229487703697" />
       <axis xyz="0 1 0"/>
       <limit effort="0.0" lower="-3.14159" upper="3.14159" velocity="0.0"/>
    </joint>
    <link name="Link3">
        <inertial>
            <origin xyz="0.0 0.0 -0.20578701992804493" rpy="0 0 0"/>
            <mass value="0.28055491951235834" />
            <inertia ixx="100" ixy="0" ixz="0" iyy="100" iyz="0" izz="100" />
        </inertial>
        <visual>
            <origin xyz="0.0 0.0 -0.20578701992804493" rpy="0 0 0"/>
            <geometry>
                <box size="1.0535946264310272 0.646988211672374 0.41157403985608987" />
            </geometry>
            <material name="Sensor">
                <color rgba="0.239 0.875 0.282 1.0"/>
            </material>
        </visual>
        <collision>
            <origin xyz="0.0 0.0 -0.20578701992804493" rpy="0 0 0"/>
            <geometry>
                <box size="1.0535946264310272 0.646988211672374 0.41157403985608987" />
            </geometry>
        </collision>
    </link>
    <joint name="Link3_Link4" type="revolute">
       <parent link="Link3"/>
       <child  link="Link4"/>
       <origin rpy="0 0 0" xyz="0.0 0.0 -0.41157403985608987" />
       <axis xyz="1 0 0"/>
       <limit effort="0.0" lower="-3.14159" upper="3.14159" velocity="0.0"/>
    </joint>
    <link name="Link4">
        <inertial>
            <origin xyz="0.0 0.0 -0.26509631768654685" rpy="0 0 0"/>
            <mass value="0.4782189451274343" />
            <inertia ixx="100" ixy="0" ixz="0" iyy="100" iyz="0" izz="100" />
        </inertial>
        <visual>
            <origin xyz="0.0 0.0 -0.26509631768654685" rpy="0 0 0"/>
            <geometry>
                <box size="0.8989822226486474 1.0033258058943924 0.5301926353730937" />
            </geometry>
            <material name="Sensor">
                <color rgba="0.239 0.875 0.282 1.0"/>
            </material>
        </visual>
        <collision>
            <origin xyz="0.0 0.0 -0.26509631768654685" rpy="0 0 0"/>
            <geometry>
                <box size="0.8989822226486474 1.0033258058943924 0.5301926353730937" />
            </geometry>
        </collision>
    </link>
    <joint name="Link4_Link5" type="revolute">
       <parent link="Link4"/>
       <child  link="Link5"/>
       <origin rpy="0 0 0" xyz="0.4494911113243237 0.0 -0.26509631768654685" />
       <axis xyz="1 0 0"/>
       <limit effort="0.0" lower="-3.14159" upper="3.14159" velocity="0.0"/>
    </joint>
    <link name="Link5">
        <inertial>
            <origin xyz="0.3506809306162008 0.0 0.0" rpy="0 0 0"/>
            <mass value="0.9053088773591335" />
            <inertia ixx="100" ixy="0" ixz="0" iyy="100" iyz="0" izz="100" />
        </inertial>
        <visual>
            <origin xyz="0.3506809306162008 0.0 0.0" rpy="0 0 0"/>
            <geometry>
                <box size="0.7013618612324016 1.1504489123860653 1.1219856311909184" />
            </geometry>
            <material name="Sensor">
                <color rgba="0.239 0.875 0.282 1.0"/>
            </material>
        </visual>
        <collision>
            <origin xyz="0.3506809306162008 0.0 0.0" rpy="0 0 0"/>
            <geometry>
                <box size="0.7013618612324016 1.1504489123860653 1.1219856311909184" />
            </geometry>
        </collision>
    </link>
    <joint name="Link5_Link6" type="revolute">
       <parent link="Link5"/>
       <child  link="Link6"/>
       <origin rpy="0 0 0" xyz="0.3506809306162008 0.0 0.5609928155954592" />
       <axis xyz="1 0 0"/>
       <limit effort="0.0" lower="-3.14159" upper="3.14159" velocity="0.0"/>
    </joint>
    <link name="Link6">
        <inertial>
            <origin xyz="0.0 0.0 0.5336911351985628" rpy="0 0 0"/>
            <mass value="0.8591355997331697" />
            <inertia ixx="100" ixy="0" ixz="0" iyy="100" iyz="0" izz="100" />
        </inertial>
        <visual>
            <origin xyz="0.0 0.0 0.5336911351985628" rpy="0 0 0"/>
            <geometry>
                <box size="0.9571876097841823 0.8409005994904067 1.0673822703971256" />
            </geometry>
            <material name="Sensor">
                <color rgba="0.239 0.875 0.282 1.0"/>
            </material>
        </visual>
        <collision>
            <origin xyz="0.0 0.0 0.5336911351985628" rpy="0 0 0"/>
            <geometry>
                <box size="0.9571876097841823 0.8409005994904067 1.0673822703971256" />
            </geometry>
        </collision>
    </link>
    <joint name="Link6_Link7" type="revolute">
       <parent link="Link6"/>
       <child  link="Link7"/>
       <origin rpy="0 0 0" xyz="0.0 0.0 1.0673822703971256" />
       <axis xyz="0 1 0"/>
       <limit effort="0.0" lower="-3.14159" upper="3.14159" velocity="0.0"/>
    </joint>
    <link name="Link7">
        <inertial>
            <origin xyz="0.0 0.0 0.3236138831168809" rpy="0 0 0"/>
            <mass value="0.18919375314784886" />
            <inertia ixx="100" ixy="0" ixz="0" iyy="100" iyz="0" izz="100" />
        </inertial>
        <visual>
            <origin xyz="0.0 0.0 0.3236138831168809" rpy="0 0 0"/>
            <geometry>
                <box size="1.1576446460998389 0.25250755966792315 0.6472277662337618" />
            </geometry>
            <material name="Sensor">
                <color rgba="0.239 0.875 0.282 1.0"/>
            </material>
        </visual>
        <collision>
            <origin xyz="0.0 0.0 0.3236138831168809" rpy="0 0 0"/>
            <geometry>
                <box size="1.1576446460998389 0.25250755966792315 0.6472277662337618" />
            </geometry>
        </collision>
    </link>
    <joint name="Link7_Link8" type="revolute">
       <parent link="Link7"/>
       <child  link="Link8"/>
       <origin rpy="0 0 0" xyz="0.0 -0.12625377983396158 0.3236138831168809" />
       <axis xyz="0 1 0"/>
       <limit effort="0.0" lower="-3.14159" upper="3.14159" velocity="0.0"/>
    </joint>
    <link name="Link8">
        <inertial>
            <origin xyz="0.0 -0.4919615681424383 0.0" rpy="0 0 0"/>
            <mass value="0.2694263610638474" />
            <inertia ixx="100" ixy="0" ixz="0" iyy="100" iyz="0" izz="100" />
        </inertial>
        <visual>
            <origin xyz="0.0 -0.4919615681424383 0.0" rpy="0 0 0"/>
            <geometry>
                <box size="0.8114096837184815 0.9839231362848766 0.3374727621850435" />
            </geometry>
            <material name="No Sensor">
                <color rgba="0.184 0.553 0.933 1.0"/>
            </material>
        </visual>
        <collision>
            <origin xyz="0.0 -0.4919615681424383 0.0" rpy="0 0 0"/>
            <geometry>
                <box size="0.8114096837184815 0.9839231362848766 0.3374727621850435" />
            </geometry>
        </collision>
    </link>
    <joint name="Link8_Link9" type="revolute">
       <parent link="Link8"/>
       <child  link="Link9"/>
       <origin rpy="0 0 0" xyz="0.0 -0.9839231362848766 0.0" />
       <axis xyz="1 0 0"/>
       <limit effort="0.0" lower="-3.14159" upper="3.14159" velocity="0.0"/>
    </joint>
    <link name="Link9">
        <inertial>
            <origin xyz="0.0 -0.26481058972492444 0.0" rpy="0 0 0"/>
            <mass value="0.23177097548745296" />
            <inertia ixx="100" ixy="0" ixz="0" iyy="100" iyz="0" izz="100" />
        </inertial>
        <visual>
            <origin xyz="0.0 -0.26481058972492444 0.0" rpy="0 0 0"/>
            <geometry>
                <box size="0.6497549876808645 0.5296211794498489 0.673510053105183" />
            </geometry>
            <material name="No Sensor">
                <color rgba="0.184 0.553 0.933 1.0"/>
            </material>
        </visual>
        <collision>
            <origin xyz="0.0 -0.26481058972492444 0.0" rpy="0 0 0"/>
            <geometry>
                <box size="0.6497549876808645 0.5296211794498489 0.673510053105183" />
            </geometry>
        </collision>
    </link>
</robot>