<robot name = "robot">
    <link name="Link0">
        <inertial>
            <origin xyz="0 0 2" rpy="0 0 0"/>
            <mass value="0.5531403507093564" />
            <inertia ixx="100" ixy="0" ixz="0" iyy="100" iyz="0" izz="100" />
        </inertial>
        <visual>
            <origin xyz="0 0 2" rpy="0 0 0"/>
            <geometry>
                <box size="1.186872133873722 0.6843487519814965 0.6810106878162174" />
            </geometry>
            <material name="No Sensor">
                <color rgba="0.184 0.553 0.933 1.0"/>
            </material>
        </visual>
        <collision>
            <origin xyz="0 0 2" rpy="0 0 0"/>
            <geometry>
                <box size="1.186872133873722 0.6843487519814965 0.6810106878162174" />
            </geometry>
        </collision>
    </link>
    <joint name="Link0_Link1" type="revolute">
       <parent link="Link0"/>
       <child  link="Link1"/>
       <origin rpy="0 0 0" xyz="0.593436066936861 0 2" />
       <axis xyz="1 0 0"/>
       <limit effort="0.0" lower="-3.14159" upper="3.14159" velocity="0.0"/>
    </joint>
    <link name="Link1">
        <inertial>
            <origin xyz="0.4982385752483192 0 0" rpy="0 0 0"/>
            <mass value="0.42914465453749523" />
            <inertia ixx="100" ixy="0" ixz="0" iyy="100" iyz="0" izz="100" />
        </inertial>
        <visual>
            <origin xyz="0.4982385752483192 0 0" rpy="0 0 0"/>
            <geometry>
                <box size="0.9964771504966384 0.8459759495755602 0.5090709865943224" />
            </geometry>
            <material name="Sensor">
                <color rgba="0.239 0.875 0.282 1.0"/>
            </material>
        </visual>
        <collision>
            <origin xyz="0.4982385752483192 0 0" rpy="0 0 0"/>
            <geometry>
                <box size="0.9964771504966384 0.8459759495755602 0.5090709865943224" />
            </geometry>
        </collision>
    </link>
    <joint name="Link1_Link2" type="revolute">
       <parent link="Link1"/>
       <child  link="Link2"/>
       <origin rpy="0 0 0" xyz="0.4982385752483192 0.0 -0.2545354932971612" />
       <axis xyz="0 1 0"/>
       <limit effort="0.0" lower="-3.14159" upper="3.14159" velocity="0.0"/>
    </joint>
    <link name="Link2">
        <inertial>
            <origin xyz="0.0 0.0 -0.4657770459097652" rpy="0 0 0"/>
            <mass value="0.7786798545890827" />
            <inertia ixx="100" ixy="0" ixz="0" iyy="100" iyz="0" izz="100" />
        </inertial>
        <visual>
            <origin xyz="0.0 0.0 -0.4657770459097652" rpy="0 0 0"/>
            <geometry>
                <box size="0.7331700652315026 1.1401083766800943 0.9315540918195304" />
            </geometry>
            <material name="No Sensor">
                <color rgba="0.184 0.553 0.933 1.0"/>
            </material>
        </visual>
        <collision>
            <origin xyz="0.0 0.0 -0.4657770459097652" rpy="0 0 0"/>
            <geometry>
                <box size="0.7331700652315026 1.1401083766800943 0.9315540918195304" />
            </geometry>
        </collision>
    </link>
    <joint name="Link2_Link3" type="revolute">
       <parent link="Link2"/>
       <child  link="Link3"/>
       <origin rpy="0 0 0" xyz="0.0 0.5700541883400472 -0.4657770459097652" />
       <axis xyz="0 1 0"/>
       <limit effort="0.0" lower="-3.14159" upper="3.14159" velocity="0.0"/>
    </joint>
    <link name="Link3">
        <inertial>
            <origin xyz="0.0 0.5633769622129867 0.0" rpy="0 0 0"/>
            <mass value="0.4821710045817255" />
            <inertia ixx="100" ixy="0" ixz="0" iyy="100" iyz="0" izz="100" />
        </inertial>
        <visual>
            <origin xyz="0.0 0.5633769622129867 0.0" rpy="0 0 0"/>
            <geometry>
                <box size="0.8131265282888835 1.1267539244259734 0.5262763826645223" />
            </geometry>
            <material name="No Sensor">
                <color rgba="0.184 0.553 0.933 1.0"/>
            </material>
        </visual>
        <collision>
            <origin xyz="0.0 0.5633769622129867 0.0" rpy="0 0 0"/>
            <geometry>
                <box size="0.8131265282888835 1.1267539244259734 0.5262763826645223" />
            </geometry>
        </collision>
    </link>
    <joint name="Link3_Link4" type="revolute">
       <parent link="Link3"/>
       <child  link="Link4"/>
       <origin rpy="0 0 0" xyz="0.0 0.5633769622129867 -0.26313819133226113" />
       <axis xyz="1 0 0"/>
       <limit effort="0.0" lower="-3.14159" upper="3.14159" velocity="0.0"/>
    </joint>
    <link name="Link4">
        <inertial>
            <origin xyz="0.0 0.0 -0.5448967639585106" rpy="0 0 0"/>
            <mass value="0.6112452035545675" />
            <inertia ixx="100" ixy="0" ixz="0" iyy="100" iyz="0" izz="100" />
        </inertial>
        <visual>
            <origin xyz="0.0 0.0 -0.5448967639585106" rpy="0 0 0"/>
            <geometry>
                <box size="1.2468474753997545 0.44983983332308586 1.0897935279170212" />
            </geometry>
            <material name="Sensor">
                <color rgba="0.239 0.875 0.282 1.0"/>
            </material>
        </visual>
        <collision>
            <origin xyz="0.0 0.0 -0.5448967639585106" rpy="0 0 0"/>
            <geometry>
                <box size="1.2468474753997545 0.44983983332308586 1.0897935279170212" />
            </geometry>
        </collision>
    </link>
    <joint name="Link4_Link5" type="revolute">
       <parent link="Link4"/>
       <child  link="Link5"/>
       <origin rpy="0 0 0" xyz="0.0 -0.22491991666154293 -0.5448967639585106" />
       <axis xyz="0 0 1"/>
       <limit effort="0.0" lower="-3.14159" upper="3.14159" velocity="0.0"/>
    </joint>
    <link name="Link5">
        <inertial>
            <origin xyz="0.0 -0.557026958702576 0.0" rpy="0 0 0"/>
            <mass value="0.9230201215083949" />
            <inertia ixx="100" ixy="0" ixz="0" iyy="100" iyz="0" izz="100" />
        </inertial>
        <visual>
            <origin xyz="0.0 -0.557026958702576 0.0" rpy="0 0 0"/>
            <geometry>
                <box size="0.9923419607916683 1.114053917405152 0.8349175744816693" />
            </geometry>
            <material name="Sensor">
                <color rgba="0.239 0.875 0.282 1.0"/>
            </material>
        </visual>
        <collision>
            <origin xyz="0.0 -0.557026958702576 0.0" rpy="0 0 0"/>
            <geometry>
                <box size="0.9923419607916683 1.114053917405152 0.8349175744816693" />
            </geometry>
        </collision>
    </link>
    <joint name="Link5_Link6" type="revolute">
       <parent link="Link5"/>
       <child  link="Link6"/>
       <origin rpy="0 0 0" xyz="0.0 -1.114053917405152 0.0" />
       <axis xyz="0 1 0"/>
       <limit effort="0.0" lower="-3.14159" upper="3.14159" velocity="0.0"/>
    </joint>
    <link name="Link6">
        <inertial>
            <origin xyz="0.0 -0.36675996565735586 0.0" rpy="0 0 0"/>
            <mass value="0.3935986981348137" />
            <inertia ixx="100" ixy="0" ixz="0" iyy="100" iyz="0" izz="100" />
        </inertial>
        <visual>
            <origin xyz="0.0 -0.36675996565735586 0.0" rpy="0 0 0"/>
            <geometry>
                <box size="0.48238126387694147 0.7335199313147117 1.1123752135825575" />
            </geometry>
            <material name="Sensor">
                <color rgba="0.239 0.875 0.282 1.0"/>
            </material>
        </visual>
        <collision>
            <origin xyz="0.0 -0.36675996565735586 0.0" rpy="0 0 0"/>
            <geometry>
                <box size="0.48238126387694147 0.7335199313147117 1.1123752135825575" />
            </geometry>
        </collision>
    </link>
    <joint name="Link6_Link7" type="revolute">
       <parent link="Link6"/>
       <child  link="Link7"/>
       <origin rpy="0 0 0" xyz="0.0 -0.7335199313147117 0.0" />
       <axis xyz="0 1 0"/>
       <limit effort="0.0" lower="-3.14159" upper="3.14159" velocity="0.0"/>
    </joint>
    <link name="Link7">
        <inertial>
            <origin xyz="0.0 -0.21175526842613662 0.0" rpy="0 0 0"/>
            <mass value="0.551238417633081" />
            <inertia ixx="100" ixy="0" ixz="0" iyy="100" iyz="0" izz="100" />
        </inertial>
        <visual>
            <origin xyz="0.0 -0.21175526842613662 0.0" rpy="0 0 0"/>
            <geometry>
                <box size="1.0478045046781688 0.42351053685227324 1.242209928883655" />
            </geometry>
            <material name="Sensor">
                <color rgba="0.239 0.875 0.282 1.0"/>
            </material>
        </visual>
        <collision>
            <origin xyz="0.0 -0.21175526842613662 0.0" rpy="0 0 0"/>
            <geometry>
                <box size="1.0478045046781688 0.42351053685227324 1.242209928883655" />
            </geometry>
        </collision>
    </link>
    <joint name="Link7_Link8" type="revolute">
       <parent link="Link7"/>
       <child  link="Link8"/>
       <origin rpy="0 0 0" xyz="0.0 -0.21175526842613662 -0.6211049644418275" />
       <axis xyz="1 0 0"/>
       <limit effort="0.0" lower="-3.14159" upper="3.14159" velocity="0.0"/>
    </joint>
    <link name="Link8">
        <inertial>
            <origin xyz="0.0 0.0 -0.5022006576638969" rpy="0 0 0"/>
            <mass value="0.18099964149636769" />
            <inertia ixx="100" ixy="0" ixz="0" iyy="100" iyz="0" izz="100" />
        </inertial>
        <visual>
            <origin xyz="0.0 0.0 -0.5022006576638969" rpy="0 0 0"/>
            <geometry>
                <box size="0.28041224118736663 0.6426484632796582 1.0044013153277938" />
            </geometry>
            <material name="No Sensor">
                <color rgba="0.184 0.553 0.933 1.0"/>
            </material>
        </visual>
        <collision>
            <origin xyz="0.0 0.0 -0.5022006576638969" rpy="0 0 0"/>
            <geometry>
                <box size="0.28041224118736663 0.6426484632796582 1.0044013153277938" />
            </geometry>
        </collision>
    </link>
    <joint name="Link8_Link9" type="revolute">
       <parent link="Link8"/>
       <child  link="Link9"/>
       <origin rpy="0 0 0" xyz="0.0 -0.3213242316398291 -0.5022006576638969" />
       <axis xyz="0 0 1"/>
       <limit effort="0.0" lower="-3.14159" upper="3.14159" velocity="0.0"/>
    </joint>
    <link name="Link9">
        <inertial>
            <origin xyz="0.0 -0.19606332106701974 0.0" rpy="0 0 0"/>
            <mass value="0.5633761927054595" />
            <inertia ixx="100" ixy="0" ixz="0" iyy="100" iyz="0" izz="100" />
        </inertial>
        <visual>
            <origin xyz="0.0 -0.19606332106701974 0.0" rpy="0 0 0"/>
            <geometry>
                <box size="1.223739682897925 0.39212664213403947 1.17404054865323" />
            </geometry>
            <material name="No Sensor">
                <color rgba="0.184 0.553 0.933 1.0"/>
            </material>
        </visual>
        <collision>
            <origin xyz="0.0 -0.19606332106701974 0.0" rpy="0 0 0"/>
            <geometry>
                <box size="1.223739682897925 0.39212664213403947 1.17404054865323" />
            </geometry>
        </collision>
    </link>
</robot>