<robot name = "robot">
    <link name="Link0">
        <inertial>
            <origin xyz="0 0 2" rpy="0 0 0"/>
            <mass value="0.17356801524454343" />
            <inertia ixx="100" ixy="0" ixz="0" iyy="100" iyz="0" izz="100" />
        </inertial>
        <visual>
            <origin xyz="0 0 2" rpy="0 0 0"/>
            <geometry>
                <box size="0.3792514080774897 1.1360201939444052 0.4028621293958289" />
            </geometry>
            <material name="No Sensor">
                <color rgba="0.184 0.553 0.933 1.0"/>
            </material>
        </visual>
        <collision>
            <origin xyz="0 0 2" rpy="0 0 0"/>
            <geometry>
                <box size="0.3792514080774897 1.1360201939444052 0.4028621293958289" />
            </geometry>
        </collision>
    </link>
    <joint name="Link0_Link1" type="revolute">
       <parent link="Link0"/>
       <child  link="Link1"/>
       <origin rpy="0 0 0" xyz="0.18962570403874485 0 2" />
       <axis xyz="1 0 0"/>
       <limit effort="0.0" lower="-3.14159" upper="3.14159" velocity="0.0"/>
    </joint>
    <link name="Link1">
        <inertial>
            <origin xyz="0.30525817849660386 0 0" rpy="0 0 0"/>
            <mass value="0.19767583554200951" />
            <inertia ixx="100" ixy="0" ixz="0" iyy="100" iyz="0" izz="100" />
        </inertial>
        <visual>
            <origin xyz="0.30525817849660386 0 0" rpy="0 0 0"/>
            <geometry>
                <box size="0.6105163569932077 0.6111619384814453 0.5297853922706043" />
            </geometry>
            <material name="Sensor">
                <color rgba="0.239 0.875 0.282 1.0"/>
            </material>
        </visual>
        <collision>
            <origin xyz="0.30525817849660386 0 0" rpy="0 0 0"/>
            <geometry>
                <box size="0.6105163569932077 0.6111619384814453 0.5297853922706043" />
            </geometry>
        </collision>
    </link>
    <joint name="Link1_Link2" type="revolute">
       <parent link="Link1"/>
       <child  link="Link2"/>
       <origin rpy="0 0 0" xyz="0.6105163569932077 0.0 0.0" />
       <axis xyz="0 0 1"/>
       <limit effort="0.0" lower="-3.14159" upper="3.14159" velocity="0.0"/>
    </joint>
    <link name="Link2">
        <inertial>
            <origin xyz="0.30240212192706506 0.0 0.0" rpy="0 0 0"/>
            <mass value="0.15756028019481774" />
            <inertia ixx="100" ixy="0" ixz="0" iyy="100" iyz="0" izz="100" />
        </inertial>
        <visual>
            <origin xyz="0.30240212192706506 0.0 0.0" rpy="0 0 0"/>
            <geometry>
                <box size="0.6048042438541301 0.79300156482881 0.3285170166577439" />
            </geometry>
            <material name="Sensor">
                <color rgba="0.239 0.875 0.282 1.0"/>
            </material>
        </visual>
        <collision>
            <origin xyz="0.30240212192706506 0.0 0.0" rpy="0 0 0"/>
            <geometry>
                <box size="0.6048042438541301 0.79300156482881 0.3285170166577439" />
            </geometry>
        </collision>
    </link>
    <joint name="Link2_Link3" type="revolute">
       <parent link="Link2"/>
       <child  link="Link3"/>
       <origin rpy="0 0 0" xyz="0.30240212192706506 0.0 0.16425850832887195" />
       <axis xyz="0 1 0"/>
       <limit effort="0.0" lower="-3.14159" upper="3.14159" velocity="0.0"/>
    </joint>
    <link name="Link3">
        <inertial>
            <origin xyz="0.0 0.0 0.19212470498986273" rpy="0 0 0"/>
            <mass value="0.19942036030279875" />
            <inertia ixx="100" ixy="0" ixz="0" iyy="100" iyz="0" izz="100" />
        </inertial>
        <visual>
            <origin xyz="0.0 0.0 0.19212470498986273" rpy="0 0 0"/>
            <geometry>
                <box size="0.6228696711111941 0.8332188810001392 0.38424940997972545" />
            </geometry>
            <material name="Sensor">
                <color rgba="0.239 0.875 0.282 1.0"/>
            </material>
        </visual>
        <collision>
            <origin xyz="0.0 0.0 0.19212470498986273" rpy="0 0 0"/>
            <geometry>
                <box size="0.6228696711111941 0.8332188810001392 0.38424940997972545" />
            </geometry>
        </collision>
    </link>
    <joint name="Link3_Link4" type="revolute">
       <parent link="Link3"/>
       <child  link="Link4"/>
       <origin rpy="0 0 0" xyz="0.0 0.4166094405000696 0.19212470498986273" />
       <axis xyz="1 0 0"/>
       <limit effort="0.0" lower="-3.14159" upper="3.14159" velocity="0.0"/>
    </joint>
    <link name="Link4">
        <inertial>
            <origin xyz="0.0 0.28138954127882704 0.0" rpy="0 0 0"/>
            <mass value="0.09003974379050246" />
            <inertia ixx="100" ixy="0" ixz="0" iyy="100" iyz="0" izz="100" />
        </inertial>
        <visual>
            <origin xyz="0.0 0.28138954127882704 0.0" rpy="0 0 0"/>
            <geometry>
                <box size="0.4929879452919641 0.5627790825576541 0.3245338511835042" />
            </geometry>
            <material name="Sensor">
                <color rgba="0.239 0.875 0.282 1.0"/>
            </material>
        </visual>
        <collision>
            <origin xyz="0.0 0.28138954127882704 0.0" rpy="0 0 0"/>
            <geometry>
                <box size="0.4929879452919641 0.5627790825576541 0.3245338511835042" />
            </geometry>
        </collision>
    </link>
    <joint name="Link4_Link5" type="revolute">
       <parent link="Link4"/>
       <child  link="Link5"/>
       <origin rpy="0 0 0" xyz="0.0 0.28138954127882704 -0.1622669255917521" />
       <axis xyz="1 0 0"/>
       <limit effort="0.0" lower="-3.14159" upper="3.14159" velocity="0.0"/>
    </joint>
    <link name="Link5">
        <inertial>
            <origin xyz="0.0 0.0 -0.33030050459776494" rpy="0 0 0"/>
            <mass value="0.35871677316196876" />
            <inertia ixx="100" ixy="0" ixz="0" iyy="100" iyz="0" izz="100" />
        </inertial>
        <visual>
            <origin xyz="0.0 0.0 -0.33030050459776494" rpy="0 0 0"/>
            <geometry>
                <box size="1.0576907953019956 0.5133974728261202 0.6606010091955299" />
            </geometry>
            <material name="Sensor">
                <color rgba="0.239 0.875 0.282 1.0"/>
            </material>
        </visual>
        <collision>
            <origin xyz="0.0 0.0 -0.33030050459776494" rpy="0 0 0"/>
            <geometry>
                <box size="1.0576907953019956 0.5133974728261202 0.6606010091955299" />
            </geometry>
        </collision>
    </link>
    <joint name="Link5_Link6" type="revolute">
       <parent link="Link5"/>
       <child  link="Link6"/>
       <origin rpy="0 0 0" xyz="0.0 0.0 -0.6606010091955299" />
       <axis xyz="1 0 0"/>
       <limit effort="0.0" lower="-3.14159" upper="3.14159" velocity="0.0"/>
    </joint>
    <link name="Link6">
        <inertial>
            <origin xyz="0.0 0.0 -0.1888690234897057" rpy="0 0 0"/>
            <mass value="0.13733832896855458" />
            <inertia ixx="100" ixy="0" ixz="0" iyy="100" iyz="0" izz="100" />
        </inertial>
        <visual>
            <origin xyz="0.0 0.0 -0.1888690234897057" rpy="0 0 0"/>
            <geometry>
                <box size="0.6554128659393603 0.5547356362881533 0.3777380469794114" />
            </geometry>
            <material name="No Sensor">
                <color rgba="0.184 0.553 0.933 1.0"/>
            </material>
        </visual>
        <collision>
            <origin xyz="0.0 0.0 -0.1888690234897057" rpy="0 0 0"/>
            <geometry>
                <box size="0.6554128659393603 0.5547356362881533 0.3777380469794114" />
            </geometry>
        </collision>
    </link>
    <joint name="Link6_Link7" type="revolute">
       <parent link="Link6"/>
       <child  link="Link7"/>
       <origin rpy="0 0 0" xyz="-0.32770643296968016 0.0 -0.1888690234897057" />
       <axis xyz="0 1 0"/>
       <limit effort="0.0" lower="-3.14159" upper="3.14159" velocity="0.0"/>
    </joint>
    <link name="Link7">
        <inertial>
            <origin xyz="-0.5717796870359242 0.0 0.0" rpy="0 0 0"/>
            <mass value="0.5505438404033763" />
            <inertia ixx="100" ixy="0" ixz="0" iyy="100" iyz="0" izz="100" />
        </inertial>
        <visual>
            <origin xyz="-0.5717796870359242 0.0 0.0" rpy="0 0 0"/>
            <geometry>
                <box size="1.1435593740718484 0.9313948478763496 0.5168914619254061" />
            </geometry>
            <material name="No Sensor">
                <color rgba="0.184 0.553 0.933 1.0"/>
            </material>
        </visual>
        <collision>
            <origin xyz="-0.5717796870359242 0.0 0.0" rpy="0 0 0"/>
            <geometry>
                <box size="1.1435593740718484 0.9313948478763496 0.5168914619254061" />
            </geometry>
        </collision>
    </link>
    <joint name="Link7_Link8" type="revolute">
       <parent link="Link7"/>
       <child  link="Link8"/>
       <origin rpy="0 0 0" xyz="-0.5717796870359242 0.4656974239381748 0.0" />
       <axis xyz="1 0 0"/>
       <limit effort="0.0" lower="-3.14159" upper="3.14159" velocity="0.0"/>
    </joint>
    <link name="Link8">
        <inertial>
            <origin xyz="0.0 0.18674750804276452 0.0" rpy="0 0 0"/>
            <mass value="0.0673292387241798" />
            <inertia ixx="100" ixy="0" ixz="0" iyy="100" iyz="0" izz="100" />
        </inertial>
        <visual>
            <origin xyz="0.0 0.18674750804276452 0.0" rpy="0 0 0"/>
            <geometry>
                <box size="0.34243092687336907 0.37349501608552904 0.5264364013653792" />
            </geometry>
            <material name="No Sensor">
                <color rgba="0.184 0.553 0.933 1.0"/>
            </material>
        </visual>
        <collision>
            <origin xyz="0.0 0.18674750804276452 0.0" rpy="0 0 0"/>
            <geometry>
                <box size="0.34243092687336907 0.37349501608552904 0.5264364013653792" />
            </geometry>
        </collision>
    </link>
    <joint name="Link8_Link9" type="revolute">
       <parent link="Link8"/>
       <child  link="Link9"/>
       <origin rpy="0 0 0" xyz="0.0 0.18674750804276452 -0.2632182006826896" />
       <axis xyz="0 0 1"/>
       <limit effort="0.0" lower="-3.14159" upper="3.14159" velocity="0.0"/>
    </joint>
    <link name="Link9">
        <inertial>
            <origin xyz="0.0 0.0 -0.362514773785171" rpy="0 0 0"/>
            <mass value="0.08567390884480565" />
            <inertia ixx="100" ixy="0" ixz="0" iyy="100" iyz="0" izz="100" />
        </inertial>
        <visual>
            <origin xyz="0.0 0.0 -0.362514773785171" rpy="0 0 0"/>
            <geometry>
                <box size="0.2990434788655092 0.3951468639570195 0.725029547570342" />
            </geometry>
            <material name="No Sensor">
                <color rgba="0.184 0.553 0.933 1.0"/>
            </material>
        </visual>
        <collision>
            <origin xyz="0.0 0.0 -0.362514773785171" rpy="0 0 0"/>
            <geometry>
                <box size="0.2990434788655092 0.3951468639570195 0.725029547570342" />
            </geometry>
        </collision>
    </link>
</robot>