<robot name = "robot">
    <link name="Link0">
        <inertial>
            <origin xyz="0 0 2" rpy="0 0 0"/>
            <mass value="0.6075803153769049" />
            <inertia ixx="100" ixy="0" ixz="0" iyy="100" iyz="0" izz="100" />
        </inertial>
        <visual>
            <origin xyz="0 0 2" rpy="0 0 0"/>
            <geometry>
                <box size="0.9038401991962549 0.6937697927247224 0.9689394880898436" />
            </geometry>
            <material name="Sensor">
                <color rgba="0.239 0.875 0.282 1.0"/>
            </material>
        </visual>
        <collision>
            <origin xyz="0 0 2" rpy="0 0 0"/>
            <geometry>
                <box size="0.9038401991962549 0.6937697927247224 0.9689394880898436" />
            </geometry>
        </collision>
    </link>
    <joint name="Link0_Link1" type="revolute">
       <parent link="Link0"/>
       <child  link="Link1"/>
       <origin rpy="0 0 0" xyz="0.45192009959812746 0 2" />
       <axis xyz="1 0 0"/>
       <limit effort="0.0" lower="-3.14159" upper="3.14159" velocity="0.0"/>
    </joint>
    <link name="Link1">
        <inertial>
            <origin xyz="0.1799879862226602 0 0" rpy="0 0 0"/>
            <mass value="0.4696858187804295" />
            <inertia ixx="100" ixy="0" ixz="0" iyy="100" iyz="0" izz="100" />
        </inertial>
        <visual>
            <origin xyz="0.1799879862226602 0 0" rpy="0 0 0"/>
            <geometry>
                <box size="0.3599759724453204 1.188719173368931 1.0976267092393877" />
            </geometry>
            <material name="Sensor">
                <color rgba="0.239 0.875 0.282 1.0"/>
            </material>
        </visual>
        <collision>
            <origin xyz="0.1799879862226602 0 0" rpy="0 0 0"/>
            <geometry>
                <box size="0.3599759724453204 1.188719173368931 1.0976267092393877" />
            </geometry>
        </collision>
    </link>
    <joint name="Link1_Link2" type="revolute">
       <parent link="Link1"/>
       <child  link="Link2"/>
       <origin rpy="0 0 0" xyz="0.1799879862226602 0.0 0.5488133546196938" />
       <axis xyz="0 0 1"/>
       <limit effort="0.0" lower="-3.14159" upper="3.14159" velocity="0.0"/>
    </joint>
    <link name="Link2">
        <inertial>
            <origin xyz="0.0 0.0 0.3332833645073737" rpy="0 0 0"/>
            <mass value="0.3810295101263322" />
            <inertia ixx="100" ixy="0" ixz="0" iyy="100" iyz="0" izz="100" />
        </inertial>
        <visual>
            <origin xyz="0.0 0.0 0.3332833645073737" rpy="0 0 0"/>
            <geometry>
                <box size="0.9090356596658833 0.6288311686617318 0.6665667290147474" />
            </geometry>
            <material name="No Sensor">
                <color rgba="0.184 0.553 0.933 1.0"/>
            </material>
        </visual>
        <collision>
            <origin xyz="0.0 0.0 0.3332833645073737" rpy="0 0 0"/>
            <geometry>
                <box size="0.9090356596658833 0.6288311686617318 0.6665667290147474" />
            </geometry>
        </collision>
    </link>
    <joint name="Link2_Link3" type="revolute">
       <parent link="Link2"/>
       <child  link="Link3"/>
       <origin rpy="0 0 0" xyz="0.0 0.3144155843308659 0.3332833645073737" />
       <axis xyz="0 0 1"/>
       <limit effort="0.0" lower="-3.14159" upper="3.14159" velocity="0.0"/>
    </joint>
    <link name="Link3">
        <inertial>
            <origin xyz="0.0 0.5926418850034003 0.0" rpy="0 0 0"/>
            <mass value="0.9663872815851082" />
            <inertia ixx="100" ixy="0" ixz="0" iyy="100" iyz="0" izz="100" />
        </inertial>
        <visual>
            <origin xyz="0.0 0.5926418850034003 0.0" rpy="0 0 0"/>
            <geometry>
                <box size="0.7321539221574674 1.1852837700068006 1.1135929549181025" />
            </geometry>
            <material name="Sensor">
                <color rgba="0.239 0.875 0.282 1.0"/>
            </material>
        </visual>
        <collision>
            <origin xyz="0.0 0.5926418850034003 0.0" rpy="0 0 0"/>
            <geometry>
                <box size="0.7321539221574674 1.1852837700068006 1.1135929549181025" />
            </geometry>
        </collision>
    </link>
    <joint name="Link3_Link4" type="revolute">
       <parent link="Link3"/>
       <child  link="Link4"/>
       <origin rpy="0 0 0" xyz="0.3660769610787337 0.5926418850034003 0.0" />
       <axis xyz="0 0 1"/>
       <limit effort="0.0" lower="-3.14159" upper="3.14159" velocity="0.0"/>
    </joint>
    <link name="Link4">
        <inertial>
            <origin xyz="0.3639619246082797 0.0 0.0" rpy="0 0 0"/>
            <mass value="0.6590682404271483" />
            <inertia ixx="100" ixy="0" ixz="0" iyy="100" iyz="0" izz="100" />
        </inertial>
        <visual>
            <origin xyz="0.3639619246082797 0.0 0.0" rpy="0 0 0"/>
            <geometry>
                <box size="0.7279238492165594 0.804518498278167 1.1254038622793217" />
            </geometry>
            <material name="Sensor">
                <color rgba="0.239 0.875 0.282 1.0"/>
            </material>
        </visual>
        <collision>
            <origin xyz="0.3639619246082797 0.0 0.0" rpy="0 0 0"/>
            <geometry>
                <box size="0.7279238492165594 0.804518498278167 1.1254038622793217" />
            </geometry>
        </collision>
    </link>
    <joint name="Link4_Link5" type="revolute">
       <parent link="Link4"/>
       <child  link="Link5"/>
       <origin rpy="0 0 0" xyz="0.7279238492165594 0.0 0.0" />
       <axis xyz="0 1 0"/>
       <limit effort="0.0" lower="-3.14159" upper="3.14159" velocity="0.0"/>
    </joint>
    <link name="Link5">
        <inertial>
            <origin xyz="0.599632216886145 0.0 0.0" rpy="0 0 0"/>
            <mass value="1.0647897699725506" />
            <inertia ixx="100" ixy="0" ixz="0" iyy="100" iyz="0" izz="100" />
        </inertial>
        <visual>
            <origin xyz="0.599632216886145 0.0 0.0" rpy="0 0 0"/>
            <geometry>
                <box size="1.19926443377229 0.889184755868246 0.9985203200897537" />
            </geometry>
            <material name="Sensor">
                <color rgba="0.239 0.875 0.282 1.0"/>
            </material>
        </visual>
        <collision>
            <origin xyz="0.599632216886145 0.0 0.0" rpy="0 0 0"/>
            <geometry>
                <box size="1.19926443377229 0.889184755868246 0.9985203200897537" />
            </geometry>
        </collision>
    </link>
    <joint name="Link5_Link6" type="revolute">
       <parent link="Link5"/>
       <child  link="Link6"/>
       <origin rpy="0 0 0" xyz="0.599632216886145 0.0 0.49926016004487683" />
       <axis xyz="1 0 0"/>
       <limit effort="0.0" lower="-3.14159" upper="3.14159" velocity="0.0"/>
    </joint>
    <link name="Link6">
        <inertial>
            <origin xyz="0.0 0.0 0.5433760249269156" rpy="0 0 0"/>
            <mass value="0.7636768885718331" />
            <inertia ixx="100" ixy="0" ixz="0" iyy="100" iyz="0" izz="100" />
        </inertial>
        <visual>
            <origin xyz="0.0 0.0 0.5433760249269156" rpy="0 0 0"/>
            <geometry>
                <box size="0.6016249063604426 1.16802831908618 1.0867520498538312" />
            </geometry>
            <material name="No Sensor">
                <color rgba="0.184 0.553 0.933 1.0"/>
            </material>
        </visual>
        <collision>
            <origin xyz="0.0 0.0 0.5433760249269156" rpy="0 0 0"/>
            <geometry>
                <box size="0.6016249063604426 1.16802831908618 1.0867520498538312" />
            </geometry>
        </collision>
    </link>
    <joint name="Link6_Link7" type="revolute">
       <parent link="Link6"/>
       <child  link="Link7"/>
       <origin rpy="0 0 0" xyz="-0.3008124531802213 0.0 0.5433760249269156" />
       <axis xyz="1 0 0"/>
       <limit effort="0.0" lower="-3.14159" upper="3.14159" velocity="0.0"/>
    </joint>
    <link name="Link7">
        <inertial>
            <origin xyz="-0.4010279406123814 0.0 0.0" rpy="0 0 0"/>
            <mass value="0.9859245787277234" />
            <inertia ixx="100" ixy="0" ixz="0" iyy="100" iyz="0" izz="100" />
        </inertial>
        <visual>
            <origin xyz="-0.4010279406123814 0.0 0.0" rpy="0 0 0"/>
            <geometry>
                <box size="0.8020558812247628 1.1176272096151738 1.0998718814403323" />
            </geometry>
            <material name="No Sensor">
                <color rgba="0.184 0.553 0.933 1.0"/>
            </material>
        </visual>
        <collision>
            <origin xyz="-0.4010279406123814 0.0 0.0" rpy="0 0 0"/>
            <geometry>
                <box size="0.8020558812247628 1.1176272096151738 1.0998718814403323" />
            </geometry>
        </collision>
    </link>
    <joint name="Link7_Link8" type="revolute">
       <parent link="Link7"/>
       <child  link="Link8"/>
       <origin rpy="0 0 0" xyz="-0.4010279406123814 -0.5588136048075869 0.0" />
       <axis xyz="0 0 1"/>
       <limit effort="0.0" lower="-3.14159" upper="3.14159" velocity="0.0"/>
    </joint>
    <link name="Link8">
        <inertial>
            <origin xyz="0.0 -0.19034641219869403 0.0" rpy="0 0 0"/>
            <mass value="0.3167037099263866" />
            <inertia ixx="100" ixy="0" ixz="0" iyy="100" iyz="0" izz="100" />
        </inertial>
        <visual>
            <origin xyz="0.0 -0.19034641219869403 0.0" rpy="0 0 0"/>
            <geometry>
                <box size="1.058411356606142 0.38069282439738805 0.7860025748218121" />
            </geometry>
            <material name="No Sensor">
                <color rgba="0.184 0.553 0.933 1.0"/>
            </material>
        </visual>
        <collision>
            <origin xyz="0.0 -0.19034641219869403 0.0" rpy="0 0 0"/>
            <geometry>
                <box size="1.058411356606142 0.38069282439738805 0.7860025748218121" />
            </geometry>
        </collision>
    </link>
    <joint name="Link8_Link9" type="revolute">
       <parent link="Link8"/>
       <child  link="Link9"/>
       <origin rpy="0 0 0" xyz="0.0 -0.19034641219869403 -0.39300128741090606" />
       <axis xyz="0 1 0"/>
       <limit effort="0.0" lower="-3.14159" upper="3.14159" velocity="0.0"/>
    </joint>
    <link name="Link9">
        <inertial>
            <origin xyz="0.0 0.0 -0.3353565995125959" rpy="0 0 0"/>
            <mass value="0.7879243773409597" />
            <inertia ixx="100" ixy="0" ixz="0" iyy="100" iyz="0" izz="100" />
        </inertial>
        <visual>
            <origin xyz="0.0 0.0 -0.3353565995125959" rpy="0 0 0"/>
            <geometry>
                <box size="1.150783114706916 1.0208318305538304 0.6707131990251918" />
            </geometry>
            <material name="No Sensor">
                <color rgba="0.184 0.553 0.933 1.0"/>
            </material>
        </visual>
        <collision>
            <origin xyz="0.0 0.0 -0.3353565995125959" rpy="0 0 0"/>
            <geometry>
                <box size="1.150783114706916 1.0208318305538304 0.6707131990251918" />
            </geometry>
        </collision>
    </link>
</robot>