<robot name = "robot">
    <link name="Link0">
        <inertial>
            <origin xyz="0 0 2" rpy="0 0 0"/>
            <mass value="0.21624541369894298" />
            <inertia ixx="100" ixy="0" ixz="0" iyy="100" iyz="0" izz="100" />
        </inertial>
        <visual>
            <origin xyz="0 0 2" rpy="0 0 0"/>
            <geometry>
                <box size="0.6289843112378013 0.6062558256629118 0.5670889272850883" />
            </geometry>
            <material name="No Sensor">
                <color rgba="0 0 1.0 1.0"/>
            </material>
        </visual>
        <collision>
            <origin xyz="0 0 2" rpy="0 0 0"/>
            <geometry>
                <box size="0.6289843112378013 0.6062558256629118 0.5670889272850883" />
            </geometry>
        </collision>
    </link>
    <joint name="Link0_Link1" type="revolute">
       <parent link="Link0"/>
       <child  link="Link1"/>
       <origin rpy="0 0 0" xyz="0.31449215561890065 0 2" />
       <axis xyz="0 1 0"/>
       <limit effort="0.0" lower="-3.14159" upper="3.14159" velocity="0.0"/>
    </joint>
    <link name="Link1">
        <inertial>
            <origin xyz="0.45893841651197087 0 0" rpy="0 0 0"/>
            <mass value="0.5811824037493866" />
            <inertia ixx="100" ixy="0" ixz="0" iyy="100" iyz="0" izz="100" />
        </inertial>
        <visual>
            <origin xyz="0.45893841651197087 0 0" rpy="0 0 0"/>
            <geometry>
                <box size="0.9178768330239417 0.8398412137662195 0.7539297228844999" />
            </geometry>
            <material name="No Sensor">
                <color rgba="0 0 1.0 1.0"/>
            </material>
        </visual>
        <collision>
            <origin xyz="0.45893841651197087 0 0" rpy="0 0 0"/>
            <geometry>
                <box size="0.9178768330239417 0.8398412137662195 0.7539297228844999" />
            </geometry>
        </collision>
    </link>
    <joint name="Link1_Link2" type="revolute">
       <parent link="Link1"/>
       <child  link="Link2"/>
       <origin rpy="0 0 0" xyz="0.9178768330239417 0 0" />
       <axis xyz="0 1 0"/>
       <limit effort="0.0" lower="-3.14159" upper="3.14159" velocity="0.0"/>
    </joint>
    <link name="Link2">
        <inertial>
            <origin xyz="0.4822041829570827 0 0" rpy="0 0 0"/>
            <mass value="0.5316901750132368" />
            <inertia ixx="100" ixy="0" ixz="0" iyy="100" iyz="0" izz="100" />
        </inertial>
        <visual>
            <origin xyz="0.4822041829570827 0 0" rpy="0 0 0"/>
            <geometry>
                <box size="0.9644083659141655 0.5847642782086091 0.942794046238755" />
            </geometry>
            <material name="Sensor">
                <color rgba="0 1.0 0 1.0"/>
            </material>
        </visual>
        <collision>
            <origin xyz="0.4822041829570827 0 0" rpy="0 0 0"/>
            <geometry>
                <box size="0.9644083659141655 0.5847642782086091 0.942794046238755" />
            </geometry>
        </collision>
    </link>
    <joint name="Link2_Link3" type="revolute">
       <parent link="Link2"/>
       <child  link="Link3"/>
       <origin rpy="0 0 0" xyz="0.9644083659141655 0 0" />
       <axis xyz="0 1 0"/>
       <limit effort="0.0" lower="-3.14159" upper="3.14159" velocity="0.0"/>
    </joint>
    <link name="Link3">
        <inertial>
            <origin xyz="0.264693996533004 0 0" rpy="0 0 0"/>
            <mass value="0.18348856189937793" />
            <inertia ixx="100" ixy="0" ixz="0" iyy="100" iyz="0" izz="100" />
        </inertial>
        <visual>
            <origin xyz="0.264693996533004 0 0" rpy="0 0 0"/>
            <geometry>
                <box size="0.529387993066008 0.539368021143064 0.642613309427384" />
            </geometry>
            <material name="No Sensor">
                <color rgba="0 0 1.0 1.0"/>
            </material>
        </visual>
        <collision>
            <origin xyz="0.264693996533004 0 0" rpy="0 0 0"/>
            <geometry>
                <box size="0.529387993066008 0.539368021143064 0.642613309427384" />
            </geometry>
        </collision>
    </link>
    <joint name="Link3_Link4" type="revolute">
       <parent link="Link3"/>
       <child  link="Link4"/>
       <origin rpy="0 0 0" xyz="0.529387993066008 0 0" />
       <axis xyz="0 1 0"/>
       <limit effort="0.0" lower="-3.14159" upper="3.14159" velocity="0.0"/>
    </joint>
    <link name="Link4">
        <inertial>
            <origin xyz="0.3753649178933039 0 0" rpy="0 0 0"/>
            <mass value="0.4901703055930457" />
            <inertia ixx="100" ixy="0" ixz="0" iyy="100" iyz="0" izz="100" />
        </inertial>
        <visual>
            <origin xyz="0.3753649178933039 0 0" rpy="0 0 0"/>
            <geometry>
                <box size="0.7507298357866078 0.9529532095751408 0.6851595966656147" />
            </geometry>
            <material name="No Sensor">
                <color rgba="0 0 1.0 1.0"/>
            </material>
        </visual>
        <collision>
            <origin xyz="0.3753649178933039 0 0" rpy="0 0 0"/>
            <geometry>
                <box size="0.7507298357866078 0.9529532095751408 0.6851595966656147" />
            </geometry>
        </collision>
    </link>
    <joint name="Link4_Link5" type="revolute">
       <parent link="Link4"/>
       <child  link="Link5"/>
       <origin rpy="0 0 0" xyz="0.7507298357866078 0 0" />
       <axis xyz="0 1 0"/>
       <limit effort="0.0" lower="-3.14159" upper="3.14159" velocity="0.0"/>
    </joint>
    <link name="Link5">
        <inertial>
            <origin xyz="0.3105699818673182 0 0" rpy="0 0 0"/>
            <mass value="0.28084461013944767" />
            <inertia ixx="100" ixy="0" ixz="0" iyy="100" iyz="0" izz="100" />
        </inertial>
        <visual>
            <origin xyz="0.3105699818673182 0 0" rpy="0 0 0"/>
            <geometry>
                <box size="0.6211399637346364 0.8082302805762832 0.559424527511536" />
            </geometry>
            <material name="Sensor">
                <color rgba="0 1.0 0 1.0"/>
            </material>
        </visual>
        <collision>
            <origin xyz="0.3105699818673182 0 0" rpy="0 0 0"/>
            <geometry>
                <box size="0.6211399637346364 0.8082302805762832 0.559424527511536" />
            </geometry>
        </collision>
    </link>
</robot>