<robot name = "robot">
    <link name="Link0">
        <inertial>
            <origin xyz="0 0 2" rpy="0 0 0"/>
            <mass value="0.4431323837220064" />
            <inertia ixx="100" ixy="0" ixz="0" iyy="100" iyz="0" izz="100" />
        </inertial>
        <visual>
            <origin xyz="0 0 2" rpy="0 0 0"/>
            <geometry>
                <box size="0.7214481228701298 0.7974544776358078 0.7702336361563769" />
            </geometry>
            <material name="No Sensor">
                <color rgba="0.184 0.553 0.933 1.0"/>
            </material>
        </visual>
        <collision>
            <origin xyz="0 0 2" rpy="0 0 0"/>
            <geometry>
                <box size="0.7214481228701298 0.7974544776358078 0.7702336361563769" />
            </geometry>
        </collision>
    </link>
    <joint name="Link0_Link1" type="revolute">
       <parent link="Link0"/>
       <child  link="Link1"/>
       <origin rpy="0 0 0" xyz="0.3607240614350649 0 2" />
       <axis xyz="1 0 0"/>
       <limit effort="0.0" lower="-3.14159" upper="3.14159" velocity="0.0"/>
    </joint>
    <link name="Link1">
        <inertial>
            <origin xyz="0.46257867269943115 0 0" rpy="0 0 0"/>
            <mass value="0.27155458959106615" />
            <inertia ixx="100" ixy="0" ixz="0" iyy="100" iyz="0" izz="100" />
        </inertial>
        <visual>
            <origin xyz="0.46257867269943115 0 0" rpy="0 0 0"/>
            <geometry>
                <box size="0.9251573453988623 0.4631389265762489 0.6337679329684967" />
            </geometry>
            <material name="Sensor">
                <color rgba="0.239 0.875 0.282 1.0"/>
            </material>
        </visual>
        <collision>
            <origin xyz="0.46257867269943115 0 0" rpy="0 0 0"/>
            <geometry>
                <box size="0.9251573453988623 0.4631389265762489 0.6337679329684967" />
            </geometry>
        </collision>
    </link>
    <joint name="Link1_Link2" type="revolute">
       <parent link="Link1"/>
       <child  link="Link2"/>
       <origin rpy="0 0 0" xyz="0.46257867269943115 0.23156946328812444 0.0" />
       <axis xyz="0 1 0"/>
       <limit effort="0.0" lower="-3.14159" upper="3.14159" velocity="0.0"/>
    </joint>
    <link name="Link2">
        <inertial>
            <origin xyz="0.0 0.5872814994586237 0.0" rpy="0 0 0"/>
            <mass value="0.4434412732531254" />
            <inertia ixx="100" ixy="0" ixz="0" iyy="100" iyz="0" izz="100" />
        </inertial>
        <visual>
            <origin xyz="0.0 0.5872814994586237 0.0" rpy="0 0 0"/>
            <geometry>
                <box size="0.5644082047245251 1.1745629989172475 0.6689081363643288" />
            </geometry>
            <material name="Sensor">
                <color rgba="0.239 0.875 0.282 1.0"/>
            </material>
        </visual>
        <collision>
            <origin xyz="0.0 0.5872814994586237 0.0" rpy="0 0 0"/>
            <geometry>
                <box size="0.5644082047245251 1.1745629989172475 0.6689081363643288" />
            </geometry>
        </collision>
    </link>
    <joint name="Link2_Link3" type="revolute">
       <parent link="Link2"/>
       <child  link="Link3"/>
       <origin rpy="0 0 0" xyz="0.0 0.5872814994586237 -0.3344540681821644" />
       <axis xyz="0 1 0"/>
       <limit effort="0.0" lower="-3.14159" upper="3.14159" velocity="0.0"/>
    </joint>
    <link name="Link3">
        <inertial>
            <origin xyz="0.0 0.0 -0.6240303922240165" rpy="0 0 0"/>
            <mass value="0.8007249056108289" />
            <inertia ixx="100" ixy="0" ixz="0" iyy="100" iyz="0" izz="100" />
        </inertial>
        <visual>
            <origin xyz="0.0 0.0 -0.6240303922240165" rpy="0 0 0"/>
            <geometry>
                <box size="0.5663231481664555 1.132878372926637 1.248060784448033" />
            </geometry>
            <material name="No Sensor">
                <color rgba="0.184 0.553 0.933 1.0"/>
            </material>
        </visual>
        <collision>
            <origin xyz="0.0 0.0 -0.6240303922240165" rpy="0 0 0"/>
            <geometry>
                <box size="0.5663231481664555 1.132878372926637 1.248060784448033" />
            </geometry>
        </collision>
    </link>
    <joint name="Link3_Link4" type="revolute">
       <parent link="Link3"/>
       <child  link="Link4"/>
       <origin rpy="0 0 0" xyz="-0.28316157408322773 0.0 -0.6240303922240165" />
       <axis xyz="1 0 0"/>
       <limit effort="0.0" lower="-3.14159" upper="3.14159" velocity="0.0"/>
    </joint>
    <link name="Link4">
        <inertial>
            <origin xyz="-0.5651649813227518 0.0 0.0" rpy="0 0 0"/>
            <mass value="0.7966482754225184" />
            <inertia ixx="100" ixy="0" ixz="0" iyy="100" iyz="0" izz="100" />
        </inertial>
        <visual>
            <origin xyz="-0.5651649813227518 0.0 0.0" rpy="0 0 0"/>
            <geometry>
                <box size="1.1303299626455037 1.1884984734941606 0.5930110037438258" />
            </geometry>
            <material name="No Sensor">
                <color rgba="0.184 0.553 0.933 1.0"/>
            </material>
        </visual>
        <collision>
            <origin xyz="-0.5651649813227518 0.0 0.0" rpy="0 0 0"/>
            <geometry>
                <box size="1.1303299626455037 1.1884984734941606 0.5930110037438258" />
            </geometry>
        </collision>
    </link>
    <joint name="Link4_Link5" type="revolute">
       <parent link="Link4"/>
       <child  link="Link5"/>
       <origin rpy="0 0 0" xyz="-0.5651649813227518 0.0 0.2965055018719129" />
       <axis xyz="1 0 0"/>
       <limit effort="0.0" lower="-3.14159" upper="3.14159" velocity="0.0"/>
    </joint>
    <link name="Link5">
        <inertial>
            <origin xyz="0.0 0.0 0.506095362528767" rpy="0 0 0"/>
            <mass value="0.8116550952069246" />
            <inertia ixx="100" ixy="0" ixz="0" iyy="100" iyz="0" izz="100" />
        </inertial>
        <visual>
            <origin xyz="0.0 0.0 0.506095362528767" rpy="0 0 0"/>
            <geometry>
                <box size="1.1268634486504114 0.7116031693251716 1.012190725057534" />
            </geometry>
            <material name="Sensor">
                <color rgba="0.239 0.875 0.282 1.0"/>
            </material>
        </visual>
        <collision>
            <origin xyz="0.0 0.0 0.506095362528767" rpy="0 0 0"/>
            <geometry>
                <box size="1.1268634486504114 0.7116031693251716 1.012190725057534" />
            </geometry>
        </collision>
    </link>
    <joint name="Link5_Link6" type="revolute">
       <parent link="Link5"/>
       <child  link="Link6"/>
       <origin rpy="0 0 0" xyz="0.0 -0.3558015846625858 0.506095362528767" />
       <axis xyz="0 1 0"/>
       <limit effort="0.0" lower="-3.14159" upper="3.14159" velocity="0.0"/>
    </joint>
    <link name="Link6">
        <inertial>
            <origin xyz="0.0 -0.4443840430180742 0.0" rpy="0 0 0"/>
            <mass value="0.09201515189415578" />
            <inertia ixx="100" ixy="0" ixz="0" iyy="100" iyz="0" izz="100" />
        </inertial>
        <visual>
            <origin xyz="0.0 -0.4443840430180742 0.0" rpy="0 0 0"/>
            <geometry>
                <box size="0.28672935755187545 0.8887680860361484 0.36107609271623675" />
            </geometry>
            <material name="Sensor">
                <color rgba="0.239 0.875 0.282 1.0"/>
            </material>
        </visual>
        <collision>
            <origin xyz="0.0 -0.4443840430180742 0.0" rpy="0 0 0"/>
            <geometry>
                <box size="0.28672935755187545 0.8887680860361484 0.36107609271623675" />
            </geometry>
        </collision>
    </link>
    <joint name="Link6_Link7" type="revolute">
       <parent link="Link6"/>
       <child  link="Link7"/>
       <origin rpy="0 0 0" xyz="0.0 -0.4443840430180742 0.18053804635811838" />
       <axis xyz="0 1 0"/>
       <limit effort="0.0" lower="-3.14159" upper="3.14159" velocity="0.0"/>
    </joint>
    <link name="Link7">
        <inertial>
            <origin xyz="0.0 0.0 0.5435933494139245" rpy="0 0 0"/>
            <mass value="1.1605168132256056" />
            <inertia ixx="100" ixy="0" ixz="0" iyy="100" iyz="0" izz="100" />
        </inertial>
        <visual>
            <origin xyz="0.0 0.0 0.5435933494139245" rpy="0 0 0"/>
            <geometry>
                <box size="0.9883023498001428 1.0800838652009106 1.087186698827849" />
            </geometry>
            <material name="No Sensor">
                <color rgba="0.184 0.553 0.933 1.0"/>
            </material>
        </visual>
        <collision>
            <origin xyz="0.0 0.0 0.5435933494139245" rpy="0 0 0"/>
            <geometry>
                <box size="0.9883023498001428 1.0800838652009106 1.087186698827849" />
            </geometry>
        </collision>
    </link>
    <joint name="Link7_Link8" type="revolute">
       <parent link="Link7"/>
       <child  link="Link8"/>
       <origin rpy="0 0 0" xyz="-0.4941511749000714 0.0 0.5435933494139245" />
       <axis xyz="1 0 0"/>
       <limit effort="0.0" lower="-3.14159" upper="3.14159" velocity="0.0"/>
    </joint>
    <link name="Link8">
        <inertial>
            <origin xyz="-0.6197584732672395 0.0 0.0" rpy="0 0 0"/>
            <mass value="0.3784993316948017" />
            <inertia ixx="100" ixy="0" ixz="0" iyy="100" iyz="0" izz="100" />
        </inertial>
        <visual>
            <origin xyz="-0.6197584732672395 0.0 0.0" rpy="0 0 0"/>
            <geometry>
                <box size="1.239516946534479 0.4460892653320435 0.6845274616719605" />
            </geometry>
            <material name="Sensor">
                <color rgba="0.239 0.875 0.282 1.0"/>
            </material>
        </visual>
        <collision>
            <origin xyz="-0.6197584732672395 0.0 0.0" rpy="0 0 0"/>
            <geometry>
                <box size="1.239516946534479 0.4460892653320435 0.6845274616719605" />
            </geometry>
        </collision>
    </link>
    <joint name="Link8_Link9" type="revolute">
       <parent link="Link8"/>
       <child  link="Link9"/>
       <origin rpy="0 0 0" xyz="-0.6197584732672395 0.22304463266602176 0.0" />
       <axis xyz="0 0 1"/>
       <limit effort="0.0" lower="-3.14159" upper="3.14159" velocity="0.0"/>
    </joint>
    <link name="Link9">
        <inertial>
            <origin xyz="0.0 0.27242967125270984 0.0" rpy="0 0 0"/>
            <mass value="0.3217161997263615" />
            <inertia ixx="100" ixy="0" ixz="0" iyy="100" iyz="0" izz="100" />
        </inertial>
        <visual>
            <origin xyz="0.0 0.27242967125270984 0.0" rpy="0 0 0"/>
            <geometry>
                <box size="0.6290809782474991 0.5448593425054197 0.9386030789259829" />
            </geometry>
            <material name="Sensor">
                <color rgba="0.239 0.875 0.282 1.0"/>
            </material>
        </visual>
        <collision>
            <origin xyz="0.0 0.27242967125270984 0.0" rpy="0 0 0"/>
            <geometry>
                <box size="0.6290809782474991 0.5448593425054197 0.9386030789259829" />
            </geometry>
        </collision>
    </link>
</robot>