<robot name = "robot">
    <link name="Link0">
        <inertial>
            <origin xyz="0 0 2" rpy="0 0 0"/>
            <mass value="0.16532830942459756" />
            <inertia ixx="100" ixy="0" ixz="0" iyy="100" iyz="0" izz="100" />
        </inertial>
        <visual>
            <origin xyz="0 0 2" rpy="0 0 0"/>
            <geometry>
                <box size="0.25103293265773463 0.7260891180021048 0.9070403290247293" />
            </geometry>
            <material name="Sensor">
                <color rgba="0.239 0.875 0.282 1.0"/>
            </material>
        </visual>
        <collision>
            <origin xyz="0 0 2" rpy="0 0 0"/>
            <geometry>
                <box size="0.25103293265773463 0.7260891180021048 0.9070403290247293" />
            </geometry>
        </collision>
    </link>
    <joint name="Link0_Link1" type="revolute">
       <parent link="Link0"/>
       <child  link="Link1"/>
       <origin rpy="0 0 0" xyz="0.12551646632886732 0 2" />
       <axis xyz="1 0 0"/>
       <limit effort="0.0" lower="-3.14159" upper="3.14159" velocity="0.0"/>
    </joint>
    <link name="Link1">
        <inertial>
            <origin xyz="0.5466616069597612 0 0" rpy="0 0 0"/>
            <mass value="0.5245599222014167" />
            <inertia ixx="100" ixy="0" ixz="0" iyy="100" iyz="0" izz="100" />
        </inertial>
        <visual>
            <origin xyz="0.5466616069597612 0 0" rpy="0 0 0"/>
            <geometry>
                <box size="1.0933232139195224 0.43373941187600173 1.106159237987372" />
            </geometry>
            <material name="Sensor">
                <color rgba="0.239 0.875 0.282 1.0"/>
            </material>
        </visual>
        <collision>
            <origin xyz="0.5466616069597612 0 0" rpy="0 0 0"/>
            <geometry>
                <box size="1.0933232139195224 0.43373941187600173 1.106159237987372" />
            </geometry>
        </collision>
    </link>
    <joint name="Link1_Link2" type="revolute">
       <parent link="Link1"/>
       <child  link="Link2"/>
       <origin rpy="0 0 0" xyz="0.5466616069597612 0.21686970593800087 0.0" />
       <axis xyz="0 1 0"/>
       <limit effort="0.0" lower="-3.14159" upper="3.14159" velocity="0.0"/>
    </joint>
    <link name="Link2">
        <inertial>
            <origin xyz="0.0 0.5711369646380862 0.0" rpy="0 0 0"/>
            <mass value="0.19489078725880413" />
            <inertia ixx="100" ixy="0" ixz="0" iyy="100" iyz="0" izz="100" />
        </inertial>
        <visual>
            <origin xyz="0.0 0.5711369646380862 0.0" rpy="0 0 0"/>
            <geometry>
                <box size="0.6143654798570279 1.1422739292761723 0.277711740122365" />
            </geometry>
            <material name="No Sensor">
                <color rgba="0.184 0.553 0.933 1.0"/>
            </material>
        </visual>
        <collision>
            <origin xyz="0.0 0.5711369646380862 0.0" rpy="0 0 0"/>
            <geometry>
                <box size="0.6143654798570279 1.1422739292761723 0.277711740122365" />
            </geometry>
        </collision>
    </link>
    <joint name="Link2_Link3" type="revolute">
       <parent link="Link2"/>
       <child  link="Link3"/>
       <origin rpy="0 0 0" xyz="-0.30718273992851397 0.5711369646380862 0.0" />
       <axis xyz="0 1 0"/>
       <limit effort="0.0" lower="-3.14159" upper="3.14159" velocity="0.0"/>
    </joint>
    <link name="Link3">
        <inertial>
            <origin xyz="-0.1676950695615853 0.0 0.0" rpy="0 0 0"/>
            <mass value="0.3549768114735983" />
            <inertia ixx="100" ixy="0" ixz="0" iyy="100" iyz="0" izz="100" />
        </inertial>
        <visual>
            <origin xyz="-0.1676950695615853 0.0 0.0" rpy="0 0 0"/>
            <geometry>
                <box size="0.3353901391231706 1.2314104657541125 0.8595019257734966" />
            </geometry>
            <material name="Sensor">
                <color rgba="0.239 0.875 0.282 1.0"/>
            </material>
        </visual>
        <collision>
            <origin xyz="-0.1676950695615853 0.0 0.0" rpy="0 0 0"/>
            <geometry>
                <box size="0.3353901391231706 1.2314104657541125 0.8595019257734966" />
            </geometry>
        </collision>
    </link>
    <joint name="Link3_Link4" type="revolute">
       <parent link="Link3"/>
       <child  link="Link4"/>
       <origin rpy="0 0 0" xyz="-0.1676950695615853 -0.6157052328770563 0.0" />
       <axis xyz="0 1 0"/>
       <limit effort="0.0" lower="-3.14159" upper="3.14159" velocity="0.0"/>
    </joint>
    <link name="Link4">
        <inertial>
            <origin xyz="0.0 -0.20960709234684527 0.0" rpy="0 0 0"/>
            <mass value="0.2518651895832021" />
            <inertia ixx="100" ixy="0" ixz="0" iyy="100" iyz="0" izz="100" />
        </inertial>
        <visual>
            <origin xyz="0.0 -0.20960709234684527 0.0" rpy="0 0 0"/>
            <geometry>
                <box size="0.6676323468141833 0.41921418469369054 0.89990115308969" />
            </geometry>
            <material name="Sensor">
                <color rgba="0.239 0.875 0.282 1.0"/>
            </material>
        </visual>
        <collision>
            <origin xyz="0.0 -0.20960709234684527 0.0" rpy="0 0 0"/>
            <geometry>
                <box size="0.6676323468141833 0.41921418469369054 0.89990115308969" />
            </geometry>
        </collision>
    </link>
    <joint name="Link4_Link5" type="revolute">
       <parent link="Link4"/>
       <child  link="Link5"/>
       <origin rpy="0 0 0" xyz="0.0 -0.41921418469369054 0.0" />
       <axis xyz="1 0 0"/>
       <limit effort="0.0" lower="-3.14159" upper="3.14159" velocity="0.0"/>
    </joint>
    <link name="Link5">
        <inertial>
            <origin xyz="0.0 -0.28080695673035233 0.0" rpy="0 0 0"/>
            <mass value="0.09242717835274168" />
            <inertia ixx="100" ixy="0" ixz="0" iyy="100" iyz="0" izz="100" />
        </inertial>
        <visual>
            <origin xyz="0.0 -0.28080695673035233 0.0" rpy="0 0 0"/>
            <geometry>
                <box size="0.2869750683593578 0.5616139134607047 0.5734791969890753" />
            </geometry>
            <material name="Sensor">
                <color rgba="0.239 0.875 0.282 1.0"/>
            </material>
        </visual>
        <collision>
            <origin xyz="0.0 -0.28080695673035233 0.0" rpy="0 0 0"/>
            <geometry>
                <box size="0.2869750683593578 0.5616139134607047 0.5734791969890753" />
            </geometry>
        </collision>
    </link>
    <joint name="Link5_Link6" type="revolute">
       <parent link="Link5"/>
       <child  link="Link6"/>
       <origin rpy="0 0 0" xyz="0.1434875341796789 -0.28080695673035233 0.0" />
       <axis xyz="0 0 1"/>
       <limit effort="0.0" lower="-3.14159" upper="3.14159" velocity="0.0"/>
    </joint>
    <link name="Link6">
        <inertial>
            <origin xyz="0.4287209467572768 0.0 0.0" rpy="0 0 0"/>
            <mass value="0.8466040354946436" />
            <inertia ixx="100" ixy="0" ixz="0" iyy="100" iyz="0" izz="100" />
        </inertial>
        <visual>
            <origin xyz="0.4287209467572768 0.0 0.0" rpy="0 0 0"/>
            <geometry>
                <box size="0.8574418935145536 0.9008312566756971 1.0960545992364694" />
            </geometry>
            <material name="No Sensor">
                <color rgba="0.184 0.553 0.933 1.0"/>
            </material>
        </visual>
        <collision>
            <origin xyz="0.4287209467572768 0.0 0.0" rpy="0 0 0"/>
            <geometry>
                <box size="0.8574418935145536 0.9008312566756971 1.0960545992364694" />
            </geometry>
        </collision>
    </link>
    <joint name="Link6_Link7" type="revolute">
       <parent link="Link6"/>
       <child  link="Link7"/>
       <origin rpy="0 0 0" xyz="0.4287209467572768 0.0 -0.5480272996182347" />
       <axis xyz="0 1 0"/>
       <limit effort="0.0" lower="-3.14159" upper="3.14159" velocity="0.0"/>
    </joint>
    <link name="Link7">
        <inertial>
            <origin xyz="0.0 0.0 -0.4140869592042691" rpy="0 0 0"/>
            <mass value="0.8879164544716504" />
            <inertia ixx="100" ixy="0" ixz="0" iyy="100" iyz="0" izz="100" />
        </inertial>
        <visual>
            <origin xyz="0.0 0.0 -0.4140869592042691" rpy="0 0 0"/>
            <geometry>
                <box size="1.1775809425975434 0.9104577276110997 0.8281739184085382" />
            </geometry>
            <material name="No Sensor">
                <color rgba="0.184 0.553 0.933 1.0"/>
            </material>
        </visual>
        <collision>
            <origin xyz="0.0 0.0 -0.4140869592042691" rpy="0 0 0"/>
            <geometry>
                <box size="1.1775809425975434 0.9104577276110997 0.8281739184085382" />
            </geometry>
        </collision>
    </link>
    <joint name="Link7_Link8" type="revolute">
       <parent link="Link7"/>
       <child  link="Link8"/>
       <origin rpy="0 0 0" xyz="-0.5887904712987717 0.0 -0.4140869592042691" />
       <axis xyz="0 1 0"/>
       <limit effort="0.0" lower="-3.14159" upper="3.14159" velocity="0.0"/>
    </joint>
    <link name="Link8">
        <inertial>
            <origin xyz="-0.3243577718145042 0.0 0.0" rpy="0 0 0"/>
            <mass value="0.31891360077379155" />
            <inertia ixx="100" ixy="0" ixz="0" iyy="100" iyz="0" izz="100" />
        </inertial>
        <visual>
            <origin xyz="-0.3243577718145042 0.0 0.0" rpy="0 0 0"/>
            <geometry>
                <box size="0.6487155436290084 1.216612492642142 0.4040791718323574" />
            </geometry>
            <material name="No Sensor">
                <color rgba="0.184 0.553 0.933 1.0"/>
            </material>
        </visual>
        <collision>
            <origin xyz="-0.3243577718145042 0.0 0.0" rpy="0 0 0"/>
            <geometry>
                <box size="0.6487155436290084 1.216612492642142 0.4040791718323574" />
            </geometry>
        </collision>
    </link>
    <joint name="Link8_Link9" type="revolute">
       <parent link="Link8"/>
       <child  link="Link9"/>
       <origin rpy="0 0 0" xyz="-0.6487155436290084 0.0 0.0" />
       <axis xyz="0 0 1"/>
       <limit effort="0.0" lower="-3.14159" upper="3.14159" velocity="0.0"/>
    </joint>
    <link name="Link9">
        <inertial>
            <origin xyz="-0.5725434043243243 0.0 0.0" rpy="0 0 0"/>
            <mass value="0.5129563089232644" />
            <inertia ixx="100" ixy="0" ixz="0" iyy="100" iyz="0" izz="100" />
        </inertial>
        <visual>
            <origin xyz="-0.5725434043243243 0.0 0.0" rpy="0 0 0"/>
            <geometry>
                <box size="1.1450868086486485 0.5610130678848415 0.798489089666104" />
            </geometry>
            <material name="No Sensor">
                <color rgba="0.184 0.553 0.933 1.0"/>
            </material>
        </visual>
        <collision>
            <origin xyz="-0.5725434043243243 0.0 0.0" rpy="0 0 0"/>
            <geometry>
                <box size="1.1450868086486485 0.5610130678848415 0.798489089666104" />
            </geometry>
        </collision>
    </link>
</robot>