<robot name = "robot">
    <link name="Link0">
        <inertial>
            <origin xyz="0 0 2" rpy="0 0 0"/>
            <mass value="0.21343461435300348" />
            <inertia ixx="100" ixy="0" ixz="0" iyy="100" iyz="0" izz="100" />
        </inertial>
        <visual>
            <origin xyz="0 0 2" rpy="0 0 0"/>
            <geometry>
                <box size="0.47286389225356085 0.4443950205047229 1.0156861187707538" />
            </geometry>
            <material name="No Sensor">
                <color rgba="0.184 0.553 0.933 1.0"/>
            </material>
        </visual>
        <collision>
            <origin xyz="0 0 2" rpy="0 0 0"/>
            <geometry>
                <box size="0.47286389225356085 0.4443950205047229 1.0156861187707538" />
            </geometry>
        </collision>
    </link>
    <joint name="Link0_Link1" type="revolute">
       <parent link="Link0"/>
       <child  link="Link1"/>
       <origin rpy="0 0 0" xyz="0.23643194612678042 0 2" />
       <axis xyz="1 0 0"/>
       <limit effort="0.0" lower="-3.14159" upper="3.14159" velocity="0.0"/>
    </joint>
    <link name="Link1">
        <inertial>
            <origin xyz="0.6143469094875227 0 0" rpy="0 0 0"/>
            <mass value="0.1630009619324722" />
            <inertia ixx="100" ixy="0" ixz="0" iyy="100" iyz="0" izz="100" />
        </inertial>
        <visual>
            <origin xyz="0.6143469094875227 0 0" rpy="0 0 0"/>
            <geometry>
                <box size="1.2286938189750454 0.2659099615925625 0.49889814198257976" />
            </geometry>
            <material name="Sensor">
                <color rgba="0.239 0.875 0.282 1.0"/>
            </material>
        </visual>
        <collision>
            <origin xyz="0.6143469094875227 0 0" rpy="0 0 0"/>
            <geometry>
                <box size="1.2286938189750454 0.2659099615925625 0.49889814198257976" />
            </geometry>
        </collision>
    </link>
    <joint name="Link1_Link2" type="revolute">
       <parent link="Link1"/>
       <child  link="Link2"/>
       <origin rpy="0 0 0" xyz="1.2286938189750454 0.0 0.0" />
       <axis xyz="0 1 0"/>
       <limit effort="0.0" lower="-3.14159" upper="3.14159" velocity="0.0"/>
    </joint>
    <link name="Link2">
        <inertial>
            <origin xyz="0.521156435885374 0.0 0.0" rpy="0 0 0"/>
            <mass value="0.5010257923422422" />
            <inertia ixx="100" ixy="0" ixz="0" iyy="100" iyz="0" izz="100" />
        </inertial>
        <visual>
            <origin xyz="0.521156435885374 0.0 0.0" rpy="0 0 0"/>
            <geometry>
                <box size="1.042312871770748 0.9691652977533548 0.4959799577394348" />
            </geometry>
            <material name="No Sensor">
                <color rgba="0.184 0.553 0.933 1.0"/>
            </material>
        </visual>
        <collision>
            <origin xyz="0.521156435885374 0.0 0.0" rpy="0 0 0"/>
            <geometry>
                <box size="1.042312871770748 0.9691652977533548 0.4959799577394348" />
            </geometry>
        </collision>
    </link>
    <joint name="Link2_Link3" type="revolute">
       <parent link="Link2"/>
       <child  link="Link3"/>
       <origin rpy="0 0 0" xyz="1.042312871770748 0.0 0.0" />
       <axis xyz="0 1 0"/>
       <limit effort="0.0" lower="-3.14159" upper="3.14159" velocity="0.0"/>
    </joint>
    <link name="Link3">
        <inertial>
            <origin xyz="0.40244619053792263 0.0 0.0" rpy="0 0 0"/>
            <mass value="0.6533109446732146" />
            <inertia ixx="100" ixy="0" ixz="0" iyy="100" iyz="0" izz="100" />
        </inertial>
        <visual>
            <origin xyz="0.40244619053792263 0.0 0.0" rpy="0 0 0"/>
            <geometry>
                <box size="0.8048923810758453 0.8355857940990207 0.9713842766472296" />
            </geometry>
            <material name="Sensor">
                <color rgba="0.239 0.875 0.282 1.0"/>
            </material>
        </visual>
        <collision>
            <origin xyz="0.40244619053792263 0.0 0.0" rpy="0 0 0"/>
            <geometry>
                <box size="0.8048923810758453 0.8355857940990207 0.9713842766472296" />
            </geometry>
        </collision>
    </link>
    <joint name="Link3_Link4" type="revolute">
       <parent link="Link3"/>
       <child  link="Link4"/>
       <origin rpy="0 0 0" xyz="0.40244619053792263 0.0 -0.4856921383236148" />
       <axis xyz="0 0 1"/>
       <limit effort="0.0" lower="-3.14159" upper="3.14159" velocity="0.0"/>
    </joint>
    <link name="Link4">
        <inertial>
            <origin xyz="0.0 0.0 -0.2790047354104448" rpy="0 0 0"/>
            <mass value="0.2607846877066183" />
            <inertia ixx="100" ixy="0" ixz="0" iyy="100" iyz="0" izz="100" />
        </inertial>
        <visual>
            <origin xyz="0.0 0.0 -0.2790047354104448" rpy="0 0 0"/>
            <geometry>
                <box size="0.7136737112127011 0.6548484715227227 0.5580094708208896" />
            </geometry>
            <material name="Sensor">
                <color rgba="0.239 0.875 0.282 1.0"/>
            </material>
        </visual>
        <collision>
            <origin xyz="0.0 0.0 -0.2790047354104448" rpy="0 0 0"/>
            <geometry>
                <box size="0.7136737112127011 0.6548484715227227 0.5580094708208896" />
            </geometry>
        </collision>
    </link>
    <joint name="Link4_Link5" type="revolute">
       <parent link="Link4"/>
       <child  link="Link5"/>
       <origin rpy="0 0 0" xyz="0.35683685560635053 0.0 -0.2790047354104448" />
       <axis xyz="1 0 0"/>
       <limit effort="0.0" lower="-3.14159" upper="3.14159" velocity="0.0"/>
    </joint>
    <link name="Link5">
        <inertial>
            <origin xyz="0.24415445420341136 0.0 0.0" rpy="0 0 0"/>
            <mass value="0.14983420393001523" />
            <inertia ixx="100" ixy="0" ixz="0" iyy="100" iyz="0" izz="100" />
        </inertial>
        <visual>
            <origin xyz="0.24415445420341136 0.0 0.0" rpy="0 0 0"/>
            <geometry>
                <box size="0.48830890840682273 0.34250335815060395 0.8958833874176423" />
            </geometry>
            <material name="Sensor">
                <color rgba="0.239 0.875 0.282 1.0"/>
            </material>
        </visual>
        <collision>
            <origin xyz="0.24415445420341136 0.0 0.0" rpy="0 0 0"/>
            <geometry>
                <box size="0.48830890840682273 0.34250335815060395 0.8958833874176423" />
            </geometry>
        </collision>
    </link>
    <joint name="Link5_Link6" type="revolute">
       <parent link="Link5"/>
       <child  link="Link6"/>
       <origin rpy="0 0 0" xyz="0.24415445420341136 0.0 -0.44794169370882114" />
       <axis xyz="0 0 1"/>
       <limit effort="0.0" lower="-3.14159" upper="3.14159" velocity="0.0"/>
    </joint>
    <link name="Link6">
        <inertial>
            <origin xyz="0.0 0.0 -0.12657286023218622" rpy="0 0 0"/>
            <mass value="0.21819980400643638" />
            <inertia ixx="100" ixy="0" ixz="0" iyy="100" iyz="0" izz="100" />
        </inertial>
        <visual>
            <origin xyz="0.0 0.0 -0.12657286023218622" rpy="0 0 0"/>
            <geometry>
                <box size="0.9195704485402362 0.9373434739168471 0.25314572046437245" />
            </geometry>
            <material name="Sensor">
                <color rgba="0.239 0.875 0.282 1.0"/>
            </material>
        </visual>
        <collision>
            <origin xyz="0.0 0.0 -0.12657286023218622" rpy="0 0 0"/>
            <geometry>
                <box size="0.9195704485402362 0.9373434739168471 0.25314572046437245" />
            </geometry>
        </collision>
    </link>
    <joint name="Link6_Link7" type="revolute">
       <parent link="Link6"/>
       <child  link="Link7"/>
       <origin rpy="0 0 0" xyz="0.0 0.0 -0.25314572046437245" />
       <axis xyz="1 0 0"/>
       <limit effort="0.0" lower="-3.14159" upper="3.14159" velocity="0.0"/>
    </joint>
    <link name="Link7">
        <inertial>
            <origin xyz="0.0 0.0 -0.3883046678531537" rpy="0 0 0"/>
            <mass value="0.19913116331222577" />
            <inertia ixx="100" ixy="0" ixz="0" iyy="100" iyz="0" izz="100" />
        </inertial>
        <visual>
            <origin xyz="0.0 0.0 -0.3883046678531537" rpy="0 0 0"/>
            <geometry>
                <box size="0.6882530325209861 0.37255336491136315 0.7766093357063074" />
            </geometry>
            <material name="No Sensor">
                <color rgba="0.184 0.553 0.933 1.0"/>
            </material>
        </visual>
        <collision>
            <origin xyz="0.0 0.0 -0.3883046678531537" rpy="0 0 0"/>
            <geometry>
                <box size="0.6882530325209861 0.37255336491136315 0.7766093357063074" />
            </geometry>
        </collision>
    </link>
    <joint name="Link7_Link8" type="revolute">
       <parent link="Link7"/>
       <child  link="Link8"/>
       <origin rpy="0 0 0" xyz="0.0 -0.18627668245568157 -0.3883046678531537" />
       <axis xyz="0 0 1"/>
       <limit effort="0.0" lower="-3.14159" upper="3.14159" velocity="0.0"/>
    </joint>
    <link name="Link8">
        <inertial>
            <origin xyz="0.0 -0.37463850548166905 0.0" rpy="0 0 0"/>
            <mass value="0.5755622525655443" />
            <inertia ixx="100" ixy="0" ixz="0" iyy="100" iyz="0" izz="100" />
        </inertial>
        <visual>
            <origin xyz="0.0 -0.37463850548166905 0.0" rpy="0 0 0"/>
            <geometry>
                <box size="1.2297396209018743 0.7492770109633381 0.6246499792735207" />
            </geometry>
            <material name="No Sensor">
                <color rgba="0.184 0.553 0.933 1.0"/>
            </material>
        </visual>
        <collision>
            <origin xyz="0.0 -0.37463850548166905 0.0" rpy="0 0 0"/>
            <geometry>
                <box size="1.2297396209018743 0.7492770109633381 0.6246499792735207" />
            </geometry>
        </collision>
    </link>
    <joint name="Link8_Link9" type="revolute">
       <parent link="Link8"/>
       <child  link="Link9"/>
       <origin rpy="0 0 0" xyz="0.0 -0.37463850548166905 -0.31232498963676036" />
       <axis xyz="0 1 0"/>
       <limit effort="0.0" lower="-3.14159" upper="3.14159" velocity="0.0"/>
    </joint>
    <link name="Link9">
        <inertial>
            <origin xyz="0.0 0.0 -0.2685616887643977" rpy="0 0 0"/>
            <mass value="0.6960965402739713" />
            <inertia ixx="100" ixy="0" ixz="0" iyy="100" iyz="0" izz="100" />
        </inertial>
        <visual>
            <origin xyz="0.0 0.0 -0.2685616887643977" rpy="0 0 0"/>
            <geometry>
                <box size="1.0638399923945956 1.2182014382446995 0.5371233775287954" />
            </geometry>
            <material name="No Sensor">
                <color rgba="0.184 0.553 0.933 1.0"/>
            </material>
        </visual>
        <collision>
            <origin xyz="0.0 0.0 -0.2685616887643977" rpy="0 0 0"/>
            <geometry>
                <box size="1.0638399923945956 1.2182014382446995 0.5371233775287954" />
            </geometry>
        </collision>
    </link>
</robot>