<robot name = "robot">
    <link name="Link0">
        <inertial>
            <origin xyz="0 0 2" rpy="0 0 0"/>
            <mass value="0.24159438313137246" />
            <inertia ixx="100" ixy="0" ixz="0" iyy="100" iyz="0" izz="100" />
        </inertial>
        <visual>
            <origin xyz="0 0 2" rpy="0 0 0"/>
            <geometry>
                <box size="0.4719931710897395 1.1207323061773764 0.4567191553394264" />
            </geometry>
            <material name="Sensor">
                <color rgba="0.239 0.875 0.282 1.0"/>
            </material>
        </visual>
        <collision>
            <origin xyz="0 0 2" rpy="0 0 0"/>
            <geometry>
                <box size="0.4719931710897395 1.1207323061773764 0.4567191553394264" />
            </geometry>
        </collision>
    </link>
    <joint name="Link0_Link1" type="revolute">
       <parent link="Link0"/>
       <child  link="Link1"/>
       <origin rpy="0 0 0" xyz="0.23599658554486974 0 2" />
       <axis xyz="1 0 0"/>
       <limit effort="0.0" lower="-3.14159" upper="3.14159" velocity="0.0"/>
    </joint>
    <link name="Link1">
        <inertial>
            <origin xyz="0.5714300757180009 0 0" rpy="0 0 0"/>
            <mass value="0.7124975516153823" />
            <inertia ixx="100" ixy="0" ixz="0" iyy="100" iyz="0" izz="100" />
        </inertial>
        <visual>
            <origin xyz="0.5714300757180009 0 0" rpy="0 0 0"/>
            <geometry>
                <box size="1.1428601514360017 0.5819798053011772 1.0712291230578317" />
            </geometry>
            <material name="No Sensor">
                <color rgba="0.184 0.553 0.933 1.0"/>
            </material>
        </visual>
        <collision>
            <origin xyz="0.5714300757180009 0 0" rpy="0 0 0"/>
            <geometry>
                <box size="1.1428601514360017 0.5819798053011772 1.0712291230578317" />
            </geometry>
        </collision>
    </link>
    <joint name="Link1_Link2" type="revolute">
       <parent link="Link1"/>
       <child  link="Link2"/>
       <origin rpy="0 0 0" xyz="0.5714300757180009 0.0 -0.5356145615289158" />
       <axis xyz="0 0 1"/>
       <limit effort="0.0" lower="-3.14159" upper="3.14159" velocity="0.0"/>
    </joint>
    <link name="Link2">
        <inertial>
            <origin xyz="0.0 0.0 -0.24438846638816086" rpy="0 0 0"/>
            <mass value="0.09816769621995919" />
            <inertia ixx="100" ixy="0" ixz="0" iyy="100" iyz="0" izz="100" />
        </inertial>
        <visual>
            <origin xyz="0.0 0.0 -0.24438846638816086" rpy="0 0 0"/>
            <geometry>
                <box size="0.7420568700511907 0.2706578996279936 0.4887769327763217" />
            </geometry>
            <material name="Sensor">
                <color rgba="0.239 0.875 0.282 1.0"/>
            </material>
        </visual>
        <collision>
            <origin xyz="0.0 0.0 -0.24438846638816086" rpy="0 0 0"/>
            <geometry>
                <box size="0.7420568700511907 0.2706578996279936 0.4887769327763217" />
            </geometry>
        </collision>
    </link>
    <joint name="Link2_Link3" type="revolute">
       <parent link="Link2"/>
       <child  link="Link3"/>
       <origin rpy="0 0 0" xyz="0.0 -0.1353289498139968 -0.24438846638816086" />
       <axis xyz="0 1 0"/>
       <limit effort="0.0" lower="-3.14159" upper="3.14159" velocity="0.0"/>
    </joint>
    <link name="Link3">
        <inertial>
            <origin xyz="0.0 -0.6092703314104659 0.0" rpy="0 0 0"/>
            <mass value="1.5321151085328013" />
            <inertia ixx="100" ixy="0" ixz="0" iyy="100" iyz="0" izz="100" />
        </inertial>
        <visual>
            <origin xyz="0.0 -0.6092703314104659 0.0" rpy="0 0 0"/>
            <geometry>
                <box size="1.1234294027918161 1.2185406628209319 1.11919454021392" />
            </geometry>
            <material name="No Sensor">
                <color rgba="0.184 0.553 0.933 1.0"/>
            </material>
        </visual>
        <collision>
            <origin xyz="0.0 -0.6092703314104659 0.0" rpy="0 0 0"/>
            <geometry>
                <box size="1.1234294027918161 1.2185406628209319 1.11919454021392" />
            </geometry>
        </collision>
    </link>
    <joint name="Link3_Link4" type="revolute">
       <parent link="Link3"/>
       <child  link="Link4"/>
       <origin rpy="0 0 0" xyz="0.0 -0.6092703314104659 0.55959727010696" />
       <axis xyz="1 0 0"/>
       <limit effort="0.0" lower="-3.14159" upper="3.14159" velocity="0.0"/>
    </joint>
    <link name="Link4">
        <inertial>
            <origin xyz="0.0 0.0 0.37288664656707304" rpy="0 0 0"/>
            <mass value="0.14599907611527876" />
            <inertia ixx="100" ixy="0" ixz="0" iyy="100" iyz="0" izz="100" />
        </inertial>
        <visual>
            <origin xyz="0.0 0.0 0.37288664656707304" rpy="0 0 0"/>
            <geometry>
                <box size="0.26037415388569995 0.7518745921487388 0.7457732931341461" />
            </geometry>
            <material name="Sensor">
                <color rgba="0.239 0.875 0.282 1.0"/>
            </material>
        </visual>
        <collision>
            <origin xyz="0.0 0.0 0.37288664656707304" rpy="0 0 0"/>
            <geometry>
                <box size="0.26037415388569995 0.7518745921487388 0.7457732931341461" />
            </geometry>
        </collision>
    </link>
    <joint name="Link4_Link5" type="revolute">
       <parent link="Link4"/>
       <child  link="Link5"/>
       <origin rpy="0 0 0" xyz="0.0 0.3759372960743694 0.37288664656707304" />
       <axis xyz="0 1 0"/>
       <limit effort="0.0" lower="-3.14159" upper="3.14159" velocity="0.0"/>
    </joint>
    <link name="Link5">
        <inertial>
            <origin xyz="0.0 0.13537597467970075 0.0" rpy="0 0 0"/>
            <mass value="0.2443504350150486" />
            <inertia ixx="100" ixy="0" ixz="0" iyy="100" iyz="0" izz="100" />
        </inertial>
        <visual>
            <origin xyz="0.0 0.13537597467970075 0.0" rpy="0 0 0"/>
            <geometry>
                <box size="1.0213206432667459 0.2707519493594015 0.8836482349262754" />
            </geometry>
            <material name="No Sensor">
                <color rgba="0.184 0.553 0.933 1.0"/>
            </material>
        </visual>
        <collision>
            <origin xyz="0.0 0.13537597467970075 0.0" rpy="0 0 0"/>
            <geometry>
                <box size="1.0213206432667459 0.2707519493594015 0.8836482349262754" />
            </geometry>
        </collision>
    </link>
    <joint name="Link5_Link6" type="revolute">
       <parent link="Link5"/>
       <child  link="Link6"/>
       <origin rpy="0 0 0" xyz="0.0 0.13537597467970075 -0.4418241174631377" />
       <axis xyz="0 0 1"/>
       <limit effort="0.0" lower="-3.14159" upper="3.14159" velocity="0.0"/>
    </joint>
    <link name="Link6">
        <inertial>
            <origin xyz="0.0 0.0 -0.3566092632491723" rpy="0 0 0"/>
            <mass value="0.0826955686865952" />
            <inertia ixx="100" ixy="0" ixz="0" iyy="100" iyz="0" izz="100" />
        </inertial>
        <visual>
            <origin xyz="0.0 0.0 -0.3566092632491723" rpy="0 0 0"/>
            <geometry>
                <box size="0.4302696888767692 0.2694752414876246 0.7132185264983446" />
            </geometry>
            <material name="Sensor">
                <color rgba="0.239 0.875 0.282 1.0"/>
            </material>
        </visual>
        <collision>
            <origin xyz="0.0 0.0 -0.3566092632491723" rpy="0 0 0"/>
            <geometry>
                <box size="0.4302696888767692 0.2694752414876246 0.7132185264983446" />
            </geometry>
        </collision>
    </link>
    <joint name="Link6_Link7" type="revolute">
       <parent link="Link6"/>
       <child  link="Link7"/>
       <origin rpy="0 0 0" xyz="0.0 0.1347376207438123 -0.3566092632491723" />
       <axis xyz="0 1 0"/>
       <limit effort="0.0" lower="-3.14159" upper="3.14159" velocity="0.0"/>
    </joint>
    <link name="Link7">
        <inertial>
            <origin xyz="0.0 0.4950248482577024 0.0" rpy="0 0 0"/>
            <mass value="0.20539853719865275" />
            <inertia ixx="100" ixy="0" ixz="0" iyy="100" iyz="0" izz="100" />
        </inertial>
        <visual>
            <origin xyz="0.0 0.4950248482577024 0.0" rpy="0 0 0"/>
            <geometry>
                <box size="0.40416284237967237 0.9900496965154048 0.5133150151851347" />
            </geometry>
            <material name="Sensor">
                <color rgba="0.239 0.875 0.282 1.0"/>
            </material>
        </visual>
        <collision>
            <origin xyz="0.0 0.4950248482577024 0.0" rpy="0 0 0"/>
            <geometry>
                <box size="0.40416284237967237 0.9900496965154048 0.5133150151851347" />
            </geometry>
        </collision>
    </link>
    <joint name="Link7_Link8" type="revolute">
       <parent link="Link7"/>
       <child  link="Link8"/>
       <origin rpy="0 0 0" xyz="0.0 0.9900496965154048 0.0" />
       <axis xyz="0 1 0"/>
       <limit effort="0.0" lower="-3.14159" upper="3.14159" velocity="0.0"/>
    </joint>
    <link name="Link8">
        <inertial>
            <origin xyz="0.0 0.24377061001745615 0.0" rpy="0 0 0"/>
            <mass value="0.5382643443625381" />
            <inertia ixx="100" ixy="0" ixz="0" iyy="100" iyz="0" izz="100" />
        </inertial>
        <visual>
            <origin xyz="0.0 0.24377061001745615 0.0" rpy="0 0 0"/>
            <geometry>
                <box size="1.0277024105738202 0.4875412200349123 1.0742785326613684" />
            </geometry>
            <material name="Sensor">
                <color rgba="0.239 0.875 0.282 1.0"/>
            </material>
        </visual>
        <collision>
            <origin xyz="0.0 0.24377061001745615 0.0" rpy="0 0 0"/>
            <geometry>
                <box size="1.0277024105738202 0.4875412200349123 1.0742785326613684" />
            </geometry>
        </collision>
    </link>
    <joint name="Link8_Link9" type="revolute">
       <parent link="Link8"/>
       <child  link="Link9"/>
       <origin rpy="0 0 0" xyz="0.5138512052869101 0.24377061001745615 0.0" />
       <axis xyz="0 1 0"/>
       <limit effort="0.0" lower="-3.14159" upper="3.14159" velocity="0.0"/>
    </joint>
    <link name="Link9">
        <inertial>
            <origin xyz="0.3819716718863451 0.0 0.0" rpy="0 0 0"/>
            <mass value="0.8757712431768542" />
            <inertia ixx="100" ixy="0" ixz="0" iyy="100" iyz="0" izz="100" />
        </inertial>
        <visual>
            <origin xyz="0.3819716718863451 0.0 0.0" rpy="0 0 0"/>
            <geometry>
                <box size="0.7639433437726902 1.0231650520792968 1.1204276857248128" />
            </geometry>
            <material name="No Sensor">
                <color rgba="0.184 0.553 0.933 1.0"/>
            </material>
        </visual>
        <collision>
            <origin xyz="0.3819716718863451 0.0 0.0" rpy="0 0 0"/>
            <geometry>
                <box size="0.7639433437726902 1.0231650520792968 1.1204276857248128" />
            </geometry>
        </collision>
    </link>
</robot>