<robot name = "robot">
    <link name="Link0">
        <inertial>
            <origin xyz="0 0 2" rpy="0 0 0"/>
            <mass value="0.9306917805410074" />
            <inertia ixx="100" ixy="0" ixz="0" iyy="100" iyz="0" izz="100" />
        </inertial>
        <visual>
            <origin xyz="0 0 2" rpy="0 0 0"/>
            <geometry>
                <box size="1.0501443119174996 1.161308354273646 0.7631490075412158" />
            </geometry>
            <material name="Sensor">
                <color rgba="0.239 0.875 0.282 1.0"/>
            </material>
        </visual>
        <collision>
            <origin xyz="0 0 2" rpy="0 0 0"/>
            <geometry>
                <box size="1.0501443119174996 1.161308354273646 0.7631490075412158" />
            </geometry>
        </collision>
    </link>
    <joint name="Link0_Link1" type="revolute">
       <parent link="Link0"/>
       <child  link="Link1"/>
       <origin rpy="0 0 0" xyz="0.5250721559587498 0 2" />
       <axis xyz="1 0 0"/>
       <limit effort="0.0" lower="-3.14159" upper="3.14159" velocity="0.0"/>
    </joint>
    <link name="Link1">
        <inertial>
            <origin xyz="0.33971101484032606 0 0" rpy="0 0 0"/>
            <mass value="0.12153871211881985" />
            <inertia ixx="100" ixy="0" ixz="0" iyy="100" iyz="0" izz="100" />
        </inertial>
        <visual>
            <origin xyz="0.33971101484032606 0 0" rpy="0 0 0"/>
            <geometry>
                <box size="0.6794220296806521 0.34159480217154525 0.5236773038049665" />
            </geometry>
            <material name="Sensor">
                <color rgba="0.239 0.875 0.282 1.0"/>
            </material>
        </visual>
        <collision>
            <origin xyz="0.33971101484032606 0 0" rpy="0 0 0"/>
            <geometry>
                <box size="0.6794220296806521 0.34159480217154525 0.5236773038049665" />
            </geometry>
        </collision>
    </link>
    <joint name="Link1_Link2" type="revolute">
       <parent link="Link1"/>
       <child  link="Link2"/>
       <origin rpy="0 0 0" xyz="0.33971101484032606 0.0 -0.26183865190248323" />
       <axis xyz="0 0 1"/>
       <limit effort="0.0" lower="-3.14159" upper="3.14159" velocity="0.0"/>
    </joint>
    <link name="Link2">
        <inertial>
            <origin xyz="0.0 0.0 -0.4355946934354374" rpy="0 0 0"/>
            <mass value="0.49110169902307577" />
            <inertia ixx="100" ixy="0" ixz="0" iyy="100" iyz="0" izz="100" />
        </inertial>
        <visual>
            <origin xyz="0.0 0.0 -0.4355946934354374" rpy="0 0 0"/>
            <geometry>
                <box size="1.1366478145458545 0.4959443412735529 0.8711893868708748" />
            </geometry>
            <material name="Sensor">
                <color rgba="0.239 0.875 0.282 1.0"/>
            </material>
        </visual>
        <collision>
            <origin xyz="0.0 0.0 -0.4355946934354374" rpy="0 0 0"/>
            <geometry>
                <box size="1.1366478145458545 0.4959443412735529 0.8711893868708748" />
            </geometry>
        </collision>
    </link>
    <joint name="Link2_Link3" type="revolute">
       <parent link="Link2"/>
       <child  link="Link3"/>
       <origin rpy="0 0 0" xyz="0.0 0.0 -0.8711893868708748" />
       <axis xyz="0 1 0"/>
       <limit effort="0.0" lower="-3.14159" upper="3.14159" velocity="0.0"/>
    </joint>
    <link name="Link3">
        <inertial>
            <origin xyz="0.0 0.0 -0.574684265696438" rpy="0 0 0"/>
            <mass value="0.29488208948527606" />
            <inertia ixx="100" ixy="0" ixz="0" iyy="100" iyz="0" izz="100" />
        </inertial>
        <visual>
            <origin xyz="0.0 0.0 -0.574684265696438" rpy="0 0 0"/>
            <geometry>
                <box size="0.7450073958428007 0.34437253593421435 1.149368531392876" />
            </geometry>
            <material name="Sensor">
                <color rgba="0.239 0.875 0.282 1.0"/>
            </material>
        </visual>
        <collision>
            <origin xyz="0.0 0.0 -0.574684265696438" rpy="0 0 0"/>
            <geometry>
                <box size="0.7450073958428007 0.34437253593421435 1.149368531392876" />
            </geometry>
        </collision>
    </link>
    <joint name="Link3_Link4" type="revolute">
       <parent link="Link3"/>
       <child  link="Link4"/>
       <origin rpy="0 0 0" xyz="-0.37250369792140037 0.0 -0.574684265696438" />
       <axis xyz="0 1 0"/>
       <limit effort="0.0" lower="-3.14159" upper="3.14159" velocity="0.0"/>
    </joint>
    <link name="Link4">
        <inertial>
            <origin xyz="-0.15888541622905689 0.0 0.0" rpy="0 0 0"/>
            <mass value="0.36140601434149766" />
            <inertia ixx="100" ixy="0" ixz="0" iyy="100" iyz="0" izz="100" />
        </inertial>
        <visual>
            <origin xyz="-0.15888541622905689 0.0 0.0" rpy="0 0 0"/>
            <geometry>
                <box size="0.31777083245811377 0.930702325466581 1.2219981399843842" />
            </geometry>
            <material name="Sensor">
                <color rgba="0.239 0.875 0.282 1.0"/>
            </material>
        </visual>
        <collision>
            <origin xyz="-0.15888541622905689 0.0 0.0" rpy="0 0 0"/>
            <geometry>
                <box size="0.31777083245811377 0.930702325466581 1.2219981399843842" />
            </geometry>
        </collision>
    </link>
    <joint name="Link4_Link5" type="revolute">
       <parent link="Link4"/>
       <child  link="Link5"/>
       <origin rpy="0 0 0" xyz="-0.15888541622905689 -0.4653511627332905 0.0" />
       <axis xyz="0 1 0"/>
       <limit effort="0.0" lower="-3.14159" upper="3.14159" velocity="0.0"/>
    </joint>
    <link name="Link5">
        <inertial>
            <origin xyz="0.0 -0.2879543602291878 0.0" rpy="0 0 0"/>
            <mass value="0.17870448661954774" />
            <inertia ixx="100" ixy="0" ixz="0" iyy="100" iyz="0" izz="100" />
        </inertial>
        <visual>
            <origin xyz="0.0 -0.2879543602291878 0.0" rpy="0 0 0"/>
            <geometry>
                <box size="0.959373790820744 0.5759087204583756 0.32344016636799866" />
            </geometry>
            <material name="No Sensor">
                <color rgba="0.184 0.553 0.933 1.0"/>
            </material>
        </visual>
        <collision>
            <origin xyz="0.0 -0.2879543602291878 0.0" rpy="0 0 0"/>
            <geometry>
                <box size="0.959373790820744 0.5759087204583756 0.32344016636799866" />
            </geometry>
        </collision>
    </link>
    <joint name="Link5_Link6" type="revolute">
       <parent link="Link5"/>
       <child  link="Link6"/>
       <origin rpy="0 0 0" xyz="0.0 -0.5759087204583756 0.0" />
       <axis xyz="0 0 1"/>
       <limit effort="0.0" lower="-3.14159" upper="3.14159" velocity="0.0"/>
    </joint>
    <link name="Link6">
        <inertial>
            <origin xyz="0.0 -0.4917585091265467 0.0" rpy="0 0 0"/>
            <mass value="0.49685520257102594" />
            <inertia ixx="100" ixy="0" ixz="0" iyy="100" iyz="0" izz="100" />
        </inertial>
        <visual>
            <origin xyz="0.0 -0.4917585091265467 0.0" rpy="0 0 0"/>
            <geometry>
                <box size="0.8297370470473434 0.9835170182530933 0.6088460336535408" />
            </geometry>
            <material name="No Sensor">
                <color rgba="0.184 0.553 0.933 1.0"/>
            </material>
        </visual>
        <collision>
            <origin xyz="0.0 -0.4917585091265467 0.0" rpy="0 0 0"/>
            <geometry>
                <box size="0.8297370470473434 0.9835170182530933 0.6088460336535408" />
            </geometry>
        </collision>
    </link>
    <joint name="Link6_Link7" type="revolute">
       <parent link="Link6"/>
       <child  link="Link7"/>
       <origin rpy="0 0 0" xyz="-0.4148685235236717 -0.4917585091265467 0.0" />
       <axis xyz="0 0 1"/>
       <limit effort="0.0" lower="-3.14159" upper="3.14159" velocity="0.0"/>
    </joint>
    <link name="Link7">
        <inertial>
            <origin xyz="-0.45187573625515154 0.0 0.0" rpy="0 0 0"/>
            <mass value="0.20966931085906068" />
            <inertia ixx="100" ixy="0" ixz="0" iyy="100" iyz="0" izz="100" />
        </inertial>
        <visual>
            <origin xyz="-0.45187573625515154 0.0 0.0" rpy="0 0 0"/>
            <geometry>
                <box size="0.9037514725103031 0.8165914081984585 0.28410641739832987" />
            </geometry>
            <material name="No Sensor">
                <color rgba="0.184 0.553 0.933 1.0"/>
            </material>
        </visual>
        <collision>
            <origin xyz="-0.45187573625515154 0.0 0.0" rpy="0 0 0"/>
            <geometry>
                <box size="0.9037514725103031 0.8165914081984585 0.28410641739832987" />
            </geometry>
        </collision>
    </link>
    <joint name="Link7_Link8" type="revolute">
       <parent link="Link7"/>
       <child  link="Link8"/>
       <origin rpy="0 0 0" xyz="-0.45187573625515154 0.4082957040992293 0.0" />
       <axis xyz="1 0 0"/>
       <limit effort="0.0" lower="-3.14159" upper="3.14159" velocity="0.0"/>
    </joint>
    <link name="Link8">
        <inertial>
            <origin xyz="0.0 0.3150029017262396 0.0" rpy="0 0 0"/>
            <mass value="0.46421181588304644" />
            <inertia ixx="100" ixy="0" ixz="0" iyy="100" iyz="0" izz="100" />
        </inertial>
        <visual>
            <origin xyz="0.0 0.3150029017262396 0.0" rpy="0 0 0"/>
            <geometry>
                <box size="1.1706944530487666 0.6300058034524793 0.6294019439968851" />
            </geometry>
            <material name="No Sensor">
                <color rgba="0.184 0.553 0.933 1.0"/>
            </material>
        </visual>
        <collision>
            <origin xyz="0.0 0.3150029017262396 0.0" rpy="0 0 0"/>
            <geometry>
                <box size="1.1706944530487666 0.6300058034524793 0.6294019439968851" />
            </geometry>
        </collision>
    </link>
    <joint name="Link8_Link9" type="revolute">
       <parent link="Link8"/>
       <child  link="Link9"/>
       <origin rpy="0 0 0" xyz="0.5853472265243833 0.3150029017262396 0.0" />
       <axis xyz="0 0 1"/>
       <limit effort="0.0" lower="-3.14159" upper="3.14159" velocity="0.0"/>
    </joint>
    <link name="Link9">
        <inertial>
            <origin xyz="0.5481779378988355 0.0 0.0" rpy="0 0 0"/>
            <mass value="0.5643813359565174" />
            <inertia ixx="100" ixy="0" ixz="0" iyy="100" iyz="0" izz="100" />
        </inertial>
        <visual>
            <origin xyz="0.5481779378988355 0.0 0.0" rpy="0 0 0"/>
            <geometry>
                <box size="1.096355875797671 0.734277901996814 0.7010687942633032" />
            </geometry>
            <material name="No Sensor">
                <color rgba="0.184 0.553 0.933 1.0"/>
            </material>
        </visual>
        <collision>
            <origin xyz="0.5481779378988355 0.0 0.0" rpy="0 0 0"/>
            <geometry>
                <box size="1.096355875797671 0.734277901996814 0.7010687942633032" />
            </geometry>
        </collision>
    </link>
</robot>