<robot name = "robot">
    <link name="Link0">
        <inertial>
            <origin xyz="0 0 2" rpy="0 0 0"/>
            <mass value="0.20076288972879314" />
            <inertia ixx="100" ixy="0" ixz="0" iyy="100" iyz="0" izz="100" />
        </inertial>
        <visual>
            <origin xyz="0 0 2" rpy="0 0 0"/>
            <geometry>
                <box size="0.9125490004394449 0.46709046387190056 0.471005787567951" />
            </geometry>
            <material name="No Sensor">
                <color rgba="0.184 0.553 0.933 1.0"/>
            </material>
        </visual>
        <collision>
            <origin xyz="0 0 2" rpy="0 0 0"/>
            <geometry>
                <box size="0.9125490004394449 0.46709046387190056 0.471005787567951" />
            </geometry>
        </collision>
    </link>
    <joint name="Link0_Link1" type="revolute">
       <parent link="Link0"/>
       <child  link="Link1"/>
       <origin rpy="0 0 0" xyz="0.45627450021972243 0 2" />
       <axis xyz="1 0 0"/>
       <limit effort="0.0" lower="-3.14159" upper="3.14159" velocity="0.0"/>
    </joint>
    <link name="Link1">
        <inertial>
            <origin xyz="0.24622838620883442 0 0" rpy="0 0 0"/>
            <mass value="0.16684982083417946" />
            <inertia ixx="100" ixy="0" ixz="0" iyy="100" iyz="0" izz="100" />
        </inertial>
        <visual>
            <origin xyz="0.24622838620883442 0 0" rpy="0 0 0"/>
            <geometry>
                <box size="0.49245677241766883 0.5145883170240357 0.6584119555984481" />
            </geometry>
            <material name="No Sensor">
                <color rgba="0.184 0.553 0.933 1.0"/>
            </material>
        </visual>
        <collision>
            <origin xyz="0.24622838620883442 0 0" rpy="0 0 0"/>
            <geometry>
                <box size="0.49245677241766883 0.5145883170240357 0.6584119555984481" />
            </geometry>
        </collision>
    </link>
    <joint name="Link1_Link2" type="revolute">
       <parent link="Link1"/>
       <child  link="Link2"/>
       <origin rpy="0 0 0" xyz="0.24622838620883442 0.25729415851201787 0.0" />
       <axis xyz="1 0 0"/>
       <limit effort="0.0" lower="-3.14159" upper="3.14159" velocity="0.0"/>
    </joint>
    <link name="Link2">
        <inertial>
            <origin xyz="0.0 0.598709777096351 0.0" rpy="0 0 0"/>
            <mass value="1.1398277739824194" />
            <inertia ixx="100" ixy="0" ixz="0" iyy="100" iyz="0" izz="100" />
        </inertial>
        <visual>
            <origin xyz="0.0 0.598709777096351 0.0" rpy="0 0 0"/>
            <geometry>
                <box size="1.0786954482179012 1.197419554192702 0.8824579967325411" />
            </geometry>
            <material name="No Sensor">
                <color rgba="0.184 0.553 0.933 1.0"/>
            </material>
        </visual>
        <collision>
            <origin xyz="0.0 0.598709777096351 0.0" rpy="0 0 0"/>
            <geometry>
                <box size="1.0786954482179012 1.197419554192702 0.8824579967325411" />
            </geometry>
        </collision>
    </link>
    <joint name="Link2_Link3" type="revolute">
       <parent link="Link2"/>
       <child  link="Link3"/>
       <origin rpy="0 0 0" xyz="0.5393477241089506 0.598709777096351 0.0" />
       <axis xyz="1 0 0"/>
       <limit effort="0.0" lower="-3.14159" upper="3.14159" velocity="0.0"/>
    </joint>
    <link name="Link3">
        <inertial>
            <origin xyz="0.19236956824011125 0.0 0.0" rpy="0 0 0"/>
            <mass value="0.30576621328559805" />
            <inertia ixx="100" ixy="0" ixz="0" iyy="100" iyz="0" izz="100" />
        </inertial>
        <visual>
            <origin xyz="0.19236956824011125 0.0 0.0" rpy="0 0 0"/>
            <geometry>
                <box size="0.3847391364802225 0.6699934526833755 1.1861853889098444" />
            </geometry>
            <material name="Sensor">
                <color rgba="0.239 0.875 0.282 1.0"/>
            </material>
        </visual>
        <collision>
            <origin xyz="0.19236956824011125 0.0 0.0" rpy="0 0 0"/>
            <geometry>
                <box size="0.3847391364802225 0.6699934526833755 1.1861853889098444" />
            </geometry>
        </collision>
    </link>
    <joint name="Link3_Link4" type="revolute">
       <parent link="Link3"/>
       <child  link="Link4"/>
       <origin rpy="0 0 0" xyz="0.19236956824011125 0.0 -0.5930926944549222" />
       <axis xyz="0 1 0"/>
       <limit effort="0.0" lower="-3.14159" upper="3.14159" velocity="0.0"/>
    </joint>
    <link name="Link4">
        <inertial>
            <origin xyz="0.0 0.0 -0.5925668236380905" rpy="0 0 0"/>
            <mass value="0.5877827830788648" />
            <inertia ixx="100" ixy="0" ixz="0" iyy="100" iyz="0" izz="100" />
        </inertial>
        <visual>
            <origin xyz="0.0 0.0 -0.5925668236380905" rpy="0 0 0"/>
            <geometry>
                <box size="0.5705442753283897 0.8692809860477866 1.185133647276181" />
            </geometry>
            <material name="Sensor">
                <color rgba="0.239 0.875 0.282 1.0"/>
            </material>
        </visual>
        <collision>
            <origin xyz="0.0 0.0 -0.5925668236380905" rpy="0 0 0"/>
            <geometry>
                <box size="0.5705442753283897 0.8692809860477866 1.185133647276181" />
            </geometry>
        </collision>
    </link>
    <joint name="Link4_Link5" type="revolute">
       <parent link="Link4"/>
       <child  link="Link5"/>
       <origin rpy="0 0 0" xyz="0.0 -0.4346404930238933 -0.5925668236380905" />
       <axis xyz="1 0 0"/>
       <limit effort="0.0" lower="-3.14159" upper="3.14159" velocity="0.0"/>
    </joint>
    <link name="Link5">
        <inertial>
            <origin xyz="0.0 -0.37519952705842213 0.0" rpy="0 0 0"/>
            <mass value="0.6232589241955272" />
            <inertia ixx="100" ixy="0" ixz="0" iyy="100" iyz="0" izz="100" />
        </inertial>
        <visual>
            <origin xyz="0.0 -0.37519952705842213 0.0" rpy="0 0 0"/>
            <geometry>
                <box size="0.7106823360458484 0.7503990541168443 1.1686937097536678" />
            </geometry>
            <material name="Sensor">
                <color rgba="0.239 0.875 0.282 1.0"/>
            </material>
        </visual>
        <collision>
            <origin xyz="0.0 -0.37519952705842213 0.0" rpy="0 0 0"/>
            <geometry>
                <box size="0.7106823360458484 0.7503990541168443 1.1686937097536678" />
            </geometry>
        </collision>
    </link>
    <joint name="Link5_Link6" type="revolute">
       <parent link="Link5"/>
       <child  link="Link6"/>
       <origin rpy="0 0 0" xyz="0.0 -0.37519952705842213 -0.5843468548768339" />
       <axis xyz="1 0 0"/>
       <limit effort="0.0" lower="-3.14159" upper="3.14159" velocity="0.0"/>
    </joint>
    <link name="Link6">
        <inertial>
            <origin xyz="0.0 0.0 -0.381817265338922" rpy="0 0 0"/>
            <mass value="1.0401395883829938" />
            <inertia ixx="100" ixy="0" ixz="0" iyy="100" iyz="0" izz="100" />
        </inertial>
        <visual>
            <origin xyz="0.0 0.0 -0.381817265338922" rpy="0 0 0"/>
            <geometry>
                <box size="1.1798235710096754 1.154486873389572 0.763634530677844" />
            </geometry>
            <material name="Sensor">
                <color rgba="0.239 0.875 0.282 1.0"/>
            </material>
        </visual>
        <collision>
            <origin xyz="0.0 0.0 -0.381817265338922" rpy="0 0 0"/>
            <geometry>
                <box size="1.1798235710096754 1.154486873389572 0.763634530677844" />
            </geometry>
        </collision>
    </link>
    <joint name="Link6_Link7" type="revolute">
       <parent link="Link6"/>
       <child  link="Link7"/>
       <origin rpy="0 0 0" xyz="0.5899117855048377 0.0 -0.381817265338922" />
       <axis xyz="1 0 0"/>
       <limit effort="0.0" lower="-3.14159" upper="3.14159" velocity="0.0"/>
    </joint>
    <link name="Link7">
        <inertial>
            <origin xyz="0.4449056252976018 0.0 0.0" rpy="0 0 0"/>
            <mass value="0.30496472227048166" />
            <inertia ixx="100" ixy="0" ixz="0" iyy="100" iyz="0" izz="100" />
        </inertial>
        <visual>
            <origin xyz="0.4449056252976018 0.0 0.0" rpy="0 0 0"/>
            <geometry>
                <box size="0.8898112505952036 0.8390061758781516 0.40849481992782133" />
            </geometry>
            <material name="Sensor">
                <color rgba="0.239 0.875 0.282 1.0"/>
            </material>
        </visual>
        <collision>
            <origin xyz="0.4449056252976018 0.0 0.0" rpy="0 0 0"/>
            <geometry>
                <box size="0.8898112505952036 0.8390061758781516 0.40849481992782133" />
            </geometry>
        </collision>
    </link>
    <joint name="Link7_Link8" type="revolute">
       <parent link="Link7"/>
       <child  link="Link8"/>
       <origin rpy="0 0 0" xyz="0.8898112505952036 0.0 0.0" />
       <axis xyz="0 1 0"/>
       <limit effort="0.0" lower="-3.14159" upper="3.14159" velocity="0.0"/>
    </joint>
    <link name="Link8">
        <inertial>
            <origin xyz="0.43672450219073455 0.0 0.0" rpy="0 0 0"/>
            <mass value="0.18927067700970485" />
            <inertia ixx="100" ixy="0" ixz="0" iyy="100" iyz="0" izz="100" />
        </inertial>
        <visual>
            <origin xyz="0.43672450219073455 0.0 0.0" rpy="0 0 0"/>
            <geometry>
                <box size="0.8734490043814691 0.5691443228782305 0.3807355006001497" />
            </geometry>
            <material name="No Sensor">
                <color rgba="0.184 0.553 0.933 1.0"/>
            </material>
        </visual>
        <collision>
            <origin xyz="0.43672450219073455 0.0 0.0" rpy="0 0 0"/>
            <geometry>
                <box size="0.8734490043814691 0.5691443228782305 0.3807355006001497" />
            </geometry>
        </collision>
    </link>
    <joint name="Link8_Link9" type="revolute">
       <parent link="Link8"/>
       <child  link="Link9"/>
       <origin rpy="0 0 0" xyz="0.8734490043814691 0.0 0.0" />
       <axis xyz="0 0 1"/>
       <limit effort="0.0" lower="-3.14159" upper="3.14159" velocity="0.0"/>
    </joint>
    <link name="Link9">
        <inertial>
            <origin xyz="0.2325015022845221 0.0 0.0" rpy="0 0 0"/>
            <mass value="0.3149050004967134" />
            <inertia ixx="100" ixy="0" ixz="0" iyy="100" iyz="0" izz="100" />
        </inertial>
        <visual>
            <origin xyz="0.2325015022845221 0.0 0.0" rpy="0 0 0"/>
            <geometry>
                <box size="0.4650030045690442 0.5636602971825204 1.201451800776721" />
            </geometry>
            <material name="No Sensor">
                <color rgba="0.184 0.553 0.933 1.0"/>
            </material>
        </visual>
        <collision>
            <origin xyz="0.2325015022845221 0.0 0.0" rpy="0 0 0"/>
            <geometry>
                <box size="0.4650030045690442 0.5636602971825204 1.201451800776721" />
            </geometry>
        </collision>
    </link>
</robot>