<robot name = "robot">
    <link name="Link0">
        <inertial>
            <origin xyz="0 0 2" rpy="0 0 0"/>
            <mass value="0.5128304078562345" />
            <inertia ixx="100" ixy="0" ixz="0" iyy="100" iyz="0" izz="100" />
        </inertial>
        <visual>
            <origin xyz="0 0 2" rpy="0 0 0"/>
            <geometry>
                <box size="0.9570551786748137 0.5830084769159914 0.91909821232701" />
            </geometry>
            <material name="No Sensor">
                <color rgba="0.184 0.553 0.933 1.0"/>
            </material>
        </visual>
        <collision>
            <origin xyz="0 0 2" rpy="0 0 0"/>
            <geometry>
                <box size="0.9570551786748137 0.5830084769159914 0.91909821232701" />
            </geometry>
        </collision>
    </link>
    <joint name="Link0_Link1" type="revolute">
       <parent link="Link0"/>
       <child  link="Link1"/>
       <origin rpy="0 0 0" xyz="0.47852758933740686 0 2" />
       <axis xyz="1 0 0"/>
       <limit effort="0.0" lower="-3.14159" upper="3.14159" velocity="0.0"/>
    </joint>
    <link name="Link1">
        <inertial>
            <origin xyz="0.5147755440734005 0 0" rpy="0 0 0"/>
            <mass value="0.2635844339542847" />
            <inertia ixx="100" ixy="0" ixz="0" iyy="100" iyz="0" izz="100" />
        </inertial>
        <visual>
            <origin xyz="0.5147755440734005 0 0" rpy="0 0 0"/>
            <geometry>
                <box size="1.029551088146801 0.33657611869611215 0.7606564625707463" />
            </geometry>
            <material name="No Sensor">
                <color rgba="0.184 0.553 0.933 1.0"/>
            </material>
        </visual>
        <collision>
            <origin xyz="0.5147755440734005 0 0" rpy="0 0 0"/>
            <geometry>
                <box size="1.029551088146801 0.33657611869611215 0.7606564625707463" />
            </geometry>
        </collision>
    </link>
    <joint name="Link1_Link2" type="revolute">
       <parent link="Link1"/>
       <child  link="Link2"/>
       <origin rpy="0 0 0" xyz="1.029551088146801 0.0 0.0" />
       <axis xyz="0 0 1"/>
       <limit effort="0.0" lower="-3.14159" upper="3.14159" velocity="0.0"/>
    </joint>
    <link name="Link2">
        <inertial>
            <origin xyz="0.17683718103195284 0.0 0.0" rpy="0 0 0"/>
            <mass value="0.1798941925775253" />
            <inertia ixx="100" ixy="0" ixz="0" iyy="100" iyz="0" izz="100" />
        </inertial>
        <visual>
            <origin xyz="0.17683718103195284 0.0 0.0" rpy="0 0 0"/>
            <geometry>
                <box size="0.3536743620639057 0.8994615057501819 0.5654978825073803" />
            </geometry>
            <material name="Sensor">
                <color rgba="0.239 0.875 0.282 1.0"/>
            </material>
        </visual>
        <collision>
            <origin xyz="0.17683718103195284 0.0 0.0" rpy="0 0 0"/>
            <geometry>
                <box size="0.3536743620639057 0.8994615057501819 0.5654978825073803" />
            </geometry>
        </collision>
    </link>
    <joint name="Link2_Link3" type="revolute">
       <parent link="Link2"/>
       <child  link="Link3"/>
       <origin rpy="0 0 0" xyz="0.17683718103195284 0.0 0.28274894125369016" />
       <axis xyz="0 1 0"/>
       <limit effort="0.0" lower="-3.14159" upper="3.14159" velocity="0.0"/>
    </joint>
    <link name="Link3">
        <inertial>
            <origin xyz="0.0 0.0 0.5584981985100145" rpy="0 0 0"/>
            <mass value="0.2979679032425855" />
            <inertia ixx="100" ixy="0" ixz="0" iyy="100" iyz="0" izz="100" />
        </inertial>
        <visual>
            <origin xyz="0.0 0.0 0.5584981985100145" rpy="0 0 0"/>
            <geometry>
                <box size="0.893501190424533 0.2985537820684181 1.116996397020029" />
            </geometry>
            <material name="Sensor">
                <color rgba="0.239 0.875 0.282 1.0"/>
            </material>
        </visual>
        <collision>
            <origin xyz="0.0 0.0 0.5584981985100145" rpy="0 0 0"/>
            <geometry>
                <box size="0.893501190424533 0.2985537820684181 1.116996397020029" />
            </geometry>
        </collision>
    </link>
    <joint name="Link3_Link4" type="revolute">
       <parent link="Link3"/>
       <child  link="Link4"/>
       <origin rpy="0 0 0" xyz="0.0 0.14927689103420905 0.5584981985100145" />
       <axis xyz="1 0 0"/>
       <limit effort="0.0" lower="-3.14159" upper="3.14159" velocity="0.0"/>
    </joint>
    <link name="Link4">
        <inertial>
            <origin xyz="0.0 0.5217765943137762 0.0" rpy="0 0 0"/>
            <mass value="0.3621835287562734" />
            <inertia ixx="100" ixy="0" ixz="0" iyy="100" iyz="0" izz="100" />
        </inertial>
        <visual>
            <origin xyz="0.0 0.5217765943137762 0.0" rpy="0 0 0"/>
            <geometry>
                <box size="0.7281592550120661 1.0435531886275524 0.47663697816785" />
            </geometry>
            <material name="Sensor">
                <color rgba="0.239 0.875 0.282 1.0"/>
            </material>
        </visual>
        <collision>
            <origin xyz="0.0 0.5217765943137762 0.0" rpy="0 0 0"/>
            <geometry>
                <box size="0.7281592550120661 1.0435531886275524 0.47663697816785" />
            </geometry>
        </collision>
    </link>
    <joint name="Link4_Link5" type="revolute">
       <parent link="Link4"/>
       <child  link="Link5"/>
       <origin rpy="0 0 0" xyz="-0.36407962750603307 0.5217765943137762 0.0" />
       <axis xyz="1 0 0"/>
       <limit effort="0.0" lower="-3.14159" upper="3.14159" velocity="0.0"/>
    </joint>
    <link name="Link5">
        <inertial>
            <origin xyz="-0.2924868711264664 0.0 0.0" rpy="0 0 0"/>
            <mass value="0.6543647797559742" />
            <inertia ixx="100" ixy="0" ixz="0" iyy="100" iyz="0" izz="100" />
        </inertial>
        <visual>
            <origin xyz="-0.2924868711264664 0.0 0.0" rpy="0 0 0"/>
            <geometry>
                <box size="0.5849737422529327 1.0137749232114304 1.1034229165541922" />
            </geometry>
            <material name="Sensor">
                <color rgba="0.239 0.875 0.282 1.0"/>
            </material>
        </visual>
        <collision>
            <origin xyz="-0.2924868711264664 0.0 0.0" rpy="0 0 0"/>
            <geometry>
                <box size="0.5849737422529327 1.0137749232114304 1.1034229165541922" />
            </geometry>
        </collision>
    </link>
    <joint name="Link5_Link6" type="revolute">
       <parent link="Link5"/>
       <child  link="Link6"/>
       <origin rpy="0 0 0" xyz="-0.2924868711264664 0.0 0.5517114582770961" />
       <axis xyz="0 0 1"/>
       <limit effort="0.0" lower="-3.14159" upper="3.14159" velocity="0.0"/>
    </joint>
    <link name="Link6">
        <inertial>
            <origin xyz="0.0 0.0 0.4148071494201793" rpy="0 0 0"/>
            <mass value="0.6728458283370262" />
            <inertia ixx="100" ixy="0" ixz="0" iyy="100" iyz="0" izz="100" />
        </inertial>
        <visual>
            <origin xyz="0.0 0.0 0.4148071494201793" rpy="0 0 0"/>
            <geometry>
                <box size="0.6871238648457362 1.1803323300063635 0.8296142988403586" />
            </geometry>
            <material name="Sensor">
                <color rgba="0.239 0.875 0.282 1.0"/>
            </material>
        </visual>
        <collision>
            <origin xyz="0.0 0.0 0.4148071494201793" rpy="0 0 0"/>
            <geometry>
                <box size="0.6871238648457362 1.1803323300063635 0.8296142988403586" />
            </geometry>
        </collision>
    </link>
    <joint name="Link6_Link7" type="revolute">
       <parent link="Link6"/>
       <child  link="Link7"/>
       <origin rpy="0 0 0" xyz="0.0 0.5901661650031818 0.4148071494201793" />
       <axis xyz="0 0 1"/>
       <limit effort="0.0" lower="-3.14159" upper="3.14159" velocity="0.0"/>
    </joint>
    <link name="Link7">
        <inertial>
            <origin xyz="0.0 0.3514306689775033 0.0" rpy="0 0 0"/>
            <mass value="0.0862759623123585" />
            <inertia ixx="100" ixy="0" ixz="0" iyy="100" iyz="0" izz="100" />
        </inertial>
        <visual>
            <origin xyz="0.0 0.3514306689775033 0.0" rpy="0 0 0"/>
            <geometry>
                <box size="0.2990974814309052 0.7028613379550066 0.410400046327681" />
            </geometry>
            <material name="No Sensor">
                <color rgba="0.184 0.553 0.933 1.0"/>
            </material>
        </visual>
        <collision>
            <origin xyz="0.0 0.3514306689775033 0.0" rpy="0 0 0"/>
            <geometry>
                <box size="0.2990974814309052 0.7028613379550066 0.410400046327681" />
            </geometry>
        </collision>
    </link>
    <joint name="Link7_Link8" type="revolute">
       <parent link="Link7"/>
       <child  link="Link8"/>
       <origin rpy="0 0 0" xyz="0.1495487407154526 0.3514306689775033 0.0" />
       <axis xyz="0 1 0"/>
       <limit effort="0.0" lower="-3.14159" upper="3.14159" velocity="0.0"/>
    </joint>
    <link name="Link8">
        <inertial>
            <origin xyz="0.4914122234607243 0.0 0.0" rpy="0 0 0"/>
            <mass value="0.26488314626313003" />
            <inertia ixx="100" ixy="0" ixz="0" iyy="100" iyz="0" izz="100" />
        </inertial>
        <visual>
            <origin xyz="0.4914122234607243 0.0 0.0" rpy="0 0 0"/>
            <geometry>
                <box size="0.9828244469214485 0.5973526679306684 0.45117763970615266" />
            </geometry>
            <material name="No Sensor">
                <color rgba="0.184 0.553 0.933 1.0"/>
            </material>
        </visual>
        <collision>
            <origin xyz="0.4914122234607243 0.0 0.0" rpy="0 0 0"/>
            <geometry>
                <box size="0.9828244469214485 0.5973526679306684 0.45117763970615266" />
            </geometry>
        </collision>
    </link>
    <joint name="Link8_Link9" type="revolute">
       <parent link="Link8"/>
       <child  link="Link9"/>
       <origin rpy="0 0 0" xyz="0.4914122234607243 0.0 -0.22558881985307633" />
       <axis xyz="0 0 1"/>
       <limit effort="0.0" lower="-3.14159" upper="3.14159" velocity="0.0"/>
    </joint>
    <link name="Link9">
        <inertial>
            <origin xyz="0.0 0.0 -0.2968233454277896" rpy="0 0 0"/>
            <mass value="0.6927115145744699" />
            <inertia ixx="100" ixy="0" ixz="0" iyy="100" iyz="0" izz="100" />
        </inertial>
        <visual>
            <origin xyz="0.0 0.0 -0.2968233454277896" rpy="0 0 0"/>
            <geometry>
                <box size="1.092788034064323 1.0677963318022827 0.5936466908555792" />
            </geometry>
            <material name="No Sensor">
                <color rgba="0.184 0.553 0.933 1.0"/>
            </material>
        </visual>
        <collision>
            <origin xyz="0.0 0.0 -0.2968233454277896" rpy="0 0 0"/>
            <geometry>
                <box size="1.092788034064323 1.0677963318022827 0.5936466908555792" />
            </geometry>
        </collision>
    </link>
</robot>