<robot name = "robot">
    <link name="0">
        <inertial>
            <origin xyz="0 0 2" rpy="0 0 0"/>
            <mass value="0.42795200418098583" />
            <inertia ixx="100" ixy="0" ixz="0" iyy="100" iyz="0" izz="100" />
        </inertial>
        <visual>
            <origin xyz="0 0 2" rpy="0 0 0"/>
            <geometry>
                <box size="0.6836061308733558 0.8205073348040821 0.7629685700648337" />
            </geometry>
            <material name="King Crab">
                <color rgba="0.8 0.496 0.516 1.0"/>
            </material>
        </visual>
        <collision>
            <origin xyz="0 0 2" rpy="0 0 0"/>
            <geometry>
                <box size="0.6836061308733558 0.8205073348040821 0.7629685700648337" />
            </geometry>
        </collision>
    </link>
    <joint name="0_1" type="revolute">
       <parent link="0"/>
       <child  link="1"/>
       <origin rpy="0 0 0" xyz="0.3418030654366779 0.41025366740204106 2" />
       <axis xyz="1 0 0"/>
       <limit effort="0.0" lower="-3.14159" upper="3.14159" velocity="0.0"/>
    </joint>
    <link name="1">
        <inertial>
            <origin xyz="0.2828719642278743 0.3112542958315417 0.43805783004026333" rpy="0 0 0"/>
            <mass value="0.3085508128028748" />
            <inertia ixx="100" ixy="0" ixz="0" iyy="100" iyz="0" izz="100" />
        </inertial>
        <visual>
            <origin xyz="0.2828719642278743 0.3112542958315417 0.43805783004026333" rpy="0 0 0"/>
            <geometry>
                <box size="0.5657439284557486 0.6225085916630834 0.8761156600805267" />
            </geometry>
            <material name="King Crab">
                <color rgba="0.8 0.496 0.516 1.0"/>
            </material>
        </visual>
        <collision>
            <origin xyz="0.2828719642278743 0.3112542958315417 0.43805783004026333" rpy="0 0 0"/>
            <geometry>
                <box size="0.5657439284557486 0.6225085916630834 0.8761156600805267" />
            </geometry>
        </collision>
    </link>
    <joint name="1_2" type="revolute">
       <parent link="1"/>
       <child  link="2"/>
       <origin rpy="0 0 0" xyz="0.5657439284557486 0.3112542958315417 0.43805783004026333" />
       <axis xyz="1 0 0"/>
       <limit effort="0.0" lower="-3.14159" upper="3.14159" velocity="0.0"/>
    </joint>
    <link name="2">
        <inertial>
            <origin xyz="0.29189733556368225 0.28685758019741314 0.37198134202571775" rpy="0 0 0"/>
            <mass value="0.24917680061749625" />
            <inertia ixx="100" ixy="0" ixz="0" iyy="100" iyz="0" izz="100" />
        </inertial>
        <visual>
            <origin xyz="0.29189733556368225 0.28685758019741314 0.37198134202571775" rpy="0 0 0"/>
            <geometry>
                <box size="0.5837946711273645 0.5737151603948263 0.7439626840514355" />
            </geometry>
            <material name="King Crab">
                <color rgba="0.8 0.496 0.516 1.0"/>
            </material>
        </visual>
        <collision>
            <origin xyz="0.29189733556368225 0.28685758019741314 0.37198134202571775" rpy="0 0 0"/>
            <geometry>
                <box size="0.5837946711273645 0.5737151603948263 0.7439626840514355" />
            </geometry>
        </collision>
    </link>
    <joint name="2_3" type="revolute">
       <parent link="2"/>
       <child  link="3"/>
       <origin rpy="0 0 0" xyz="0.5837946711273645 0.28685758019741314 0.37198134202571775" />
       <axis xyz="1 0 0"/>
       <limit effort="0.0" lower="-3.14159" upper="3.14159" velocity="0.0"/>
    </joint>
    <link name="3">
        <inertial>
            <origin xyz="0.4847063337799997 0.4073827757170446 0.3782714453816406" rpy="0 0 0"/>
            <mass value="0.5975508983060559" />
            <inertia ixx="100" ixy="0" ixz="0" iyy="100" iyz="0" izz="100" />
        </inertial>
        <visual>
            <origin xyz="0.4847063337799997 0.4073827757170446 0.3782714453816406" rpy="0 0 0"/>
            <geometry>
                <box size="0.9694126675599994 0.8147655514340892 0.7565428907632812" />
            </geometry>
            <material name="King Crab">
                <color rgba="0.8 0.496 0.516 1.0"/>
            </material>
        </visual>
        <collision>
            <origin xyz="0.4847063337799997 0.4073827757170446 0.3782714453816406" rpy="0 0 0"/>
            <geometry>
                <box size="0.9694126675599994 0.8147655514340892 0.7565428907632812" />
            </geometry>
        </collision>
    </link>
    <joint name="3_4" type="revolute">
       <parent link="3"/>
       <child  link="4"/>
       <origin rpy="0 0 0" xyz="0.9694126675599994 0.4073827757170446 0.3782714453816406" />
       <axis xyz="1 0 0"/>
       <limit effort="0.0" lower="-3.14159" upper="3.14159" velocity="0.0"/>
    </joint>
    <link name="4">
        <inertial>
            <origin xyz="0.4847063337799997 0.4073827757170446 0.3782714453816406" rpy="0 0 0"/>
            <mass value="0.5975508983060559" />
            <inertia ixx="100" ixy="0" ixz="0" iyy="100" iyz="0" izz="100" />
        </inertial>
        <visual>
            <origin xyz="0.4847063337799997 0.4073827757170446 0.3782714453816406" rpy="0 0 0"/>
            <geometry>
                <box size="0.9694126675599994 0.8147655514340892 0.7565428907632812" />
            </geometry>
            <material name="King Crab">
                <color rgba="0.8 0.496 0.516 1.0"/>
            </material>
        </visual>
        <collision>
            <origin xyz="0.4847063337799997 0.4073827757170446 0.3782714453816406" rpy="0 0 0"/>
            <geometry>
                <box size="0.9694126675599994 0.8147655514340892 0.7565428907632812" />
            </geometry>
        </collision>
    </link>
</robot>