<robot name = "robot">
    <link name="Link0">
        <inertial>
            <origin xyz="0 0 2" rpy="0 0 0"/>
            <mass value="0.3978776231703106" />
            <inertia ixx="100" ixy="0" ixz="0" iyy="100" iyz="0" izz="100" />
        </inertial>
        <visual>
            <origin xyz="0 0 2" rpy="0 0 0"/>
            <geometry>
                <box size="0.36819262934703845 1.0869977822135122 0.9941359213695352" />
            </geometry>
            <material name="No Sensor">
                <color rgba="0.184 0.553 0.933 1.0"/>
            </material>
        </visual>
        <collision>
            <origin xyz="0 0 2" rpy="0 0 0"/>
            <geometry>
                <box size="0.36819262934703845 1.0869977822135122 0.9941359213695352" />
            </geometry>
        </collision>
    </link>
    <joint name="Link0_Link1" type="revolute">
       <parent link="Link0"/>
       <child  link="Link1"/>
       <origin rpy="0 0 0" xyz="0.18409631467351922 0 2" />
       <axis xyz="1 0 0"/>
       <limit effort="0.0" lower="-3.14159" upper="3.14159" velocity="0.0"/>
    </joint>
    <link name="Link1">
        <inertial>
            <origin xyz="0.42026027382355857 0 0" rpy="0 0 0"/>
            <mass value="0.3617736271288184" />
            <inertia ixx="100" ixy="0" ixz="0" iyy="100" iyz="0" izz="100" />
        </inertial>
        <visual>
            <origin xyz="0.42026027382355857 0 0" rpy="0 0 0"/>
            <geometry>
                <box size="0.8405205476471171 0.4928915749648707 0.8732471451875841" />
            </geometry>
            <material name="Sensor">
                <color rgba="0.239 0.875 0.282 1.0"/>
            </material>
        </visual>
        <collision>
            <origin xyz="0.42026027382355857 0 0" rpy="0 0 0"/>
            <geometry>
                <box size="0.8405205476471171 0.4928915749648707 0.8732471451875841" />
            </geometry>
        </collision>
    </link>
    <joint name="Link1_Link2" type="revolute">
       <parent link="Link1"/>
       <child  link="Link2"/>
       <origin rpy="0 0 0" xyz="0.42026027382355857 0.0 -0.43662357259379203" />
       <axis xyz="0 1 0"/>
       <limit effort="0.0" lower="-3.14159" upper="3.14159" velocity="0.0"/>
    </joint>
    <link name="Link2">
        <inertial>
            <origin xyz="0.0 0.0 -0.15874467153377114" rpy="0 0 0"/>
            <mass value="0.1628996192536504" />
            <inertia ixx="100" ixy="0" ixz="0" iyy="100" iyz="0" izz="100" />
        </inertial>
        <visual>
            <origin xyz="0.0 0.0 -0.15874467153377114" rpy="0 0 0"/>
            <geometry>
                <box size="0.888355320741173 0.5775694441123251 0.3174893430675423" />
            </geometry>
            <material name="Sensor">
                <color rgba="0.239 0.875 0.282 1.0"/>
            </material>
        </visual>
        <collision>
            <origin xyz="0.0 0.0 -0.15874467153377114" rpy="0 0 0"/>
            <geometry>
                <box size="0.888355320741173 0.5775694441123251 0.3174893430675423" />
            </geometry>
        </collision>
    </link>
    <joint name="Link2_Link3" type="revolute">
       <parent link="Link2"/>
       <child  link="Link3"/>
       <origin rpy="0 0 0" xyz="0.0 -0.28878472205616257 -0.15874467153377114" />
       <axis xyz="0 0 1"/>
       <limit effort="0.0" lower="-3.14159" upper="3.14159" velocity="0.0"/>
    </joint>
    <link name="Link3">
        <inertial>
            <origin xyz="0.0 -0.3549783655371292 0.0" rpy="0 0 0"/>
            <mass value="0.813768195156983" />
            <inertia ixx="100" ixy="0" ixz="0" iyy="100" iyz="0" izz="100" />
        </inertial>
        <visual>
            <origin xyz="0.0 -0.3549783655371292 0.0" rpy="0 0 0"/>
            <geometry>
                <box size="1.1305385975643267 0.7099567310742584 1.01387271806643" />
            </geometry>
            <material name="Sensor">
                <color rgba="0.239 0.875 0.282 1.0"/>
            </material>
        </visual>
        <collision>
            <origin xyz="0.0 -0.3549783655371292 0.0" rpy="0 0 0"/>
            <geometry>
                <box size="1.1305385975643267 0.7099567310742584 1.01387271806643" />
            </geometry>
        </collision>
    </link>
    <joint name="Link3_Link4" type="revolute">
       <parent link="Link3"/>
       <child  link="Link4"/>
       <origin rpy="0 0 0" xyz="0.5652692987821634 -0.3549783655371292 0.0" />
       <axis xyz="0 0 1"/>
       <limit effort="0.0" lower="-3.14159" upper="3.14159" velocity="0.0"/>
    </joint>
    <link name="Link4">
        <inertial>
            <origin xyz="0.25194431047136984 0.0 0.0" rpy="0 0 0"/>
            <mass value="0.2877856799700098" />
            <inertia ixx="100" ixy="0" ixz="0" iyy="100" iyz="0" izz="100" />
        </inertial>
        <visual>
            <origin xyz="0.25194431047136984 0.0 0.0" rpy="0 0 0"/>
            <geometry>
                <box size="0.5038886209427397 0.8413871822675169 0.6787951603487977" />
            </geometry>
            <material name="Sensor">
                <color rgba="0.239 0.875 0.282 1.0"/>
            </material>
        </visual>
        <collision>
            <origin xyz="0.25194431047136984 0.0 0.0" rpy="0 0 0"/>
            <geometry>
                <box size="0.5038886209427397 0.8413871822675169 0.6787951603487977" />
            </geometry>
        </collision>
    </link>
    <joint name="Link4_Link5" type="revolute">
       <parent link="Link4"/>
       <child  link="Link5"/>
       <origin rpy="0 0 0" xyz="0.25194431047136984 0.0 -0.33939758017439886" />
       <axis xyz="0 0 1"/>
       <limit effort="0.0" lower="-3.14159" upper="3.14159" velocity="0.0"/>
    </joint>
    <link name="Link5">
        <inertial>
            <origin xyz="0.0 0.0 -0.24713333160448792" rpy="0 0 0"/>
            <mass value="0.11769515941051298" />
            <inertia ixx="100" ixy="0" ixz="0" iyy="100" iyz="0" izz="100" />
        </inertial>
        <visual>
            <origin xyz="0.0 0.0 -0.24713333160448792" rpy="0 0 0"/>
            <geometry>
                <box size="0.6321006425491396 0.37671338384692277 0.49426666320897583" />
            </geometry>
            <material name="Sensor">
                <color rgba="0.239 0.875 0.282 1.0"/>
            </material>
        </visual>
        <collision>
            <origin xyz="0.0 0.0 -0.24713333160448792" rpy="0 0 0"/>
            <geometry>
                <box size="0.6321006425491396 0.37671338384692277 0.49426666320897583" />
            </geometry>
        </collision>
    </link>
    <joint name="Link5_Link6" type="revolute">
       <parent link="Link5"/>
       <child  link="Link6"/>
       <origin rpy="0 0 0" xyz="0.0 0.18835669192346138 -0.24713333160448792" />
       <axis xyz="1 0 0"/>
       <limit effort="0.0" lower="-3.14159" upper="3.14159" velocity="0.0"/>
    </joint>
    <link name="Link6">
        <inertial>
            <origin xyz="0.0 0.2764291523587893 0.0" rpy="0 0 0"/>
            <mass value="0.1805688456472148" />
            <inertia ixx="100" ixy="0" ixz="0" iyy="100" iyz="0" izz="100" />
        </inertial>
        <visual>
            <origin xyz="0.0 0.2764291523587893 0.0" rpy="0 0 0"/>
            <geometry>
                <box size="0.32934158295831895 0.5528583047175786 0.9917048002315554" />
            </geometry>
            <material name="No Sensor">
                <color rgba="0.184 0.553 0.933 1.0"/>
            </material>
        </visual>
        <collision>
            <origin xyz="0.0 0.2764291523587893 0.0" rpy="0 0 0"/>
            <geometry>
                <box size="0.32934158295831895 0.5528583047175786 0.9917048002315554" />
            </geometry>
        </collision>
    </link>
    <joint name="Link6_Link7" type="revolute">
       <parent link="Link6"/>
       <child  link="Link7"/>
       <origin rpy="0 0 0" xyz="0.0 0.2764291523587893 -0.4958524001157777" />
       <axis xyz="0 0 1"/>
       <limit effort="0.0" lower="-3.14159" upper="3.14159" velocity="0.0"/>
    </joint>
    <link name="Link7">
        <inertial>
            <origin xyz="0.0 0.0 -0.1291915397625158" rpy="0 0 0"/>
            <mass value="0.20616388640356775" />
            <inertia ixx="100" ixy="0" ixz="0" iyy="100" iyz="0" izz="100" />
        </inertial>
        <visual>
            <origin xyz="0.0 0.0 -0.1291915397625158" rpy="0 0 0"/>
            <geometry>
                <box size="0.8650157249710488 0.9224110989339258 0.2583830795250316" />
            </geometry>
            <material name="No Sensor">
                <color rgba="0.184 0.553 0.933 1.0"/>
            </material>
        </visual>
        <collision>
            <origin xyz="0.0 0.0 -0.1291915397625158" rpy="0 0 0"/>
            <geometry>
                <box size="0.8650157249710488 0.9224110989339258 0.2583830795250316" />
            </geometry>
        </collision>
    </link>
    <joint name="Link7_Link8" type="revolute">
       <parent link="Link7"/>
       <child  link="Link8"/>
       <origin rpy="0 0 0" xyz="0.0 0.0 -0.2583830795250316" />
       <axis xyz="0 1 0"/>
       <limit effort="0.0" lower="-3.14159" upper="3.14159" velocity="0.0"/>
    </joint>
    <link name="Link8">
        <inertial>
            <origin xyz="0.0 0.0 -0.2404542252420896" rpy="0 0 0"/>
            <mass value="0.3362683132688863" />
            <inertia ixx="100" ixy="0" ixz="0" iyy="100" iyz="0" izz="100" />
        </inertial>
        <visual>
            <origin xyz="0.0 0.0 -0.2404542252420896" rpy="0 0 0"/>
            <geometry>
                <box size="0.9283769722513199 0.753180690542887 0.4809084504841792" />
            </geometry>
            <material name="No Sensor">
                <color rgba="0.184 0.553 0.933 1.0"/>
            </material>
        </visual>
        <collision>
            <origin xyz="0.0 0.0 -0.2404542252420896" rpy="0 0 0"/>
            <geometry>
                <box size="0.9283769722513199 0.753180690542887 0.4809084504841792" />
            </geometry>
        </collision>
    </link>
    <joint name="Link8_Link9" type="revolute">
       <parent link="Link8"/>
       <child  link="Link9"/>
       <origin rpy="0 0 0" xyz="0.0 -0.3765903452714435 -0.2404542252420896" />
       <axis xyz="0 1 0"/>
       <limit effort="0.0" lower="-3.14159" upper="3.14159" velocity="0.0"/>
    </joint>
    <link name="Link9">
        <inertial>
            <origin xyz="0.0 -0.2174914827754149 0.0" rpy="0 0 0"/>
            <mass value="0.20224413627220272" />
            <inertia ixx="100" ixy="0" ixz="0" iyy="100" iyz="0" izz="100" />
        </inertial>
        <visual>
            <origin xyz="0.0 -0.2174914827754149 0.0" rpy="0 0 0"/>
            <geometry>
                <box size="0.4248965089819222 0.4349829655508298 1.0942600050750984" />
            </geometry>
            <material name="No Sensor">
                <color rgba="0.184 0.553 0.933 1.0"/>
            </material>
        </visual>
        <collision>
            <origin xyz="0.0 -0.2174914827754149 0.0" rpy="0 0 0"/>
            <geometry>
                <box size="0.4248965089819222 0.4349829655508298 1.0942600050750984" />
            </geometry>
        </collision>
    </link>
</robot>