<robot name = "robot">
    <link name="0">
        <inertial>
            <origin xyz="0 0 2" rpy="0 0 0"/>
            <mass value="0.32618922376833337" />
            <inertia ixx="100" ixy="0" ixz="0" iyy="100" iyz="0" izz="100" />
        </inertial>
        <visual>
            <origin xyz="0 0 2" rpy="0 0 0"/>
            <geometry>
                <box size="0.6157136577287 0.9151435049080663 0.5788974284204937" />
            </geometry>
            <material name="No Sensor">
                <color rgba="0 0 1.0 1.0"/>
            </material>
        </visual>
        <collision>
            <origin xyz="0 0 2" rpy="0 0 0"/>
            <geometry>
                <box size="0.6157136577287 0.9151435049080663 0.5788974284204937" />
            </geometry>
        </collision>
    </link>
    <joint name="0_1" type="revolute">
       <parent link="0"/>
       <child  link="1"/>
       <origin rpy="0 0 0" xyz="0.30785682886435 0 2" />
       <axis xyz="0 1 0"/>
       <limit effort="0.0" lower="-3.14159" upper="3.14159" velocity="0.0"/>
    </joint>
    <link name="1">
        <inertial>
            <origin xyz="0.45183379015381936 0 0" rpy="0 0 0"/>
            <mass value="0.8449085341419045" />
            <inertia ixx="100" ixy="0" ixz="0" iyy="100" iyz="0" izz="100" />
        </inertial>
        <visual>
            <origin xyz="0.45183379015381936 0 0" rpy="0 0 0"/>
            <geometry>
                <box size="0.9036675803076387 0.942329453037141 0.9921977306877479" />
            </geometry>
            <material name="No Sensor">
                <color rgba="0 0 1.0 1.0"/>
            </material>
        </visual>
        <collision>
            <origin xyz="0.45183379015381936 0 0" rpy="0 0 0"/>
            <geometry>
                <box size="0.9036675803076387 0.942329453037141 0.9921977306877479" />
            </geometry>
        </collision>
    </link>
    <joint name="1_2" type="revolute">
       <parent link="1"/>
       <child  link="2"/>
       <origin rpy="0 0 0" xyz="0.9036675803076387 0 0" />
       <axis xyz="0 1 0"/>
       <limit effort="0.0" lower="-3.14159" upper="3.14159" velocity="0.0"/>
    </joint>
    <link name="2">
        <inertial>
            <origin xyz="0.28313786547119524 0 0" rpy="0 0 0"/>
            <mass value="0.2634160360637629" />
            <inertia ixx="100" ixy="0" ixz="0" iyy="100" iyz="0" izz="100" />
        </inertial>
        <visual>
            <origin xyz="0.28313786547119524 0 0" rpy="0 0 0"/>
            <geometry>
                <box size="0.5662757309423905 0.6992089496932985 0.6652843116242445" />
            </geometry>
            <material name="Sensor">
                <color rgba="0 1.0 0 1.0"/>
            </material>
        </visual>
        <collision>
            <origin xyz="0.28313786547119524 0 0" rpy="0 0 0"/>
            <geometry>
                <box size="0.5662757309423905 0.6992089496932985 0.6652843116242445" />
            </geometry>
        </collision>
    </link>
    <joint name="2_3" type="revolute">
       <parent link="2"/>
       <child  link="3"/>
       <origin rpy="0 0 0" xyz="0.5662757309423905 0 0" />
       <axis xyz="0 1 0"/>
       <limit effort="0.0" lower="-3.14159" upper="3.14159" velocity="0.0"/>
    </joint>
    <link name="3">
        <inertial>
            <origin xyz="0.329634503251546 0 0" rpy="0 0 0"/>
            <mass value="0.37229788590025903" />
            <inertia ixx="100" ixy="0" ixz="0" iyy="100" iyz="0" izz="100" />
        </inertial>
        <visual>
            <origin xyz="0.329634503251546 0 0" rpy="0 0 0"/>
            <geometry>
                <box size="0.659269006503092 0.69066417598902 0.8176378370079511" />
            </geometry>
            <material name="No Sensor">
                <color rgba="0 0 1.0 1.0"/>
            </material>
        </visual>
        <collision>
            <origin xyz="0.329634503251546 0 0" rpy="0 0 0"/>
            <geometry>
                <box size="0.659269006503092 0.69066417598902 0.8176378370079511" />
            </geometry>
        </collision>
    </link>
    <joint name="3_4" type="revolute">
       <parent link="3"/>
       <child  link="4"/>
       <origin rpy="0 0 0" xyz="0.659269006503092 0 0" />
       <axis xyz="0 1 0"/>
       <limit effort="0.0" lower="-3.14159" upper="3.14159" velocity="0.0"/>
    </joint>
    <link name="4">
        <inertial>
            <origin xyz="0.38937637635124883 0 0" rpy="0 0 0"/>
            <mass value="0.34501152928579093" />
            <inertia ixx="100" ixy="0" ixz="0" iyy="100" iyz="0" izz="100" />
        </inertial>
        <visual>
            <origin xyz="0.38937637635124883 0 0" rpy="0 0 0"/>
            <geometry>
                <box size="0.7787527527024977 0.6755786168501645 0.6557799259770052" />
            </geometry>
            <material name="Sensor">
                <color rgba="0 1.0 0 1.0"/>
            </material>
        </visual>
        <collision>
            <origin xyz="0.38937637635124883 0 0" rpy="0 0 0"/>
            <geometry>
                <box size="0.7787527527024977 0.6755786168501645 0.6557799259770052" />
            </geometry>
        </collision>
    </link>
    <joint name="4_5" type="revolute">
       <parent link="4"/>
       <child  link="5"/>
       <origin rpy="0 0 0" xyz="0.7787527527024977 0 0" />
       <axis xyz="0 1 0"/>
       <limit effort="0.0" lower="-3.14159" upper="3.14159" velocity="0.0"/>
    </joint>
    <link name="5">
        <inertial>
            <origin xyz="0.28944097814588565 0 0" rpy="0 0 0"/>
            <mass value="0.2967184298022962" />
            <inertia ixx="100" ixy="0" ixz="0" iyy="100" iyz="0" izz="100" />
        </inertial>
        <visual>
            <origin xyz="0.28944097814588565 0 0" rpy="0 0 0"/>
            <geometry>
                <box size="0.5788819562917713 0.9155069583200445 0.5598773002268784" />
            </geometry>
            <material name="Sensor">
                <color rgba="0 1.0 0 1.0"/>
            </material>
        </visual>
        <collision>
            <origin xyz="0.28944097814588565 0 0" rpy="0 0 0"/>
            <geometry>
                <box size="0.5788819562917713 0.9155069583200445 0.5598773002268784" />
            </geometry>
        </collision>
    </link>
    <joint name="5_6" type="revolute">
       <parent link="5"/>
       <child  link="6"/>
       <origin rpy="0 0 0" xyz="0.5788819562917713 0 0" />
       <axis xyz="0 1 0"/>
       <limit effort="0.0" lower="-3.14159" upper="3.14159" velocity="0.0"/>
    </joint>
    <link name="6">
        <inertial>
            <origin xyz="0.39954772066833105 0 0" rpy="0 0 0"/>
            <mass value="0.2767509191575373" />
            <inertia ixx="100" ixy="0" ixz="0" iyy="100" iyz="0" izz="100" />
        </inertial>
        <visual>
            <origin xyz="0.39954772066833105 0 0" rpy="0 0 0"/>
            <geometry>
                <box size="0.7990954413366621 0.6785195234259745 0.5104204551498219" />
            </geometry>
            <material name="No Sensor">
                <color rgba="0 0 1.0 1.0"/>
            </material>
        </visual>
        <collision>
            <origin xyz="0.39954772066833105 0 0" rpy="0 0 0"/>
            <geometry>
                <box size="0.7990954413366621 0.6785195234259745 0.5104204551498219" />
            </geometry>
        </collision>
    </link>
</robot>